Workbook
Name AAI: #REF!
Name ALGDED: #REF!
Name BALANZADIC: #REF!
Name BALANZADIC14: #REF!
Name BGDECL: #REF!
Name CCF: #REF!
Name EJERCICIO: #REF!
Name ENERO16: #REF!
Name ENERO16: #REF!
Name ENERO16: #REF!
Name ENERO16: #REF!
Name ENERO16: #REF!
Name ENERO16: #REF!
Name ENERO16: #REF!
Name ENERO16: #REF!
Name ENERO16: #REF!
Name ENERO16: #REF!
Name ENERO16: #REF!
Name ERDECL: #REF!
Name inpc: #REF!
Name No_MES: #REF!
Name NombreRango1: #REF!
Name NombreRango1: #REF!
Name NombreRango1: #REF!
Name NombreRango1: #REF!
Name NombreRango1: #REF!
Name NombreRango1: #REF!
Name NombreRango1: #REF!
Name NombreRango1: #REF!
Name NombreRango1: #REF!
Name NombreRango1: #REF!
Name NombreRango1: #REF!
Name VAC: #REF!

Sheet Parametros JRZ
A1: ESTIMULO FISCAL | D1: IEPS
A2: REGULAR | B2: ='[1]Parametros Jrz'!$B$2 -> 3.41 | D2: REGULAR | E2: ='[1]Parametros Jrz'!$E$2 -> 0.522479 | I2: *Aumento en los ingresos en proporcion minima a la inflacion
A3: PREMIUM | B3: ='[1]Parametros Jrz'!$B$3 -> 2.86 | D3: PREMIUM | E3: ='[1]Parametros Jrz'!$E$3 -> 0.637522
A4: DIESEL | B4: ='[1]Parametros Jrz'!$B$4 -> 0 | D4: DIESEL | E4: ='[1]Parametros Jrz'!$E$4 -> 0.433626
A6: ='[1]Parametros Jrz'!$A$6 -> Precio final al 04 de sep 2024 | D6: Precio de venta sin IVA
A7: REGULAR | B7: ='[1]Parametros Jrz'!$B$7 -> 18.99 | D7: ='[1]Parametros Jrz'!$D$7 -> 17.583333
A8: PREMIUM | B8: ='[1]Parametros Jrz'!$B$8 -> 20.99 | D8: ='[1]Parametros Jrz'!$D$8 -> 19.435185
A9: DIESEL | B9: ='[1]Parametros Jrz'!$B$9 -> 23.79 | D9: ='[1]Parametros Jrz'!$D$9 -> 22.027778
A11: PRECIO DE VENTA sin IVA por LITRO
A12: Juarez | B12: ='[1]Parametros Jrz'!B12 -> 0.005 | C12: ='[1]Parametros Jrz'!C12 -> 0.005 | D12: ='[1]Parametros Jrz'!D12 -> 0.005 | E12: ='[1]Parametros Jrz'!E12 -> 0.005 | F12: ='[1]Parametros Jrz'!F12 -> 0.005 | G12: ='[1]Parametros Jrz'!G12 -> 0.005 | H12: ='[1]Parametros Jrz'!H12 -> 0.005 | I12: ='[1]Parametros Jrz'!I12 -> 0.005 | ... M12: ='[1]Parametros Jrz'!M12 -> 0.005
A13: P.V. | B13: Enero | C13: Febrero | D13: Marzo | E13: Abril | F13: Mayo | G13: Junio | H13: Julio | I13: Agosto | J13: Septiembre | K13: Octubre | L13: Noviembre | M13: Diciembre
A14: MAXIMA | B14: ='[1]Parametros Jrz'!B14 -> 17.583333 | C14: ='[1]Parametros Jrz'!C14 -> 17.67125 | D14: ='[1]Parametros Jrz'!D14 -> 17.759606 | E14: ='[1]Parametros Jrz'!E14 -> 17.848404 | F14: ='[1]Parametros Jrz'!F14 -> 17.937646 | G14: ='[1]Parametros Jrz'!G14 -> 18.027335 | H14: ='[1]Parametros Jrz'!H14 -> 18.117471 | I14: ='[1]Parametros Jrz'!I14 -> 18.208059 | ... M14: ='[1]Parametros Jrz'!M14 -> 18.57496
A15: SUPER | B15: ='[1]Parametros Jrz'!B15 -> 19.435185 | C15: ='[1]Parametros Jrz'!C15 -> 19.532361 | D15: ='[1]Parametros Jrz'!D15 -> 19.630023 | E15: ='[1]Parametros Jrz'!E15 -> 19.728173 | F15: ='[1]Parametros Jrz'!F15 -> 19.826814 | G15: ='[1]Parametros Jrz'!G15 -> 19.925948 | H15: ='[1]Parametros Jrz'!H15 -> 20.025578 | I15: ='[1]Parametros Jrz'!I15 -> 20.125706 | ... M15: ='[1]Parametros Jrz'!M15 -> 20.531249
A16: DIESEL | B16: ='[1]Parametros Jrz'!B16 -> 22.027778 | C16: ='[1]Parametros Jrz'!C16 -> 22.137917 | D16: ='[1]Parametros Jrz'!D16 -> 22.248606 | E16: ='[1]Parametros Jrz'!E16 -> 22.359849 | F16: ='[1]Parametros Jrz'!F16 -> 22.471649 | G16: ='[1]Parametros Jrz'!G16 -> 22.584007 | H16: ='[1]Parametros Jrz'!H16 -> 22.696927 | I16: ='[1]Parametros Jrz'!I16 -> 22.810411 | ... M16: ='[1]Parametros Jrz'!M16 -> 23.270053
A18: ='[1]Parametros Jrz'!$A$18 -> Inflación 2024 | B18: ='[1]Parametros Jrz'!$B$18 -> 1.04
A21: MARGEN estimado por litro
A22: Juarez | B22: Margen comercial ( precio - costo según factura )
A23: P.V. | B23: Enero | C23: Febrero | D23: Marzo | E23: Abril | F23: Mayo | G23: Junio | H23: Julio | I23: Agosto | J23: Septiembre | K23: Octubre | L23: Noviembre | M23: Diciembre
A24: MAXIMA | B24: ='[1]Parametros Jrz'!B24 -> 0 | C24: ='[1]Parametros Jrz'!C24 -> 0 | D24: ='[1]Parametros Jrz'!D24 -> 0 | E24: ='[1]Parametros Jrz'!E24 -> 0 | F24: ='[1]Parametros Jrz'!F24 -> 0 | G24: ='[1]Parametros Jrz'!G24 -> 0 | H24: ='[1]Parametros Jrz'!H24 -> 0 | I24: ='[1]Parametros Jrz'!I24 -> 0 | ... M24: ='[1]Parametros Jrz'!M24 -> 0
A25: SUPER | B25: ='[1]Parametros Jrz'!B25 -> 0 | C25: ='[1]Parametros Jrz'!C25 -> 0 | D25: ='[1]Parametros Jrz'!D25 -> 0 | E25: ='[1]Parametros Jrz'!E25 -> 0 | F25: ='[1]Parametros Jrz'!F25 -> 0 | G25: ='[1]Parametros Jrz'!G25 -> 0 | H25: ='[1]Parametros Jrz'!H25 -> 0 | I25: ='[1]Parametros Jrz'!I25 -> 0 | ... M25: ='[1]Parametros Jrz'!M25 -> 0
A26: DIESEL | B26: ='[1]Parametros Jrz'!B26 -> 0 | C26: ='[1]Parametros Jrz'!C26 -> 0 | D26: ='[1]Parametros Jrz'!D26 -> 0 | E26: ='[1]Parametros Jrz'!E26 -> 0 | F26: ='[1]Parametros Jrz'!F26 -> 0 | G26: ='[1]Parametros Jrz'!G26 -> 0 | H26: ='[1]Parametros Jrz'!H26 -> 0 | I26: ='[1]Parametros Jrz'!I26 -> 0 | ... M26: ='[1]Parametros Jrz'!M26 -> 0
B28: ='[1]Parametros Jrz'!$B$28 -> Margen por contrato de volumen con TESORO
A29: P.V. | B29: Enero | C29: Febrero | D29: Marzo | E29: Abril | F29: Mayo | G29: Junio | H29: Julio | I29: Agosto | J29: Septiembre | K29: Octubre | L29: Noviembre | M29: Diciembre | N29: Porcentaje
A30: MAXIMA | B30: ='[1]Parametros Jrz'!B30 -> 2.08 | C30: ='[1]Parametros Jrz'!C30 -> 2.28 | D30: ='[1]Parametros Jrz'!D30 -> 2.58 | E30: ='[1]Parametros Jrz'!E30 -> 2.21 | F30: ='[1]Parametros Jrz'!F30 -> 2.34 | G30: ='[1]Parametros Jrz'!G30 -> 2.06 | H30: ='[1]Parametros Jrz'!H30 -> 2.26 | I30: ='[1]Parametros Jrz'!I30 -> 2 | ... N30: ='[1]Parametros Jrz'!N30 -> 0.48 | P30: =AVERAGE(B30:M30) -> 2.4216667
A31: SUPER | B31: ='[1]Parametros Jrz'!B31 -> 3.37 | C31: ='[1]Parametros Jrz'!C31 -> 2.79 | D31: ='[1]Parametros Jrz'!D31 -> 2.2 | E31: ='[1]Parametros Jrz'!E31 -> 2.04 | F31: ='[1]Parametros Jrz'!F31 -> 2.95 | G31: ='[1]Parametros Jrz'!G31 -> 2.63 | H31: ='[1]Parametros Jrz'!H31 -> 2.63 | I31: ='[1]Parametros Jrz'!I31 -> 2.33 | ... N31: ='[1]Parametros Jrz'!N31 -> 0.47 | P31: =AVERAGE(B31:M31) -> 2.985
A32: DIESEL | B32: ='[1]Parametros Jrz'!B32 -> 1.08 | C32: ='[1]Parametros Jrz'!C32 -> 2.3 | D32: ='[1]Parametros Jrz'!D32 -> 2.84 | E32: ='[1]Parametros Jrz'!E32 -> 2.82 | F32: ='[1]Parametros Jrz'!F32 -> 3.38 | G32: ='[1]Parametros Jrz'!G32 -> 2.79 | H32: ='[1]Parametros Jrz'!H32 -> 2.49 | I32: ='[1]Parametros Jrz'!I32 -> 2.45 | ... N32: ='[1]Parametros Jrz'!N32 -> 0.8 | P32: =AVERAGE(B32:M32) -> 2.2766667
B34: ='[1]Parametros Jrz'!$B$34 -> Margen por contrato de volumen con MGC
A35: P.V. | B35: Enero | C35: Febrero | D35: Marzo | E35: Abril | F35: Mayo | G35: Junio | H35: Julio | I35: Agosto | J35: Septiembre | K35: Octubre | L35: Noviembre | M35: Diciembre | N35: Porcentaje
A36: MAXIMA | B36: ='[1]Parametros Jrz'!B36 -> 1.93 | C36: ='[1]Parametros Jrz'!C36 -> 2.19 | D36: ='[1]Parametros Jrz'!D36 -> 2.51 | E36: ='[1]Parametros Jrz'!E36 -> 2.16 | F36: ='[1]Parametros Jrz'!F36 -> 2.23 | G36: ='[1]Parametros Jrz'!G36 -> 2.04 | H36: ='[1]Parametros Jrz'!H36 -> 2.16 | I36: ='[1]Parametros Jrz'!I36 -> 1.98 | ... N36: ='[1]Parametros Jrz'!N36 -> 0.21 | P36: =AVERAGE(B36:M36) -> 2.2625
A37: SUPER | B37: ='[1]Parametros Jrz'!B37 -> 2.75 | C37: ='[1]Parametros Jrz'!C37 -> 2.08 | D37: ='[1]Parametros Jrz'!D37 -> 1.52 | E37: ='[1]Parametros Jrz'!E37 -> 1.44 | F37: ='[1]Parametros Jrz'!F37 -> 2.43 | G37: ='[1]Parametros Jrz'!G37 -> 1.63 | H37: ='[1]Parametros Jrz'!H37 -> 1.6 | I37: ='[1]Parametros Jrz'!I37 -> 1.82 | ... N37: ='[1]Parametros Jrz'!N37 -> 0.39 | P37: =AVERAGE(B37:M37) -> 2.2075
A38: DIESEL | B38: ='[1]Parametros Jrz'!B38 -> 0.62 | C38: ='[1]Parametros Jrz'!C38 -> 1.71 | D38: ='[1]Parametros Jrz'!D38 -> 2.66 | E38: ='[1]Parametros Jrz'!E38 -> 2.71 | F38: ='[1]Parametros Jrz'!F38 -> 3.36 | G38: ='[1]Parametros Jrz'!G38 -> 2.63 | H38: ='[1]Parametros Jrz'!H38 -> 2.41 | I38: ='[1]Parametros Jrz'!I38 -> 0 | ... N38: ='[1]Parametros Jrz'!N38 -> 0.1 | P38: =AVERAGE(B38:M38) -> 1.8808333
B40: ='[1]Parametros Jrz'!$B$40 -> Margen por contrato de volumen PREMIERGAS
A41: P.V. | B41: Enero | C41: Febrero | D41: Marzo | E41: Abril | F41: Mayo | G41: Junio | H41: Julio | I41: Agosto | J41: Septiembre | K41: Octubre | L41: Noviembre | M41: Diciembre | N41: Porcentaje
A42: MAXIMA | B42: ='[1]Parametros Jrz'!B42 -> 2.26 | C42: ='[1]Parametros Jrz'!C42 -> 2.71 | D42: ='[1]Parametros Jrz'!D42 -> 3.09 | E42: ='[1]Parametros Jrz'!E42 -> 2.69 | F42: ='[1]Parametros Jrz'!F42 -> 2.69 | G42: ='[1]Parametros Jrz'!G42 -> 2.48 | H42: ='[1]Parametros Jrz'!H42 -> 2.55 | I42: ='[1]Parametros Jrz'!I42 -> 2.38 | ... N42: ='[1]Parametros Jrz'!N42 -> 0.23 | P42: =AVERAGE(B42:M42) -> 2.7258333
A43: SUPER | B43: ='[1]Parametros Jrz'!B43 -> 2.89 | C43: ='[1]Parametros Jrz'!C43 -> 2.42 | D43: ='[1]Parametros Jrz'!D43 -> 2.38 | E43: ='[1]Parametros Jrz'!E43 -> 2.1 | F43: ='[1]Parametros Jrz'!F43 -> 2.84 | G43: ='[1]Parametros Jrz'!G43 -> 2.74 | H43: ='[1]Parametros Jrz'!H43 -> 2.02 | I43: ='[1]Parametros Jrz'!I43 -> 2.02 | ... N43: ='[1]Parametros Jrz'!N43 -> 0.14 | P43: =AVERAGE(B43:M43) -> 2.7516667
A44: DIESEL | B44: ='[1]Parametros Jrz'!B44 -> 1.93 | C44: ='[1]Parametros Jrz'!C44 -> 2.89 | D44: ='[1]Parametros Jrz'!D44 -> 3.55 | E44: ='[1]Parametros Jrz'!E44 -> 3.43 | F44: ='[1]Parametros Jrz'!F44 -> 3.82 | G44: ='[1]Parametros Jrz'!G44 -> 2.9 | H44: ='[1]Parametros Jrz'!H44 -> 3.38 | I44: ='[1]Parametros Jrz'!I44 -> 3.01 | ... N44: ='[1]Parametros Jrz'!N44 -> 0.05 | P44: =AVERAGE(B44:M44) -> 2.6741667
B46: ='[1]Parametros Jrz'!$B$46 -> Margen por contrato de volumen AMCA
A47: P.V. | B47: Enero | C47: Febrero | D47: Marzo | E47: Abril | F47: Mayo | G47: Junio | H47: Julio | I47: Agosto | J47: Septiembre | K47: Octubre | L47: Noviembre | M47: Diciembre | N47: Porcentaje
A48: MAXIMA | B48: ='[1]Parametros Jrz'!B48 -> 1.74 | C48: ='[1]Parametros Jrz'!C48 -> 2.48 | D48: ='[1]Parametros Jrz'!D48 -> 2.41 | E48: ='[1]Parametros Jrz'!E48 -> 2.34 | F48: ='[1]Parametros Jrz'!F48 -> 2.56 | G48: ='[1]Parametros Jrz'!G48 -> 2.46 | H48: ='[1]Parametros Jrz'!H48 -> 2.42 | I48: ='[1]Parametros Jrz'!I48 -> 2.89 | ... N48: ='[1]Parametros Jrz'!N48 -> 0.05 | P48: =AVERAGE(B48:M48) -> 2.2366667
A49: SUPER | B49: ='[1]Parametros Jrz'!B49 -> 0 | C49: ='[1]Parametros Jrz'!C49 -> 0 | D49: ='[1]Parametros Jrz'!D49 -> 0 | E49: ='[1]Parametros Jrz'!E49 -> 0 | F49: ='[1]Parametros Jrz'!F49 -> 0 | G49: ='[1]Parametros Jrz'!G49 -> 0 | H49: ='[1]Parametros Jrz'!H49 -> 0 | I49: ='[1]Parametros Jrz'!I49 -> 0 | ... N49: ='[1]Parametros Jrz'!N49 -> 0 | P49: =AVERAGE(B49:M49) -> 0
...

Sheet EDO RESULTADOS TOTAL EST.
I1: 1147 | J1: 2 | K1: 3 | L1: 4 | M1: 5 | N1: 6 | O1: 7 | Y1: 2 | Z1: =+Y1+1 -> 3 | AA1: =+Z1+1 -> 4 | AB1: =+AA1+1 -> 5 | AC1: =+AB1+1 -> 6 | AD1: =+AC1+1 -> 7 | AE1: =+AD1+1 -> 8 | AF1: =+AE1+1 -> 9 | AG1: =+AF1+1 -> 10 | ... AK1: =+AJ1+1 -> 14 | AM1: 17
J2: 2024 | V2: TOTAL ANUAL | Y2: 2025 | AK2: TOTAL ANUAL
J3: ENE | K3: FEB | L3: MAR | M3: ABR | N3: MAY | O3: JUN | P3: JUL | Q3: AGO | R3: SEP | S3: OCT | T3: NOV | U3: DIC | V3: 2024 | W3: % Part | Y3: ENE | Z3: FEB | AA3: MAR | AB3: ABR | AC3: MAY | AD3: JUN | AE3: JUL | AF3: AGO | AG3: SEP | AH3: OCT | AI3: NOV | AJ3: DIC | AK3: 2025 | AL3: % Part | AM3: Var vs AA%
I4: INGRESOS
A6: A - INGRESOS | E6: ( mas ) | I6: A - INGRESOS | J6: =SUM(J7:J12) -> 69452870 | K6: =SUM(K7:K12) -> 68676679 | L6: =SUM(L7:L12) -> 74038427 | M6: =SUM(M7:M12) -> 69224559 | N6: =SUM(N7:N12) -> 77933808 | O6: =SUM(O7:O12) -> 77696456 | P6: =SUM(P7:P12) -> 76552162 | Q6: =SUM(Q7:Q12) -> 70332214 | ... V6: =SUM(V7:V12) -> 8.9616389e+08 | W6: =V6/V$6 -> 1 | Y6: =SUM(Y7:Y12) -> 69733029 | Z6: =SUM(Z7:Z12) -> 69139078 | AA6: =SUM(AA7:AA12) -> 76712717 | AB6: =SUM(AB7:AB12) -> 72969416 | AC6: =SUM(AC7:AC12) -> 84041095 | AD6: =SUM(AD7:AD12) -> 83841112 | AE6: =SUM(AE7:AE12) -> 83649040 | AF6: =SUM(AF7:AF12) -> 85393702 | ... AK6: =SUM(AK7:AK12) -> 9.6317828e+08 | AL6: =AK6/AK$6 -> 1 | AM6: =IFERROR(AK6/V6-1,0) -> 0.074779166
A7: A - INGRESOS | B7: estaciones | C7: INGRESOS MAGNA | D7: INGRESOS FORANEOS MAGNA | I7: MAXIMA | J7: =SUM(A:B!J7) -> 52024925 | K7: =SUM(A:B!K7) -> 51666858 | L7: =SUM(A:B!L7) -> 55424481 | M7: =SUM(A:B!M7) -> 52126321 | N7: =SUM(A:B!N7) -> 58611053 | O7: =SUM(A:B!O7) -> 57223116 | P7: =SUM(A:B!P7) -> 55837049 | Q7: =SUM(A:B!Q7) -> 53402377 | ... U7: =SUM(A:B!U7) -> 62663938 | V7: =SUM(J7:U7) -> 6.7596297e+08 | W7: =V7/V$6 -> 0.75428499 | Y7: =SUM(A:B!Y7) -> 51376336 | Z7: =SUM(A:B!Z7) -> 51093583 | AA7: =SUM(A:B!AA7) -> 56927257 | AB7: =SUM(A:B!AB7) -> 54191883 | AC7: =SUM(A:B!AC7) -> 63090563 | AD7: =SUM(A:B!AD7) -> 62100321 | AE7: =SUM(A:B!AE7) -> 61646409 | AF7: =SUM(A:B!AF7) -> 64583060 | ... AJ7: =SUM(A:B!AJ7) -> 60670598 | AK7: =SUM(Y7:AJ7) -> 7.175899e+08 | AL7: =AK7/AK$6 -> 0.74502293 | AM7: =IFERROR(AK7/V7-1,0) -> 0.06158167
A8: A - INGRESOS | B8: estaciones | C8: INGRESOS PREMIUM | D8: INGRESOS FORANEOS PREMIUM | I8: SUPER | J8: =SUM(A:B!J8) -> 5468366 | K8: =SUM(A:B!K8) -> 5650927 | L8: =SUM(A:B!L8) -> 6229300 | M8: =SUM(A:B!M8) -> 5959245 | N8: =SUM(A:B!N8) -> 6580767 | O8: =SUM(A:B!O8) -> 6797460 | P8: =SUM(A:B!P8) -> 6511011 | Q8: =SUM(A:B!Q8) -> 4596705 | ... U8: =SUM(A:B!U8) -> 6115975.3 | V8: =SUM(J8:U8) -> 71743880 | W8: =V8/V$6 -> 0.080056651 | Y8: =SUM(A:B!Y8) -> 5360351.8 | Z8: =SUM(A:B!Z8) -> 5553280.4 | AA8: =SUM(A:B!AA8) -> 6278391.1 | AB8: =SUM(A:B!AB8) -> 5971144.2 | AC8: =SUM(A:B!AC8) -> 6969804.5 | AD8: =SUM(A:B!AD8) -> 7376824 | AE8: =SUM(A:B!AE8) -> 7096503.4 | AF8: =SUM(A:B!AF8) -> 7282731 | ... AJ8: =SUM(A:B!AJ8) -> 6418291.8 | AK8: =SUM(Y8:AJ8) -> 79107483 | AL8: =AK8/AK$6 -> 0.082131714 | AM8: =IFERROR(AK8/V8-1,0) -> 0.10263738
A9: A - INGRESOS | B9: estaciones | C9: INGRESOS DIESEL | D9: INGRESOS FORANEOS DIESEL | I9: DIESEL | J9: =SUM(A:B!J9) -> 11903653 | K9: =SUM(A:B!K9) -> 11298703 | L9: =SUM(A:B!L9) -> 12326817 | M9: =SUM(A:B!M9) -> 11076012 | N9: =SUM(A:B!N9) -> 12676022 | O9: =SUM(A:B!O9) -> 13611508 | P9: =SUM(A:B!P9) -> 14146233 | Q9: =SUM(A:B!Q9) -> 12274004 | ... U9: =SUM(A:B!U9) -> 10676098 | V9: =SUM(J9:U9) -> 1.4772481e+08 | W9: =V9/V$6 -> 0.16484128 | Y9: =SUM(A:B!Y9) -> 12921702 | Z9: =SUM(A:B!Z9) -> 12420215 | AA9: =SUM(A:B!AA9) -> 13411609 | AB9: =SUM(A:B!AB9) -> 12736669 | AC9: =SUM(A:B!AC9) -> 13904947 | AD9: =SUM(A:B!AD9) -> 14292866 | AE9: =SUM(A:B!AE9) -> 14834428 | AF9: =SUM(A:B!AF9) -> 13459330 | ... AJ9: =SUM(A:B!AJ9) -> 13925549 | AK9: =SUM(Y9:AJ9) -> 1.6558143e+08 | AL9: =AK9/AK$6 -> 0.17191151 | AM9: =IFERROR(AK9/V9-1,0) -> 0.12087765
I10: INGRESOS ACEITES Y LUBRICANTES | J10: =SUM(A:B!J10) -> 55926 | K10: =SUM(A:B!K10) -> 60191 | L10: =SUM(A:B!L10) -> 57829 | M10: =SUM(A:B!M10) -> 62981 | N10: =SUM(A:B!N10) -> 65966 | O10: =SUM(A:B!O10) -> 64372 | P10: =SUM(A:B!P10) -> 57869 | Q10: =SUM(A:B!Q10) -> 59128 | ... U10: =SUM(A:B!U10) -> 66823.2 | V10: =SUM(J10:U10) -> 732231.8 | W10: =V10/V$6 -> 0.00081707354 | Y10: =SUM(A:B!Y10) -> 74640 | Z10: =SUM(A:B!Z10) -> 72000 | AA10: =SUM(A:B!AA10) -> 95460 | AB10: =SUM(A:B!AB10) -> 69720 | AC10: =SUM(A:B!AC10) -> 75780 | AD10: =SUM(A:B!AD10) -> 71100 | AE10: =SUM(A:B!AE10) -> 71700 | AF10: =SUM(A:B!AF10) -> 68580 | ... AJ10: =SUM(A:B!AJ10) -> 76260 | AK10: =SUM(Y10:AJ10) -> 899460 | AL10: =AK10/AK$6 -> 0.00093384581 | AM10: =IFERROR(AK10/V10-1,0) -> 0.2283815
I11: SOBRANTE COMBUSTIBLE | J11: =SUM(A:B!J11) -> 0 | K11: =SUM(A:B!K11) -> 0 | L11: =SUM(A:B!L11) -> 0 | M11: =SUM(A:B!M11) -> 0 | N11: =SUM(A:B!N11) -> 0 | O11: =SUM(A:B!O11) -> 0 | P11: =SUM(A:B!P11) -> 0 | Q11: =SUM(A:B!Q11) -> 0 | ... U11: =SUM(A:B!U11) -> 0 | V11: =SUM(J11:U11) -> 0 | W11: =V11/V$6 -> 0 | Y11: =SUM(A:B!Y11) -> 0 | Z11: =SUM(A:B!Z11) -> 0 | AA11: =SUM(A:B!AA11) -> 0 | AB11: =SUM(A:B!AB11) -> 0 | AC11: =SUM(A:B!AC11) -> 0 | AD11: =SUM(A:B!AD11) -> 0 | AE11: =SUM(A:B!AE11) -> 0 | AF11: =SUM(A:B!AF11) -> 0 | ... AJ11: =SUM(A:B!AJ11) -> 0 | AK11: =SUM(Y11:AJ11) -> 0 | AL11: =AK11/AK$6 -> 0 | AM11: =IFERROR(AK11/V11-1,0) -> 0
J12: =SUM(A:B!J12) -> 0 | K12: =SUM(A:B!K12) -> 0 | L12: =SUM(A:B!L12) -> 0 | M12: =SUM(A:B!M12) -> 0 | N12: =SUM(A:B!N12) -> 0 | O12: =SUM(A:B!O12) -> 0 | P12: =SUM(A:B!P12) -> 0 | Q12: =SUM(A:B!Q12) -> 0 | ... U12: =SUM(A:B!U12) -> 0 | V12: =SUM(J12:U12) -> 0 | W12: =V12/V$6 -> 0 | Y12: =SUM(A:B!Y12) -> 0 | Z12: =SUM(A:B!Z12) -> 0 | AA12: =SUM(A:B!AA12) -> 0 | AB12: =SUM(A:B!AB12) -> 0 | AC12: =SUM(A:B!AC12) -> 0 | AD12: =SUM(A:B!AD12) -> 0 | AE12: =SUM(A:B!AE12) -> 0 | AF12: =SUM(A:B!AF12) -> 0 | ... AJ12: =SUM(A:B!AJ12) -> 0 | AK12: =SUM(Y12:AJ12) -> 0 | AL12: =AK12/AK$6 -> 0 | AM12: =IFERROR(AK12/V12-1,0) -> 0
A13: B - COSTO DE VENTA | E13: ( menos ) | I13: B - COSTO DE VENTA | J13: =SUM(J14:J33) -> 59783497 | K13: =SUM(K14:K33) -> 58274255 | L13: =SUM(L14:L33) -> 63406479 | M13: =SUM(M14:M33) -> 59049480 | N13: =SUM(N14:N33) -> 65462131 | O13: =SUM(O14:O33) -> 66797081 | P13: =SUM(P14:P33) -> 66311059 | Q13: =SUM(Q14:Q33) -> 61034025 | ... V13: =SUM(V14:V33) -> 7.6792499e+08 | W13: =V13/V$6 -> 0.8569024 | Y13: =SUM(Y14:Y33) -> 60165791 | Z13: =SUM(Z14:Z33) -> 59829241 | AA13: =SUM(AA14:AA33) -> 66068704 | AB13: =SUM(AB14:AB33) -> 63509117 | AC13: =SUM(AC14:AC33) -> 72484085 | AD13: =SUM(AD14:AD33) -> 73043997 | AE13: =SUM(AE14:AE33) -> 72992851 | AF13: =SUM(AF14:AF33) -> 74396670 | ... AJ13: =SUM(AJ14:AJ33) -> 71476884 | AK13: =SUM(Y13:AJ13) -> 8.3887815e+08 | AL13: =AK13/AK$6 -> 0.87094795 | AM13: =IFERROR(AK13/V13-1,0) -> 0.092395952
A14: B - COSTO DE VENTA | C14: COSTO MAGNA | D14: COSTO FORANEO MAGNA | I14: GASOLINA REGULAR | J14: =SUM(A:B!J14) -> 54037503 | K14: =SUM(A:B!K14) -> 52988836 | L14: =SUM(A:B!L14) -> 58109663 | M14: =SUM(A:B!M14) -> 54182667 | N14: =SUM(A:B!N14) -> 61241981 | O14: =SUM(A:B!O14) -> 60864148 | P14: =SUM(A:B!P14) -> 59642077 | Q14: =SUM(A:B!Q14) -> 56951729 | ... U14: =SUM(A:B!U14) -> 53503309 | V14: =SUM(J14:U14) -> 6.827669e+08 | W14: =V14/V$6 -> 0.76187727 | Y14: =SUM(A:B!Y14) -> 43965152 | Z14: =SUM(A:B!Z14) -> 43858767 | AA14: =SUM(A:B!AA14) -> 48610578 | AB14: =SUM(A:B!AB14) -> 46833763 | AC14: =SUM(A:B!AC14) -> 53940557 | AD14: =SUM(A:B!AD14) -> 53743511 | AE14: =SUM(A:B!AE14) -> 53413437 | AF14: =SUM(A:B!AF14) -> 55867226 | ... AJ14: =SUM(A:B!AJ14) -> 53142545 | AK14: =SUM(Y14:AJ14) -> 6.2048976e+08 | AL14: =AK14/AK$6 -> 0.64421071 | AM14: =IFERROR(AK14/V14-1,0) -> -0.091212883
A15: B - COSTO DE VENTA | C15: COSTO PREMIUM | D15: COSTO FORANEO PREMIUM | I15: GASOLINA PREMIUM | J15: =SUM(A:B!J15) -> 5319273 | K15: =SUM(A:B!K15) -> 5477157 | L15: =SUM(A:B!L15) -> 6024604 | M15: =SUM(A:B!M15) -> 5759007 | N15: =SUM(A:B!N15) -> 6417905 | O15: =SUM(A:B!O15) -> 6709392 | P15: =SUM(A:B!P15) -> 6539768 | Q15: =SUM(A:B!Q15) -> 4716580 | ... U15: =SUM(A:B!U15) -> 5274244.5 | V15: =SUM(J15:U15) -> 69441601 | W15: =V15/V$6 -> 0.077487614 | Y15: =SUM(A:B!Y15) -> 4659126.8 | Z15: =SUM(A:B!Z15) -> 4832868.2 | AA15: =SUM(A:B!AA15) -> 5459075.2 | AB15: =SUM(A:B!AB15) -> 5216593.9 | AC15: =SUM(A:B!AC15) -> 6098775.6 | AD15: =SUM(A:B!AD15) -> 6452142 | AE15: =SUM(A:B!AE15) -> 6245227.6 | AF15: =SUM(A:B!AF15) -> 6398892.4 | ... AJ15: =SUM(A:B!AJ15) -> 5685605.9 | AK15: =SUM(Y15:AJ15) -> 69403895 | AL15: =AK15/AK$6 -> 0.072057163 | AM15: =IFERROR(AK15/V15-1,0) -> -0.00054299936
A16: B - COSTO DE VENTA | C16: COSTO DIESEL | D16: COSTO FORANEO DIESEL | I16: DIESEL | J16: =SUM(A:B!J16) -> 10212607 | K16: =SUM(A:B!K16) -> 10010596 | L16: =SUM(A:B!L16) -> 10864455 | M16: =SUM(A:B!M16) -> 9847047 | N16: =SUM(A:B!N16) -> 11207696 | O16: =SUM(A:B!O16) -> 12305498 | P16: =SUM(A:B!P16) -> 12857250 | Q16: =SUM(A:B!Q16) -> 10940446 | ... U16: =SUM(A:B!U16) -> 9471412.1 | V16: =SUM(J16:U16) -> 1.3157793e+08 | W16: =V16/V$6 -> 0.14682351 | Y16: =SUM(A:B!Y16) -> 11478068 | Z16: =SUM(A:B!Z16) -> 11076406 | AA16: =SUM(A:B!AA16) -> 11917910 | AB16: =SUM(A:B!AB16) -> 11399498 | AC16: =SUM(A:B!AC16) -> 12380340 | AD16: =SUM(A:B!AD16) -> 12787909 | AE16: =SUM(A:B!AE16) -> 13273242 | AF16: =SUM(A:B!AF16) -> 12072259 | ... AJ16: =SUM(A:B!AJ16) -> 12583912 | AK16: =SUM(Y16:AJ16) -> 1.4821995e+08 | AL16: =AK16/AK$6 -> 0.15388631 | AM16: =IFERROR(AK16/V16-1,0) -> 0.12648037
A17: B - COSTO DE VENTA | C17: Merma Magna | I17: MERMA GASOLINA REGULAR | J17: =SUM(A:B!J17) -> 667991 | K17: =SUM(A:B!K17) -> 194258 | L17: =SUM(A:B!L17) -> 95173 | M17: =SUM(A:B!M17) -> 32472 | N17: =SUM(A:B!N17) -> 0 | O17: =SUM(A:B!O17) -> 0 | P17: =SUM(A:B!P17) -> 0 | Q17: =SUM(A:B!Q17) -> 0 | ... U17: =SUM(A:B!U17) -> 0 | V17: =SUM(J17:U17) -> 989894 | W17: =V17/V$6 -> 0.0011045904 | Y17: =SUM(A:B!Y17) -> 0 | Z17: =SUM(A:B!Z17) -> 0 | AA17: =SUM(A:B!AA17) -> 0 | AB17: =SUM(A:B!AB17) -> 0 | AC17: =SUM(A:B!AC17) -> 0 | AD17: =SUM(A:B!AD17) -> 0 | AE17: =SUM(A:B!AE17) -> 0 | AF17: =SUM(A:B!AF17) -> 0 | ... AJ17: =SUM(A:B!AJ17) -> 0 | AK17: =SUM(Y17:AJ17) -> 0 | AL17: =AK17/AK$6 -> 0 | AM17: =IFERROR(AK17/V17-1,0) -> -1
A18: B - COSTO DE VENTA | C18: Merma Premium | I18: MERMA GASOLINA PREMIUM | J18: =SUM(A:B!J18) -> 112597 | K18: =SUM(A:B!K18) -> 32019 | L18: =SUM(A:B!L18) -> -1798 | M18: =SUM(A:B!M18) -> 5421 | N18: =SUM(A:B!N18) -> 1054 | O18: =SUM(A:B!O18) -> 0 | P18: =SUM(A:B!P18) -> 4980 | Q18: =SUM(A:B!Q18) -> 0 | ... U18: =SUM(A:B!U18) -> 0 | V18: =SUM(J18:U18) -> 176195 | W18: =V18/V$6 -> 0.00019661024 | Y18: =SUM(A:B!Y18) -> 0 | Z18: =SUM(A:B!Z18) -> 0 | AA18: =SUM(A:B!AA18) -> 0 | AB18: =SUM(A:B!AB18) -> 0 | AC18: =SUM(A:B!AC18) -> 0 | AD18: =SUM(A:B!AD18) -> 0 | AE18: =SUM(A:B!AE18) -> 0 | AF18: =SUM(A:B!AF18) -> 0 | ... AJ18: =SUM(A:B!AJ18) -> 0 | AK18: =SUM(Y18:AJ18) -> 0 | AL18: =AK18/AK$6 -> 0 | AM18: =IFERROR(AK18/V18-1,0) -> -1
A19: B - COSTO DE VENTA | C19: Merma Diesel | I19: MERMA DIESEL | J19: =SUM(A:B!J19) -> 852 | K19: =SUM(A:B!K19) -> 0 | L19: =SUM(A:B!L19) -> 302 | M19: =SUM(A:B!M19) -> 384 | N19: =SUM(A:B!N19) -> 1771 | O19: =SUM(A:B!O19) -> 0 | P19: =SUM(A:B!P19) -> 0 | Q19: =SUM(A:B!Q19) -> 9479 | ... U19: =SUM(A:B!U19) -> 0 | V19: =SUM(J19:U19) -> 14972 | W19: =V19/V$6 -> 1.6706766e-05 | Y19: =SUM(A:B!Y19) -> 0 | Z19: =SUM(A:B!Z19) -> 0 | AA19: =SUM(A:B!AA19) -> 0 | AB19: =SUM(A:B!AB19) -> 0 | AC19: =SUM(A:B!AC19) -> 0 | AD19: =SUM(A:B!AD19) -> 0 | AE19: =SUM(A:B!AE19) -> 0 | AF19: =SUM(A:B!AF19) -> 0 | ... AJ19: =SUM(A:B!AJ19) -> 0 | AK19: =SUM(Y19:AJ19) -> 0 | AL19: =AK19/AK$6 -> 0 | AM19: =IFERROR(AK19/V19-1,0) -> -1
I20: SOBRANTE MAGNA | J20: =SUM(A:B!J20) -> 0 | K20: =SUM(A:B!K20) -> -29285 | L20: =SUM(A:B!L20) -> -144224 | M20: =SUM(A:B!M20) -> -252600 | N20: =SUM(A:B!N20) -> -542629 | O20: =SUM(A:B!O20) -> -772168 | P20: =SUM(A:B!P20) -> -628594 | Q20: =SUM(A:B!Q20) -> -417439 | ... U20: =SUM(A:B!U20) -> 0 | V20: =SUM(J20:U20) -> -3818112 | W20: =V20/V$6 -> -0.0042605064 | Y20: =SUM(A:B!Y20) -> 0 | Z20: =SUM(A:B!Z20) -> 0 | AA20: =SUM(A:B!AA20) -> 0 | AB20: =SUM(A:B!AB20) -> 0 | AC20: =SUM(A:B!AC20) -> 0 | AD20: =SUM(A:B!AD20) -> 0 | AE20: =SUM(A:B!AE20) -> 0 | AF20: =SUM(A:B!AF20) -> 0 | ... AJ20: =SUM(A:B!AJ20) -> 0 | AK20: =SUM(Y20:AJ20) -> 0 | AL20: =AK20/AK$6 -> 0 | AM20: =IFERROR(AK20/V20-1,0) -> -1
I21: SOBRANTE PREMIUM | J21: =SUM(A:B!J21) -> -11558 | K21: =SUM(A:B!K21) -> -10191 | L21: =SUM(A:B!L21) -> -23886 | M21: =SUM(A:B!M21) -> -25404 | N21: =SUM(A:B!N21) -> -70527 | O21: =SUM(A:B!O21) -> -88473 | P21: =SUM(A:B!P21) -> -75995 | Q21: =SUM(A:B!Q21) -> -29922 | ... U21: =SUM(A:B!U21) -> 0 | V21: =SUM(J21:U21) -> -411781 | W21: =V21/V$6 -> -0.00045949296 | Y21: =SUM(A:B!Y21) -> 0 | Z21: =SUM(A:B!Z21) -> 0 | AA21: =SUM(A:B!AA21) -> 0 | AB21: =SUM(A:B!AB21) -> 0 | AC21: =SUM(A:B!AC21) -> 0 | AD21: =SUM(A:B!AD21) -> 0 | AE21: =SUM(A:B!AE21) -> 0 | AF21: =SUM(A:B!AF21) -> 0 | ... AJ21: =SUM(A:B!AJ21) -> 0 | AK21: =SUM(Y21:AJ21) -> 0 | AL21: =AK21/AK$6 -> 0 | AM21: =IFERROR(AK21/V21-1,0) -> -1
I22: SOBRANTE DIESEL | J22: =SUM(A:B!J22) -> -59339 | K22: =SUM(A:B!K22) -> -93897 | L22: =SUM(A:B!L22) -> -118699 | M22: =SUM(A:B!M22) -> -121515 | N22: =SUM(A:B!N22) -> -185372 | O22: =SUM(A:B!O22) -> -209250 | P22: =SUM(A:B!P22) -> -242095 | Q22: =SUM(A:B!Q22) -> -81498 | ... U22: =SUM(A:B!U22) -> 0 | V22: =SUM(J22:U22) -> -1515930 | W22: =V22/V$6 -> -0.0016915767 | Y22: =SUM(A:B!Y22) -> 0 | Z22: =SUM(A:B!Z22) -> 0 | AA22: =SUM(A:B!AA22) -> 0 | AB22: =SUM(A:B!AB22) -> 0 | AC22: =SUM(A:B!AC22) -> 0 | AD22: =SUM(A:B!AD22) -> 0 | AE22: =SUM(A:B!AE22) -> 0 | AF22: =SUM(A:B!AF22) -> 0 | ... AJ22: =SUM(A:B!AJ22) -> 0 | AK22: =SUM(Y22:AJ22) -> 0 | AL22: =AK22/AK$6 -> 0 | AM22: =IFERROR(AK22/V22-1,0) -> -1
A23: B - COSTO DE VENTA | C23: ADITIVO PARA GASOLINA TMAXIMA (REGULAR) | D23: ADITIVO PARA GASOLINA TMAXIMA( REGULAR) | I23: ADITIVO TOTAL POWER GASOLINA REG | J23: =SUM(A:B!J23) -> 110309 | K23: =SUM(A:B!K23) -> 183033 | L23: =SUM(A:B!L23) -> 118902 | M23: =SUM(A:B!M23) -> 491588 | N23: =SUM(A:B!N23) -> -240501 | O23: =SUM(A:B!O23) -> 129867 | P23: =SUM(A:B!P23) -> 132184 | Q23: =SUM(A:B!Q23) -> 108896 | ... U23: =SUM(A:B!U23) -> 0 | V23: =SUM(J23:U23) -> 1273002 | W23: =V23/V$6 -> 0.0014205013 | Y23: =SUM(A:B!Y23) -> 0 | Z23: =SUM(A:B!Z23) -> 0 | AA23: =SUM(A:B!AA23) -> 0 | AB23: =SUM(A:B!AB23) -> 0 | AC23: =SUM(A:B!AC23) -> 0 | AD23: =SUM(A:B!AD23) -> 0 | AE23: =SUM(A:B!AE23) -> 0 | AF23: =SUM(A:B!AF23) -> 0 | ... AJ23: =SUM(A:B!AJ23) -> 0 | AK23: =SUM(Y23:AJ23) -> 0 | AL23: =AK23/AK$6 -> 0 | AM23: =IFERROR(AK23/V23-1,0) -> -1
A24: B - COSTO DE VENTA | C24: ADITIVO PARA GASOLINA TSUPER (PREMIUM) | I24: ADITIVO TOTAL POWER GASOLINA PREM | J24: =SUM(A:B!J24) -> 10018 | K24: =SUM(A:B!K24) -> 20216 | L24: =SUM(A:B!L24) -> 12073 | M24: =SUM(A:B!M24) -> 11105 | N24: =SUM(A:B!N24) -> 12892 | O24: =SUM(A:B!O24) -> 14241 | P24: =SUM(A:B!P24) -> 14417 | Q24: =SUM(A:B!Q24) -> 3951 | ... U24: =SUM(A:B!U24) -> 0 | V24: =SUM(J24:U24) -> 125941 | W24: =V24/V$6 -> 0.00014053345 | Y24: =SUM(A:B!Y24) -> 0 | Z24: =SUM(A:B!Z24) -> 0 | AA24: =SUM(A:B!AA24) -> 0 | AB24: =SUM(A:B!AB24) -> 0 | AC24: =SUM(A:B!AC24) -> 0 | AD24: =SUM(A:B!AD24) -> 0 | AE24: =SUM(A:B!AE24) -> 0 | AF24: =SUM(A:B!AF24) -> 0 | ... AJ24: =SUM(A:B!AJ24) -> 0 | AK24: =SUM(Y24:AJ24) -> 0 | AL24: =AK24/AK$6 -> 0 | AM24: =IFERROR(AK24/V24-1,0) -> -1
A25: B - COSTO DE VENTA | C25: FLETE MAGNA | I25: FLETE GASOLINA REGULAR | J25: =SUM(A:B!J25) -> 0 | K25: =SUM(A:B!K25) -> 0 | L25: =SUM(A:B!L25) -> 0 | M25: =SUM(A:B!M25) -> 0 | N25: =SUM(A:B!N25) -> 1841 | O25: =SUM(A:B!O25) -> 0 | P25: =SUM(A:B!P25) -> 0 | Q25: =SUM(A:B!Q25) -> 916 | ... U25: =SUM(A:B!U25) -> 0 | V25: =SUM(J25:U25) -> 2757 | W25: =V25/V$6 -> 3.0764462e-06 | Y25: =SUM(A:B!Y25) -> 0 | Z25: =SUM(A:B!Z25) -> 0 | AA25: =SUM(A:B!AA25) -> 0 | AB25: =SUM(A:B!AB25) -> 0 | AC25: =SUM(A:B!AC25) -> 0 | AD25: =SUM(A:B!AD25) -> 0 | AE25: =SUM(A:B!AE25) -> 0 | AF25: =SUM(A:B!AF25) -> 0 | ... AJ25: =SUM(A:B!AJ25) -> 0 | AK25: =SUM(Y25:AJ25) -> 0 | AL25: =AK25/AK$6 -> 0 | AM25: =IFERROR(AK25/V25-1,0) -> -1
A26: B - COSTO DE VENTA | C26: FLETE PREMIUM | I26: FLETE GASOLINA PREMIUM | J26: =SUM(A:B!J26) -> 0 | K26: =SUM(A:B!K26) -> 0 | L26: =SUM(A:B!L26) -> 0 | M26: =SUM(A:B!M26) -> 0 | N26: =SUM(A:B!N26) -> 0 | O26: =SUM(A:B!O26) -> 0 | P26: =SUM(A:B!P26) -> 0 | Q26: =SUM(A:B!Q26) -> 0 | ... U26: =SUM(A:B!U26) -> 0 | V26: =SUM(J26:U26) -> 0 | W26: =V26/V$6 -> 0 | Y26: =SUM(A:B!Y26) -> 0 | Z26: =SUM(A:B!Z26) -> 0 | AA26: =SUM(A:B!AA26) -> 0 | AB26: =SUM(A:B!AB26) -> 0 | AC26: =SUM(A:B!AC26) -> 0 | AD26: =SUM(A:B!AD26) -> 0 | AE26: =SUM(A:B!AE26) -> 0 | AF26: =SUM(A:B!AF26) -> 0 | ... AJ26: =SUM(A:B!AJ26) -> 0 | AK26: =SUM(Y26:AJ26) -> 0 | AL26: =AK26/AK$6 -> 0 | AM26: =IFERROR(AK26/V26-1,0) -> 0
A27: B - COSTO DE VENTA | C27: FLETE DIESEL | I27: FLETE DIESEL | J27: =SUM(A:B!J27) -> 0 | K27: =SUM(A:B!K27) -> 0 | L27: =SUM(A:B!L27) -> 0 | M27: =SUM(A:B!M27) -> 0 | N27: =SUM(A:B!N27) -> 0 | O27: =SUM(A:B!O27) -> 0 | P27: =SUM(A:B!P27) -> 0 | Q27: =SUM(A:B!Q27) -> 0 | ... U27: =SUM(A:B!U27) -> 0 | V27: =SUM(J27:U27) -> 0 | W27: =V27/V$6 -> 0 | Y27: =SUM(A:B!Y27) -> 0 | Z27: =SUM(A:B!Z27) -> 0 | AA27: =SUM(A:B!AA27) -> 0 | AB27: =SUM(A:B!AB27) -> 0 | AC27: =SUM(A:B!AC27) -> 0 | AD27: =SUM(A:B!AD27) -> 0 | AE27: =SUM(A:B!AE27) -> 0 | AF27: =SUM(A:B!AF27) -> 0 | ... AJ27: =SUM(A:B!AJ27) -> 0 | AK27: =SUM(Y27:AJ27) -> 0 | AL27: =AK27/AK$6 -> 0 | AM27: =IFERROR(AK27/V27-1,0) -> 0
A28: B - COSTO DE VENTA | C28: Estimulo IEPS Magna | D28: INGRESOS FORANEOS MAGNA | I28: ESTIMULO REGULAR | J28: =SUM(A:B!J28) -> -9895352 | K28: =SUM(A:B!K28) -> -9741490 | L28: =SUM(A:B!L28) -> -10698216 | M28: =SUM(A:B!M28) -> -10091896 | N28: =SUM(A:B!N28) -> -11479619 | O28: =SUM(A:B!O28) -> -11206376 | P28: =SUM(A:B!P28) -> -11021279 | Q28: =SUM(A:B!Q28) -> -10539195 | ... U28: =SUM(A:B!U28) -> 0 | V28: =SUM(J28:U28) -> -104718341 | W28: =V28/V$6 -> -0.11685177 | Y28: =SUM(A:B!Y28) -> 0 | Z28: =SUM(A:B!Z28) -> 0 | AA28: =SUM(A:B!AA28) -> 0 | AB28: =SUM(A:B!AB28) -> 0 | AC28: =SUM(A:B!AC28) -> 0 | AD28: =SUM(A:B!AD28) -> 0 | AE28: =SUM(A:B!AE28) -> 0 | AF28: =SUM(A:B!AF28) -> 0 | ... AJ28: =SUM(A:B!AJ28) -> 0 | AK28: =SUM(Y28:AJ28) -> 0 | AL28: =AK28/AK$6 -> 0 | AM28: =IFERROR(AK28/V28-1,0) -> -1
A29: B - COSTO DE VENTA | C29: Estimulo IEPS Premium | D29: INGRESOS FORANEOS MAGNA | I29: ESTIMULO PREMIUM | J29: =SUM(A:B!J29) -> -775258 | K29: =SUM(A:B!K29) -> -798009 | L29: =SUM(A:B!L29) -> -878327 | M29: =SUM(A:B!M29) -> -837300 | N29: =SUM(A:B!N29) -> -954984 | O29: =SUM(A:B!O29) -> -999309 | P29: =SUM(A:B!P29) -> -956207 | Q29: =SUM(A:B!Q29) -> -675074 | ... U29: =SUM(A:B!U29) -> 0 | V29: =SUM(J29:U29) -> -8579690 | W29: =V29/V$6 -> -0.0095737957 | Y29: =SUM(A:B!Y29) -> 0 | Z29: =SUM(A:B!Z29) -> 0 | AA29: =SUM(A:B!AA29) -> 0 | AB29: =SUM(A:B!AB29) -> 0 | AC29: =SUM(A:B!AC29) -> 0 | AD29: =SUM(A:B!AD29) -> 0 | AE29: =SUM(A:B!AE29) -> 0 | AF29: =SUM(A:B!AF29) -> 0 | ... AJ29: =SUM(A:B!AJ29) -> 0 | AK29: =SUM(Y29:AJ29) -> 0 | AL29: =AK29/AK$6 -> 0 | AM29: =IFERROR(AK29/V29-1,0) -> -1
I30: COSTO ACEITES Y LUBRICANTES | J30: =SUM(A:B!J30) -> 53854 | K30: =SUM(A:B!K30) -> 41012 | L30: =SUM(A:B!L30) -> 46457 | M30: =SUM(A:B!M30) -> 48504 | N30: =SUM(A:B!N30) -> 50623 | O30: =SUM(A:B!O30) -> 49511 | P30: =SUM(A:B!P30) -> 44553 | Q30: =SUM(A:B!Q30) -> 45156 | ... U30: =SUM(A:B!U30) -> 56799.72 | V30: =SUM(J30:U30) -> 599655.58 | W30: =V30/V$6 -> 0.00066913607 | Y30: =SUM(A:B!Y30) -> 63444 | Z30: =SUM(A:B!Z30) -> 61200 | AA30: =SUM(A:B!AA30) -> 81141 | AB30: =SUM(A:B!AB30) -> 59262 | AC30: =SUM(A:B!AC30) -> 64413 | AD30: =SUM(A:B!AD30) -> 60435 | AE30: =SUM(A:B!AE30) -> 60945 | AF30: =SUM(A:B!AF30) -> 58293 | ... AJ30: =SUM(A:B!AJ30) -> 64821 | AK30: =SUM(Y30:AJ30) -> 764541 | AL30: =AK30/AK$6 -> 0.00079376894 | AM30: =IFERROR(AK30/V30-1,0) -> 0.27496687
I31: BONIFICACION COMPRA DE COMBUSTIBLE MAGNA | J31: =SUM(A:B!J31) -> 0 | K31: =SUM(A:B!K31) -> 0 | L31: =SUM(A:B!L31) -> 0 | M31: =SUM(A:B!M31) -> 0 | N31: =SUM(A:B!N31) -> 0 | O31: =SUM(A:B!O31) -> 0 | P31: =SUM(A:B!P31) -> 0 | Q31: =SUM(A:B!Q31) -> 0 | ... U31: =SUM(A:B!U31) -> 0 | V31: =SUM(J31:U31) -> 0 | W31: =V31/V$6 -> 0 | Y31: =SUM(A:B!Y31) -> 0 | Z31: =SUM(A:B!Z31) -> 0 | AA31: =SUM(A:B!AA31) -> 0 | AB31: =SUM(A:B!AB31) -> 0 | AC31: =SUM(A:B!AC31) -> 0 | AD31: =SUM(A:B!AD31) -> 0 | AE31: =SUM(A:B!AE31) -> 0 | AF31: =SUM(A:B!AF31) -> 0 | ... AJ31: =SUM(A:B!AJ31) -> 0 | AK31: =SUM(Y31:AJ31) -> 0 | AL31: =AK31/AK$6 -> 0 | AM31: =IFERROR(AK31/V31-1,0) -> 0
I32: BONIFICACION COMPRA DE COMBUSTIBLE PREMIUM | J32: =SUM(A:B!J32) -> 0 | K32: =SUM(A:B!K32) -> 0 | L32: =SUM(A:B!L32) -> 0 | M32: =SUM(A:B!M32) -> 0 | N32: =SUM(A:B!N32) -> 0 | O32: =SUM(A:B!O32) -> 0 | P32: =SUM(A:B!P32) -> 0 | Q32: =SUM(A:B!Q32) -> 0 | ... U32: =SUM(A:B!U32) -> 0 | V32: =SUM(J32:U32) -> 0 | W32: =V32/V$6 -> 0 | Y32: =SUM(A:B!Y32) -> 0 | Z32: =SUM(A:B!Z32) -> 0 | AA32: =SUM(A:B!AA32) -> 0 | AB32: =SUM(A:B!AB32) -> 0 | AC32: =SUM(A:B!AC32) -> 0 | AD32: =SUM(A:B!AD32) -> 0 | AE32: =SUM(A:B!AE32) -> 0 | AF32: =SUM(A:B!AF32) -> 0 | ... AJ32: =SUM(A:B!AJ32) -> 0 | AK32: =SUM(Y32:AJ32) -> 0 | AL32: =AK32/AK$6 -> 0 | AM32: =IFERROR(AK32/V32-1,0) -> 0
I33: BONIFICACION COMPRA DE COMBUSTIBLE DIESEL | J33: =SUM(A:B!J33) -> 0 | K33: =SUM(A:B!K33) -> 0 | L33: =SUM(A:B!L33) -> 0 | M33: =SUM(A:B!M33) -> 0 | N33: =SUM(A:B!N33) -> 0 | O33: =SUM(A:B!O33) -> 0 | P33: =SUM(A:B!P33) -> 0 | Q33: =SUM(A:B!Q33) -> 0 | ... U33: =SUM(A:B!U33) -> 0 | V33: =SUM(J33:U33) -> 0 | W33: =V33/V$6 -> 0 | Y33: =SUM(A:B!Y33) -> 0 | Z33: =SUM(A:B!Z33) -> 0 | AA33: =SUM(A:B!AA33) -> 0 | AB33: =SUM(A:B!AB33) -> 0 | AC33: =SUM(A:B!AC33) -> 0 | AD33: =SUM(A:B!AD33) -> 0 | AE33: =SUM(A:B!AE33) -> 0 | AF33: =SUM(A:B!AF33) -> 0 | ... AJ33: =SUM(A:B!AJ33) -> 0 | AK33: =SUM(Y33:AJ33) -> 0 | AL33: =AK33/AK$6 -> 0 | AM33: =IFERROR(AK33/V33-1,0) -> 0
I34: MARGEN DE UTILIDAD | J34: =J6-J13 -> 9669373 | K34: =K6-K13 -> 10402424 | L34: =L6-L13 -> 10631948 | M34: =M6-M13 -> 10175079 | N34: =N6-N13 -> 12471677 | O34: =O6-O13 -> 10899375 | P34: =P6-P13 -> 10241103 | Q34: =Q6-Q13 -> 9298189 | ... V34: =V6-V13 -> 1.282389e+08 | W34: =V34/V$6 -> 0.1430976 | Y34: =Y6-Y13 -> 9567238.4 | Z34: =Z6-Z13 -> 9309837 | AA34: =AA6-AA13 -> 10644012 | AB34: =AB6-AB13 -> 9460298.8 | AC34: =AC6-AC13 -> 11557010 | AD34: =AD6-AD13 -> 10797115 | AE34: =AE6-AE13 -> 10656189 | AF34: =AF6-AF13 -> 10997032 | ... AK34: =AK6-AK13 -> 1.2430013e+08 | AL34: =AK34/AK$6 -> 0.12905205 | AM34: =IFERROR(AK34/V34-1,0) -> -0.03071433
I35: *Regular | J35: =SUM(A:B!J35) -> 7104474 | K35: =SUM(A:B!K35) -> 8071504 | L35: =SUM(A:B!L35) -> 7943183 | M35: =SUM(A:B!M35) -> 7764090 | N35: =SUM(A:B!N35) -> 9629979 | O35: =SUM(A:B!O35) -> 8207647 | P35: =SUM(A:B!P35) -> 7712661 | Q35: =SUM(A:B!Q35) -> 7297471 | ... U35: =SUM(A:B!U35) -> 8363594.4 | V35: =SUM(J35:U35) -> 97185386 | W35: =V35/V$39 -> 2.0333925 | Y35: =SUM(A:B!Y35) -> 7411184.1 | Z35: =SUM(A:B!Z35) -> 7234815.7 | AA35: =SUM(A:B!AA35) -> 8316678.4 | AB35: =SUM(A:B!AB35) -> 7358119.8 | AC35: =SUM(A:B!AC35) -> 9150006.6 | AD35: =SUM(A:B!AD35) -> 8356810.8 | AE35: =SUM(A:B!AE35) -> 8232972 | AF35: =SUM(A:B!AF35) -> 8715834.2 | ... AJ35: =SUM(A:B!AJ35) -> 7528052.6 | AK35: =SUM(Y35:AJ35) -> 97100144 | AL35: =AK35/AK$39 -> 1.9585461 | AM35: =IFERROR(AK35/V35-1,0) -> -0.00087711419
I36: *Premium | J36: =SUM(A:B!J36) -> 813291 | K36: =SUM(A:B!K36) -> 929738 | L36: =SUM(A:B!L36) -> 1096634 | M36: =SUM(A:B!M36) -> 1046417 | N36: =SUM(A:B!N36) -> 1174426 | O36: =SUM(A:B!O36) -> 1161608 | P36: =SUM(A:B!P36) -> 984047 | Q36: =SUM(A:B!Q36) -> 581170 | ... U36: =SUM(A:B!U36) -> 775550.78 | V36: =SUM(J36:U36) -> 10889534 | W36: =V36/V$39 -> 0.22783978 | Y36: =SUM(A:B!Y36) -> 701224.92 | Z36: =SUM(A:B!Z36) -> 720412.16 | AA36: =SUM(A:B!AA36) -> 819315.89 | AB36: =SUM(A:B!AB36) -> 754550.32 | AC36: =SUM(A:B!AC36) -> 871028.95 | AD36: =SUM(A:B!AD36) -> 924681.99 | AE36: =SUM(A:B!AE36) -> 851275.86 | AF36: =SUM(A:B!AF36) -> 883838.65 | ... AJ36: =SUM(A:B!AJ36) -> 732685.83 | AK36: =SUM(Y36:AJ36) -> 9703588.7 | AL36: =AK36/AK$39 -> 0.195725 | AM36: =IFERROR(AK36/V36-1,0) -> -0.1089069
I37: *Diesel | J37: =SUM(A:B!J37) -> 1749533 | K37: =SUM(A:B!K37) -> 1382005 | L37: =SUM(A:B!L37) -> 1580760 | M37: =SUM(A:B!M37) -> 1350095 | N37: =SUM(A:B!N37) -> 1651925 | O37: =SUM(A:B!O37) -> 1515260 | P37: =SUM(A:B!P37) -> 1531075 | Q37: =SUM(A:B!Q37) -> 1405577 | ... U37: =SUM(A:B!U37) -> 1493095.4 | V37: =SUM(J37:U37) -> 18138611 | W37: =V37/V$39 -> 0.37951094 | Y37: =SUM(A:B!Y37) -> 1443633.3 | Z37: =SUM(A:B!Z37) -> 1343809.2 | AA37: =SUM(A:B!AA37) -> 1493698.9 | AB37: =SUM(A:B!AB37) -> 1337170.6 | AC37: =SUM(A:B!AC37) -> 1524607.2 | AD37: =SUM(A:B!AD37) -> 1504957.2 | AE37: =SUM(A:B!AE37) -> 1561186.1 | AF37: =SUM(A:B!AF37) -> 1387071.7 | ... AJ37: =SUM(A:B!AJ37) -> 1341637.5 | AK37: =SUM(Y37:AJ37) -> 17361480 | AL37: =AK37/AK$39 -> 0.35018752 | AM37: =IFERROR(AK37/V37-1,0) -> -0.042844068
I38: * Aceites y Lubricantes | J38: =SUM(A:B!J38) -> 2073 | K38: =SUM(A:B!K38) -> 19180 | L38: =SUM(A:B!L38) -> 11371 | M38: =SUM(A:B!M38) -> 14475 | N38: =SUM(A:B!N38) -> 15343 | O38: =SUM(A:B!O38) -> 14861 | P38: =SUM(A:B!P38) -> 13316 | Q38: =SUM(A:B!Q38) -> 13972 | ... U38: =SUM(A:B!U38) -> 4184.7407 | V38: =SUM(J38:U38) -> 121329.96 | W38: =V38/V$39 -> 0.0025385652 | Y38: =SUM(A:B!Y38) -> 11196 | Z38: =SUM(A:B!Z38) -> 10800 | AA38: =SUM(A:B!AA38) -> 14319 | AB38: =SUM(A:B!AB38) -> 10458 | AC38: =SUM(A:B!AC38) -> 11367 | AD38: =SUM(A:B!AD38) -> 10665 | AE38: =SUM(A:B!AE38) -> 10755 | AF38: =SUM(A:B!AF38) -> 10287 | ... AJ38: =SUM(A:B!AJ38) -> 11439 | AK38: =SUM(Y38:AJ38) -> 134919 | AL38: =AK38/AK$39 -> 0.0027213666 | AM38: =IFERROR(AK38/V38-1,0) -> 0.11200067
I39: Litros vendidos | J39: =SUM(A:B!J39) -> 3700569 | K39: =SUM(A:B!K39) -> 3632738 | L39: =SUM(A:B!L39) -> 3988189 | M39: =SUM(A:B!M39) -> 3743720 | N39: =SUM(A:B!N39) -> 4276090 | O39: =SUM(A:B!O39) -> 4259792 | P39: =SUM(A:B!P39) -> 4201852 | Q39: =SUM(A:B!Q39) -> 3874166 | ... V39: =SUM(A:B!V39) -> 47794700 | W39: =V39/V$39 -> 1 | Y39: =SUM(A:B!Y39) -> 3821480 | Z39: =SUM(A:B!Z39) -> 3748758 | AA39: =SUM(A:B!AA39) -> 4114391 | AB39: =SUM(A:B!AB39) -> 3870153 | AC39: =SUM(A:B!AC39) -> 4414525 | AD39: =SUM(A:B!AD39) -> 4346815 | AE39: =SUM(A:B!AE39) -> 4282241 | AF39: =SUM(A:B!AF39) -> 4339623 | ... AJ39: =SUM(A:B!AJ39) -> 3925340 | AK39: =SUM(Y39:AJ39) -> 49577665 | AL39: =AK39/AK$39 -> 1 | AM39: =IFERROR(AK39/V39-1,0) -> 0.037304659 | AN39: 48793805
I40: Maxima | J40: =SUM(A:B!J40) -> 2902809 | K40: =SUM(A:B!K40) -> 2857785 | L40: =SUM(A:B!L40) -> 3134970 | M40: =SUM(A:B!M40) -> 2960554 | N40: =SUM(A:B!N40) -> 3367706 | O40: =SUM(A:B!O40) -> 3288023 | P40: =SUM(A:B!P40) -> 3234223 | Q40: =SUM(A:B!Q40) -> 3091988 | ... U40: =SUM(A:B!U40) -> 3012428 | V40: =SUM(J40:U40) -> 37433009 | W40: =V40/V$39 -> 0.78320418 | Y40: =SUM(A:B!Y40) -> 2952663 | Z40: =SUM(A:B!Z40) -> 2902741 | AA40: =SUM(A:B!AA40) -> 3197079 | AB40: =SUM(A:B!AB40) -> 3008559 | AC40: =SUM(A:B!AC40) -> 3462421 | AD40: =SUM(A:B!AD40) -> 3368996 | AE40: =SUM(A:B!AE40) -> 3306021 | AF40: =SUM(A:B!AF40) -> 3423794 | ... AJ40: =SUM(A:B!AJ40) -> 3071369 | AK40: =SUM(Y40:AJ40) -> 38635804 | AL40: =AK40/AK$39 -> 0.77929858 | AM40: =IFERROR(AK40/V40-1,0) -> 0.032131935
I41: Super | J41: =SUM(A:B!J41) -> 271069 | K41: =SUM(A:B!K41) -> 279451 | L41: =SUM(A:B!L41) -> 310795 | M41: =SUM(A:B!M41) -> 292788 | N41: =SUM(A:B!N41) -> 333910 | O41: =SUM(A:B!O41) -> 349797 | P41: =SUM(A:B!P41) -> 334339 | Q41: =SUM(A:B!Q41) -> 236040 | ... U41: =SUM(A:B!U41) -> 286641 | V41: =SUM(J41:U41) -> 3592939 | W41: =V41/V$39 -> 0.075174423 | Y41: =SUM(A:B!Y41) -> 277164 | Z41: =SUM(A:B!Z41) -> 283847 | AA41: =SUM(A:B!AA41) -> 317230 | AB41: =SUM(A:B!AB41) -> 298246 | AC41: =SUM(A:B!AC41) -> 344135 | AD41: =SUM(A:B!AD41) -> 360055 | AE41: =SUM(A:B!AE41) -> 342401 | AF41: =SUM(A:B!AF41) -> 347357 | ... AJ41: =SUM(A:B!AJ41) -> 292325 | AK41: =SUM(Y41:AJ41) -> 3832524 | AL41: =AK41/AK$39 -> 0.077303439 | AM41: =IFERROR(AK41/V41-1,0) -> 0.066682179
...

Sheet S

Sheet COM-MKT
I1: Mantenimiento de Imagen | Y1: 2 | Z1: 3 | AA1: 4 | AB1: 5 | AC1: 6 | AD1: 7 | AE1: 8 | AF1: 9 | AG1: 10 | AH1: 11 | AI1: 12 | AJ1: 13 | AM1: 17
J2: 2024 | V2: TOTAL ANUAL | Y2: 2025 | AK2: TOTAL ANUAL
J3: ENE | K3: FEB | L3: MAR | M3: ABR | N3: MAY | O3: JUN | P3: JUL | Q3: AGO | R3: SEP | S3: OCT | T3: NOV | U3: DIC | V3: 2024 | W3: % Part | Y3: ENE | Z3: FEB | AA3: MAR | AB3: ABR | AC3: MAY | AD3: JUN | AE3: JUL | AF3: AGO | AG3: SEP | AH3: OCT | AI3: NOV | AJ3: DIC | AK3: 2025 | AL3: % Part | AM3: Var vs AA%
I4: INGRESOS
A6: A - INGRESOS | E6: ( mas ) | I6: A - INGRESOS | V6: =SUM(J6:U6) -> 0 | W6: =V6/V$6 -> #DIV/0! | Y6: =SUM(Y7:Y10) -> 0 | Z6: =SUM(Z7:Z10) -> 0 | AA6: =SUM(AA7:AA10) -> 0 | AB6: =SUM(AB7:AB10) -> 0 | AC6: =SUM(AC7:AC10) -> 0 | AD6: =SUM(AD7:AD10) -> 0 | AE6: =SUM(AE7:AE10) -> 0 | AF6: =SUM(AF7:AF10) -> 0 | ... AJ6: =SUM(AJ7:AJ10) -> 0 | AK6: =SUM(Y6:AJ6) -> 0 | AL6: =AK6/AK$6 -> #DIV/0! | AM6: =IFERROR(AK6/V6-1,0) -> 0
A7: A - INGRESOS | B7: estaciones | C7: INGRESOS MAGNA | D7: INGRESOS FORANEOS MAGNA | I7: T-MAXIMA REGULAR | V7: =SUM(J7:U7) -> 0 | W7: =V7/V$6 -> #DIV/0! | Y7: 0 | Z7: 0 | AA7: 0 | AB7: 0 | AC7: 0 | AD7: 0 | AE7: 0 | AF7: 0 | AG7: 0 | AH7: 0 | AI7: 0 | AJ7: 0 | AK7: =SUM(Y7:AJ7) -> 0 | AL7: =AK7/AK$6 -> #DIV/0! | AM7: =IFERROR(AK7/V7-1,0) -> 0
A8: A - INGRESOS | B8: estaciones | C8: INGRESOS PREMIUM | D8: INGRESOS FORANEOS PREMIUM | I8: T-SUPER PREMIUM | V8: =SUM(J8:U8) -> 0 | W8: =V8/V$6 -> #DIV/0! | Y8: 0 | Z8: 0 | AA8: 0 | AB8: 0 | AC8: 0 | AD8: 0 | AE8: 0 | AF8: 0 | AG8: 0 | AH8: 0 | AI8: 0 | AJ8: 0 | AK8: =SUM(Y8:AJ8) -> 0 | AL8: =AK8/AK$6 -> #DIV/0! | AM8: =IFERROR(AK8/V8-1,0) -> 0
A9: A - INGRESOS | B9: estaciones | C9: INGRESOS DIESEL | D9: INGRESOS FORANEOS DIESEL | I9: DIESEL AUTOMOTRIZ | V9: =SUM(J9:U9) -> 0 | W9: =V9/V$6 -> #DIV/0! | Y9: 0 | Z9: 0 | AA9: 0 | AB9: 0 | AC9: 0 | AD9: 0 | AE9: 0 | AF9: 0 | AG9: 0 | AH9: 0 | AI9: 0 | AJ9: 0 | AK9: =SUM(Y9:AJ9) -> 0 | AL9: =AK9/AK$6 -> #DIV/0! | AM9: =IFERROR(AK9/V9-1,0) -> 0
A10: A - INGRESOS | B10: estaciones | C10: INGRESOS ADITIVOS | D10: INGRESOS ESPECIALES | F10: INGRESOS FORANEOS ESPECIALES | G10: INGRESOS FORANEOS LUBRICANTES | H10: INGRESOS LUBRICANTES | I10: PREPAGO facturación (neto) | V10: =SUM(J10:U10) -> 0 | W10: =V10/V$6 -> #DIV/0! | Y10: 0 | Z10: 0 | AA10: 0 | AB10: 0 | AC10: 0 | AD10: 0 | AE10: 0 | AF10: 0 | AG10: 0 | AH10: 0 | AI10: 0 | AJ10: 0 | AK10: =SUM(Y10:AJ10) -> 0 | AL10: =AK10/AK$6 -> #DIV/0! | AM10: =IFERROR(AK10/V10-1,0) -> 0
A11: A - INGRESOS | B11: estaciones | C11: INGRESOS ADITIVOS | D11: INGRESOS ESPECIALES | E11: INGRESOS FORANEOS ADITIVOS | F11: INGRESOS FORANEOS ESPECIALES | G11: INGRESOS FORANEOS LUBRICANTES | H11: INGRESOS LUBRICANTES | I11: INGRESOS ACEITES Y LUBRICANTES | V11: =SUM(J11:U11) -> 0 | W11: =V11/V$6 -> #DIV/0! | Y11: 0 | Z11: 0 | AA11: 0 | AB11: 0 | AC11: 0 | AD11: 0 | AE11: 0 | AF11: 0 | AG11: 0 | AH11: 0 | AI11: 0 | AJ11: 0 | AK11: =SUM(Y11:AJ11) -> 0 | AL11: =AK11/AK$6 -> #DIV/0! | AM11: =IFERROR(AK11/V11-1,0) -> 0
I12: SOBRANTE REGULAR
I13: SOBRANTE PREMIUM
I14: SOBRANTE DIESEL
A15: B - COSTO DE VENTA | E15: ( menos ) | I15: B - COSTO DE VENTA | V15: =SUM(J15:U15) -> 0 | W15: =V15/V$6 -> #DIV/0! | Y15: =SUM(Y16:Y31) -> 0 | Z15: =SUM(Z16:Z31) -> 0 | AA15: =SUM(AA16:AA31) -> 0 | AB15: =SUM(AB16:AB31) -> 0 | AC15: =SUM(AC16:AC31) -> 0 | AD15: =SUM(AD16:AD31) -> 0 | AE15: =SUM(AE16:AE31) -> 0 | AF15: =SUM(AF16:AF31) -> 0 | ... AJ15: =SUM(AJ16:AJ31) -> 0 | AK15: =SUM(Y15:AJ15) -> 0 | AL15: =AK15/AK$6 -> #DIV/0! | AM15: =IFERROR(AK15/V15-1,0) -> 0
A16: B - COSTO DE VENTA | C16: COSTO MAGNA | D16: COSTO FORANEO MAGNA | I16: GASOLINA REGULAR | V16: =SUM(J16:U16) -> 0 | W16: =V16/V$6 -> #DIV/0! | Y16: 0 | Z16: 0 | AA16: 0 | AB16: 0 | AC16: 0 | AD16: 0 | AE16: 0 | AF16: 0 | AG16: 0 | AH16: 0 | AI16: 0 | AJ16: 0 | AK16: =SUM(Y16:AJ16) -> 0 | AL16: =AK16/AK$6 -> #DIV/0! | AM16: =IFERROR(AK16/V16-1,0) -> 0
A17: B - COSTO DE VENTA | C17: COSTO PREMIUM | D17: COSTO FORANEO PREMIUM | I17: GASOLINA PREMIUM | V17: =SUM(J17:U17) -> 0 | W17: =V17/V$6 -> #DIV/0! | Y17: 0 | Z17: 0 | AA17: 0 | AB17: 0 | AC17: 0 | AD17: 0 | AE17: 0 | AF17: 0 | AG17: 0 | AH17: 0 | AI17: 0 | AJ17: 0 | AK17: =SUM(Y17:AJ17) -> 0 | AL17: =AK17/AK$6 -> #DIV/0! | AM17: =IFERROR(AK17/V17-1,0) -> 0
A18: B - COSTO DE VENTA | C18: COSTO DIESEL | D18: COSTO FORANEO DIESEL | I18: DIESEL | V18: =SUM(J18:U18) -> 0 | W18: =V18/V$6 -> #DIV/0! | Y18: 0 | Z18: 0 | AA18: 0 | AB18: 0 | AC18: 0 | AD18: 0 | AE18: 0 | AF18: 0 | AG18: 0 | AH18: 0 | AI18: 0 | AJ18: 0 | AK18: =SUM(Y18:AJ18) -> 0 | AL18: =AK18/AK$6 -> #DIV/0! | AM18: =IFERROR(AK18/V18-1,0) -> 0
A19: B - COSTO DE VENTA | C19: Merma Magna | I19: MERMA GASOLINA REGULAR | V19: =SUM(J19:U19) -> 0 | W19: =V19/V$6 -> #DIV/0! | Y19: 0 | Z19: 0 | AA19: 0 | AB19: 0 | AC19: 0 | AD19: 0 | AE19: 0 | AF19: 0 | AG19: 0 | AH19: 0 | AI19: 0 | AJ19: 0 | AK19: =SUM(Y19:AJ19) -> 0 | AL19: =AK19/AK$6 -> #DIV/0! | AM19: =IFERROR(AK19/V19-1,0) -> 0
A20: B - COSTO DE VENTA | C20: Merma Premium | I20: MERMA GASOLINA PREMIUM | V20: =SUM(J20:U20) -> 0 | W20: =V20/V$6 -> #DIV/0! | Y20: 0 | Z20: 0 | AA20: 0 | AB20: 0 | AC20: 0 | AD20: 0 | AE20: 0 | AF20: 0 | AG20: 0 | AH20: 0 | AI20: 0 | AJ20: 0 | AK20: =SUM(Y20:AJ20) -> 0 | AL20: =AK20/AK$6 -> #DIV/0! | AM20: =IFERROR(AK20/V20-1,0) -> 0
A21: B - COSTO DE VENTA | C21: Merma Diesel | I21: MERMA DIESEL | V21: =SUM(J21:U21) -> 0 | W21: =V21/V$6 -> #DIV/0! | Y21: 0 | Z21: 0 | AA21: 0 | AB21: 0 | AC21: 0 | AD21: 0 | AE21: 0 | AF21: 0 | AG21: 0 | AH21: 0 | AI21: 0 | AJ21: 0 | AK21: =SUM(Y21:AJ21) -> 0 | AL21: =AK21/AK$6 -> #DIV/0! | AM21: =IFERROR(AK21/V21-1,0) -> 0
A22: B - COSTO DE VENTA | C22: ADITIVO PARA GASOLINA TMAXIMA (REGULAR) | D22: ADITIVO PARA GASOLINA TMAXIMA( REGULAR) | I22: ADITIVO TOTAL POWER GASOLINA REG | V22: =SUM(J22:U22) -> 0 | W22: =V22/V$6 -> #DIV/0! | Y22: 0 | Z22: 0 | AA22: 0 | AB22: 0 | AC22: 0 | AD22: 0 | AE22: 0 | AF22: 0 | AG22: 0 | AH22: 0 | AI22: 0 | AJ22: 0 | AK22: =SUM(Y22:AJ22) -> 0 | AL22: =AK22/AK$6 -> #DIV/0! | AM22: =IFERROR(AK22/V22-1,0) -> 0
A23: B - COSTO DE VENTA | C23: ADITIVO PARA GASOLINA TSUPER (PREMIUM) | I23: ADITIVO TOTAL POWER GASOLINA PREM | V23: =SUM(J23:U23) -> 0 | W23: =V23/V$6 -> #DIV/0! | Y23: 0 | Z23: 0 | AA23: 0 | AB23: 0 | AC23: 0 | AD23: 0 | AE23: 0 | AF23: 0 | AG23: 0 | AH23: 0 | AI23: 0 | AJ23: 0 | AK23: =SUM(Y23:AJ23) -> 0 | AL23: =AK23/AK$6 -> #DIV/0! | AM23: =IFERROR(AK23/V23-1,0) -> 0
A24: B - COSTO DE VENTA | C24: FLETE MAGNA | I24: FLETE GASOLINA REGULAR | V24: =SUM(J24:U24) -> 0 | W24: =V24/V$6 -> #DIV/0! | Y24: 0 | Z24: 0 | AA24: 0 | AB24: 0 | AC24: 0 | AD24: 0 | AE24: 0 | AF24: 0 | AG24: 0 | AH24: 0 | AI24: 0 | AJ24: 0 | AK24: =SUM(Y24:AJ24) -> 0 | AL24: =AK24/AK$6 -> #DIV/0! | AM24: =IFERROR(AK24/V24-1,0) -> 0
A25: B - COSTO DE VENTA | C25: FLETE PREMIUM | I25: FLETE GASOLINA PREMIUM | V25: =SUM(J25:U25) -> 0 | W25: =V25/V$6 -> #DIV/0! | Y25: 0 | Z25: 0 | AA25: 0 | AB25: 0 | AC25: 0 | AD25: 0 | AE25: 0 | AF25: 0 | AG25: 0 | AH25: 0 | AI25: 0 | AJ25: 0 | AK25: =SUM(Y25:AJ25) -> 0 | AL25: =AK25/AK$6 -> #DIV/0! | AM25: =IFERROR(AK25/V25-1,0) -> 0
A26: B - COSTO DE VENTA | C26: FLETE DIESEL | I26: FLETE DIESEL | V26: =SUM(J26:U26) -> 0 | W26: =V26/V$6 -> #DIV/0! | Y26: 0 | Z26: 0 | AA26: 0 | AB26: 0 | AC26: 0 | AD26: 0 | AE26: 0 | AF26: 0 | AG26: 0 | AH26: 0 | AI26: 0 | AJ26: 0 | AK26: =SUM(Y26:AJ26) -> 0 | AL26: =AK26/AK$6 -> #DIV/0! | AM26: =IFERROR(AK26/V26-1,0) -> 0
A27: B - COSTO DE VENTA | C27: Estimulo IEPS Magna | D27: INGRESOS FORANEOS MAGNA | I27: ESTIMULO REGULAR | V27: =SUM(J27:U27) -> 0 | W27: =V27/V$6 -> #DIV/0! | Y27: 0 | Z27: 0 | AA27: 0 | AB27: 0 | AC27: 0 | AD27: 0 | AE27: 0 | AF27: 0 | AG27: 0 | AH27: 0 | AI27: 0 | AJ27: 0 | AK27: =SUM(Y27:AJ27) -> 0 | AL27: =AK27/AK$6 -> #DIV/0! | AM27: =IFERROR(AK27/V27-1,0) -> 0
A28: B - COSTO DE VENTA | C28: Estimulo IEPS Premium | D28: INGRESOS FORANEOS MAGNA | I28: ESTIMULO PREMIUM | V28: =SUM(J28:U28) -> 0 | W28: =V28/V$6 -> #DIV/0! | Y28: 0 | Z28: 0 | AA28: 0 | AB28: 0 | AC28: 0 | AD28: 0 | AE28: 0 | AF28: 0 | AG28: 0 | AH28: 0 | AI28: 0 | AJ28: 0 | AK28: =SUM(Y28:AJ28) -> 0 | AL28: =AK28/AK$6 -> #DIV/0! | AM28: =IFERROR(AK28/V28-1,0) -> 0
I29: DESCUENTO SOBRE VENTA
I30: COSTO UNIFORMES
I31: COSTO ACEITES Y LUBRICANTES | V31: =SUM(J31:U31) -> 0 | W31: =V31/V$6 -> #DIV/0! | Y31: 0 | Z31: 0 | AA31: 0 | AB31: 0 | AC31: 0 | AD31: 0 | AE31: 0 | AF31: 0 | AG31: 0 | AH31: 0 | AI31: 0 | AJ31: 0 | AK31: =SUM(Y31:AJ31) -> 0 | AL31: =AK31/AK$6 -> #DIV/0! | AM31: =IFERROR(AK31/V31-1,0) -> 0
I32: MARGEN DE UTILIDAD | V32: =V6-V15 -> 0 | W32: =V32/V$6 -> #DIV/0! | Y32: =Y6-Y15 -> 0 | Z32: =Z6-Z15 -> 0 | AA32: =AA6-AA15 -> 0 | AB32: =AB6-AB15 -> 0 | AC32: =AC6-AC15 -> 0 | AD32: =AD6-AD15 -> 0 | AE32: =AE6-AE15 -> 0 | AF32: =AF6-AF15 -> 0 | ... AK32: =AK6-AK15 -> 0 | AL32: =AK32/AK$6 -> #DIV/0! | AM32: =IFERROR(AK32/V32-1,0) -> 0
I33: Regular | V33: =SUM(J33:U33) -> 0 | Y33: =+Y43*Y39 -> 0 | Z33: =+Z43*Z39 -> 0 | AA33: =+AA43*AA39 -> 0 | AB33: =+AB43*AB39 -> 0 | AC33: =+AC43*AC39 -> 0 | AD33: =+AD43*AD39 -> 0 | AE33: =+AE43*AE39 -> 0 | AF33: =+AF43*AF39 -> 0 | ... AJ33: =+AJ43*AJ39 -> 0 | AK33: =SUM(Y33:AJ33) -> 0 | AM33: =IFERROR(AK33/V33-1,0) -> 0
I34: Premium | V34: =SUM(J34:U34) -> 0 | Y34: =+Y44*Y40 -> 0 | Z34: =+Z44*Z40 -> 0 | AA34: =+AA44*AA40 -> 0 | AB34: =+AB44*AB40 -> 0 | AC34: =+AC44*AC40 -> 0 | AD34: =+AD44*AD40 -> 0 | AE34: =+AE44*AE40 -> 0 | AF34: =+AF44*AF40 -> 0 | ... AJ34: =+AJ44*AJ40 -> 0 | AK34: =SUM(Y34:AJ34) -> 0 | AM34: =IFERROR(AK34/V34-1,0) -> 0
I35: Diesel | V35: =SUM(J35:U35) -> 0 | Y35: =+Y45*Y41 -> 0 | Z35: =+Z45*Z41 -> 0 | AA35: =+AA45*AA41 -> 0 | AB35: =+AB45*AB41 -> 0 | AC35: =+AC45*AC41 -> 0 | AD35: =+AD45*AD41 -> 0 | AE35: =+AE45*AE41 -> 0 | AF35: =+AF45*AF41 -> 0 | ... AJ35: =+AJ45*AJ41 -> 0 | AK35: =SUM(Y35:AJ35) -> 0 | AM35: =IFERROR(AK35/V35-1,0) -> 0
I36: *Otros Conceptos
I37: * Aceites y Lubricantes
I38: Litros vendidos | V38: =SUM(J38:U38) -> 0 | W38: =V38/V$38 -> #DIV/0! | Y38: =SUM(Y39:Y41) -> 0 | Z38: =SUM(Z39:Z41) -> 0 | AA38: =SUM(AA39:AA41) -> 0 | AB38: =SUM(AB39:AB41) -> 0 | AC38: =SUM(AC39:AC41) -> 0 | AD38: =SUM(AD39:AD41) -> 0 | AE38: =SUM(AE39:AE41) -> 0 | AF38: =SUM(AF39:AF41) -> 0 | ... AJ38: =SUM(AJ39:AJ41) -> 0 | AK38: =SUM(Y38:AJ38) -> 0 | AL38: =AK38/AK$38 -> #DIV/0! | AM38: =IFERROR(AK38/V38-1,0) -> 0
I39: Regular | V39: =SUM(J39:U39) -> 0 | W39: =V39/V$38 -> #DIV/0! | Y39: 0 | Z39: 0 | AA39: 0 | AB39: 0 | AC39: 0 | AD39: 0 | AE39: 0 | AF39: 0 | AG39: 0 | AH39: 0 | AI39: 0 | AJ39: 0 | AK39: =SUM(Y39:AJ39) -> 0 | AL39: =AK39/AK$38 -> #DIV/0! | AM39: =IFERROR(AK39/V39-1,0) -> 0
I40: Premium | V40: =SUM(J40:U40) -> 0 | W40: =V40/V$38 -> #DIV/0! | Y40: 0 | Z40: 0 | AA40: 0 | AB40: 0 | AC40: 0 | AD40: 0 | AE40: 0 | AF40: 0 | AG40: 0 | AH40: 0 | AI40: 0 | AJ40: 0 | AK40: =SUM(Y40:AJ40) -> 0 | AL40: =AK40/AK$38 -> #DIV/0! | AM40: =IFERROR(AK40/V40-1,0) -> 0
I41: Diesel | V41: =SUM(J41:U41) -> 0 | W41: =V41/V$38 -> #DIV/0! | Y41: 0 | Z41: 0 | AA41: 0 | AB41: 0 | AC41: 0 | AD41: 0 | AE41: 0 | AF41: 0 | AG41: 0 | AH41: 0 | AI41: 0 | AJ41: 0 | AK41: =SUM(Y41:AJ41) -> 0 | AL41: =AK41/AK$38 -> #DIV/0! | AM41: =IFERROR(AK41/V41-1,0) -> 0
...

Sheet Z

Sheet EDO RESULTADOS MISMAS EST
I1: Mantenimiento de Imagen | J1: 2 | K1: 3 | L1: 4 | M1: 5 | N1: 6 | O1: 7 | Y1: 2 | Z1: 3 | AA1: 4 | AB1: 5 | AC1: 6 | AD1: 7 | AE1: 8 | AF1: 9 | AG1: 10 | AH1: 11 | AI1: 12 | AJ1: 13 | AM1: 17
J2: 2025 | V2: TOTAL ANUAL | Y2: 2026 | AK2: PPTO ANUAL MISMAS EST | AS2: PPTO ANUAL MISMAS EST
J3: ENE | K3: FEB | L3: MAR | M3: ABR | N3: MAY | O3: JUN | P3: JUL | Q3: AGO | R3: SEP | S3: OCT | T3: NOV | U3: DIC | V3: 2025 | W3: % Part | Y3: ENE | Z3: FEB | AA3: MAR | AB3: ABR | AC3: MAY | AD3: JUN | AE3: JUL | AF3: AGO | AG3: SEP | AH3: OCT | AI3: NOV | AJ3: DIC | AK3: 2026 | AL3: % Part | AM3: Var vs AA% | AS3: 2026
I4: INGRESOS
A6: A - INGRESOS | E6: ( mas ) | I6: A - INGRESOS | J6: ='TOTAL ESTACIONES'!J6 -> 69452870 | K6: ='TOTAL ESTACIONES'!K6 -> 68676679 | L6: ='TOTAL ESTACIONES'!L6 -> 74038427 | M6: ='TOTAL ESTACIONES'!M6 -> 69224559 | N6: ='TOTAL ESTACIONES'!N6 -> 77933808 | O6: ='TOTAL ESTACIONES'!O6 -> 77696456 | P6: ='TOTAL ESTACIONES'!P6 -> 76552162 | Q6: ='TOTAL ESTACIONES'!Q6 -> 70332214 | ... W6: ='TOTAL ESTACIONES'!W6 -> 1 | Y6: ='TOTAL ESTACIONES'!Y6 -> 69733029 | Z6: ='TOTAL ESTACIONES'!Z6 -> 69139078 | AA6: ='TOTAL ESTACIONES'!AA6 -> 76712717 | AB6: ='TOTAL ESTACIONES'!AB6 -> 72969416 | AC6: ='TOTAL ESTACIONES'!AC6 -> 84041095 | AD6: ='TOTAL ESTACIONES'!AD6 -> 83841112 | AE6: ='TOTAL ESTACIONES'!AE6 -> 83649040 | AF6: ='TOTAL ESTACIONES'!AF6 -> 85393702 | ... AM6: ='TOTAL ESTACIONES'!AM6 -> 0.074779166 | AS6: 9.6284792e+08
A7: A - INGRESOS | B7: estaciones | C7: INGRESOS MAGNA | D7: INGRESOS FORANEOS MAGNA | I7: MAXIMA | J7: ='TOTAL ESTACIONES'!J7 -> 52024925 | K7: ='TOTAL ESTACIONES'!K7 -> 51666858 | L7: ='TOTAL ESTACIONES'!L7 -> 55424481 | M7: ='TOTAL ESTACIONES'!M7 -> 52126321 | N7: ='TOTAL ESTACIONES'!N7 -> 58611053 | O7: ='TOTAL ESTACIONES'!O7 -> 57223116 | P7: ='TOTAL ESTACIONES'!P7 -> 55837049 | Q7: ='TOTAL ESTACIONES'!Q7 -> 53402377 | ... W7: ='TOTAL ESTACIONES'!W7 -> 0.75428499 | Y7: ='TOTAL ESTACIONES'!Y7 -> 51376336 | Z7: ='TOTAL ESTACIONES'!Z7 -> 51093583 | AA7: ='TOTAL ESTACIONES'!AA7 -> 56927257 | AB7: ='TOTAL ESTACIONES'!AB7 -> 54191883 | AC7: ='TOTAL ESTACIONES'!AC7 -> 63090563 | AD7: ='TOTAL ESTACIONES'!AD7 -> 62100321 | AE7: ='TOTAL ESTACIONES'!AE7 -> 61646409 | AF7: ='TOTAL ESTACIONES'!AF7 -> 64583060 | ... AM7: ='TOTAL ESTACIONES'!AM7 -> 0.06158167 | AS7: 7.175899e+08
A8: A - INGRESOS | B8: estaciones | C8: INGRESOS PREMIUM | D8: INGRESOS FORANEOS PREMIUM | I8: SUPER | J8: ='TOTAL ESTACIONES'!J8 -> 5468366 | K8: ='TOTAL ESTACIONES'!K8 -> 5650927 | L8: ='TOTAL ESTACIONES'!L8 -> 6229300 | M8: ='TOTAL ESTACIONES'!M8 -> 5959245 | N8: ='TOTAL ESTACIONES'!N8 -> 6580767 | O8: ='TOTAL ESTACIONES'!O8 -> 6797460 | P8: ='TOTAL ESTACIONES'!P8 -> 6511011 | Q8: ='TOTAL ESTACIONES'!Q8 -> 4596705 | ... W8: ='TOTAL ESTACIONES'!W8 -> 0.080056651 | Y8: ='TOTAL ESTACIONES'!Y8 -> 5360351.8 | Z8: ='TOTAL ESTACIONES'!Z8 -> 5553280.4 | AA8: ='TOTAL ESTACIONES'!AA8 -> 6278391.1 | AB8: ='TOTAL ESTACIONES'!AB8 -> 5971144.2 | AC8: ='TOTAL ESTACIONES'!AC8 -> 6969804.5 | AD8: ='TOTAL ESTACIONES'!AD8 -> 7376824 | AE8: ='TOTAL ESTACIONES'!AE8 -> 7096503.4 | AF8: ='TOTAL ESTACIONES'!AF8 -> 7282731 | ... AM8: ='TOTAL ESTACIONES'!AM8 -> 0.10263738 | AS8: 79107483
A9: A - INGRESOS | B9: estaciones | C9: INGRESOS DIESEL | D9: INGRESOS FORANEOS DIESEL | I9: DIESEL | J9: ='TOTAL ESTACIONES'!J9 -> 11903653 | K9: ='TOTAL ESTACIONES'!K9 -> 11298703 | L9: ='TOTAL ESTACIONES'!L9 -> 12326817 | M9: ='TOTAL ESTACIONES'!M9 -> 11076012 | N9: ='TOTAL ESTACIONES'!N9 -> 12676022 | O9: ='TOTAL ESTACIONES'!O9 -> 13611508 | P9: ='TOTAL ESTACIONES'!P9 -> 14146233 | Q9: ='TOTAL ESTACIONES'!Q9 -> 12274004 | ... W9: ='TOTAL ESTACIONES'!W9 -> 0.16484128 | Y9: ='TOTAL ESTACIONES'!Y9 -> 12921702 | Z9: ='TOTAL ESTACIONES'!Z9 -> 12420215 | AA9: ='TOTAL ESTACIONES'!AA9 -> 13411609 | AB9: ='TOTAL ESTACIONES'!AB9 -> 12736669 | AC9: ='TOTAL ESTACIONES'!AC9 -> 13904947 | AD9: ='TOTAL ESTACIONES'!AD9 -> 14292866 | AE9: ='TOTAL ESTACIONES'!AE9 -> 14834428 | AF9: ='TOTAL ESTACIONES'!AF9 -> 13459330 | ... AM9: ='TOTAL ESTACIONES'!AM9 -> 0.12087765 | AS9: 1.6558143e+08
I10: INGRESOS ACEITES Y LUBRICANTES | J10: ='TOTAL ESTACIONES'!J10 -> 55926 | K10: ='TOTAL ESTACIONES'!K10 -> 60191 | L10: ='TOTAL ESTACIONES'!L10 -> 57829 | M10: ='TOTAL ESTACIONES'!M10 -> 62981 | N10: ='TOTAL ESTACIONES'!N10 -> 65966 | O10: ='TOTAL ESTACIONES'!O10 -> 64372 | P10: ='TOTAL ESTACIONES'!P10 -> 57869 | Q10: ='TOTAL ESTACIONES'!Q10 -> 59128 | ... W10: ='TOTAL ESTACIONES'!W10 -> 0.00081707354 | Y10: ='TOTAL ESTACIONES'!Y10 -> 74640 | Z10: ='TOTAL ESTACIONES'!Z10 -> 72000 | AA10: ='TOTAL ESTACIONES'!AA10 -> 95460 | AB10: ='TOTAL ESTACIONES'!AB10 -> 69720 | AC10: ='TOTAL ESTACIONES'!AC10 -> 75780 | AD10: ='TOTAL ESTACIONES'!AD10 -> 71100 | AE10: ='TOTAL ESTACIONES'!AE10 -> 71700 | AF10: ='TOTAL ESTACIONES'!AF10 -> 68580 | ... AM10: ='TOTAL ESTACIONES'!AM10 -> 0.2283815 | AS10: 569100
I11: SOBRANTE COMBUSTIBLE | J11: ='TOTAL ESTACIONES'!J11 -> 0 | K11: ='TOTAL ESTACIONES'!K11 -> 0 | L11: ='TOTAL ESTACIONES'!L11 -> 0 | M11: ='TOTAL ESTACIONES'!M11 -> 0 | N11: ='TOTAL ESTACIONES'!N11 -> 0 | O11: ='TOTAL ESTACIONES'!O11 -> 0 | P11: ='TOTAL ESTACIONES'!P11 -> 0 | Q11: ='TOTAL ESTACIONES'!Q11 -> 0 | ... W11: ='TOTAL ESTACIONES'!W11 -> 0 | Y11: ='TOTAL ESTACIONES'!Y11 -> 0 | Z11: ='TOTAL ESTACIONES'!Z11 -> 0 | AA11: ='TOTAL ESTACIONES'!AA11 -> 0 | AB11: ='TOTAL ESTACIONES'!AB11 -> 0 | AC11: ='TOTAL ESTACIONES'!AC11 -> 0 | AD11: ='TOTAL ESTACIONES'!AD11 -> 0 | AE11: ='TOTAL ESTACIONES'!AE11 -> 0 | AF11: ='TOTAL ESTACIONES'!AF11 -> 0 | ... AM11: ='TOTAL ESTACIONES'!AM11 -> 0 | AS11: 0
J12: ='TOTAL ESTACIONES'!J12 -> 0 | K12: ='TOTAL ESTACIONES'!K12 -> 0 | L12: ='TOTAL ESTACIONES'!L12 -> 0 | M12: ='TOTAL ESTACIONES'!M12 -> 0 | N12: ='TOTAL ESTACIONES'!N12 -> 0 | O12: ='TOTAL ESTACIONES'!O12 -> 0 | P12: ='TOTAL ESTACIONES'!P12 -> 0 | Q12: ='TOTAL ESTACIONES'!Q12 -> 0 | ... W12: ='TOTAL ESTACIONES'!W12 -> 0 | Y12: ='TOTAL ESTACIONES'!Y12 -> 0 | Z12: ='TOTAL ESTACIONES'!Z12 -> 0 | AA12: ='TOTAL ESTACIONES'!AA12 -> 0 | AB12: ='TOTAL ESTACIONES'!AB12 -> 0 | AC12: ='TOTAL ESTACIONES'!AC12 -> 0 | AD12: ='TOTAL ESTACIONES'!AD12 -> 0 | AE12: ='TOTAL ESTACIONES'!AE12 -> 0 | AF12: ='TOTAL ESTACIONES'!AF12 -> 0 | ... AM12: ='TOTAL ESTACIONES'!AM12 -> 0 | AS12: 0
A13: B - COSTO DE VENTA | E13: ( menos ) | I13: B - COSTO DE VENTA | J13: ='TOTAL ESTACIONES'!J13 -> 59783497 | K13: ='TOTAL ESTACIONES'!K13 -> 58274255 | L13: ='TOTAL ESTACIONES'!L13 -> 63406479 | M13: ='TOTAL ESTACIONES'!M13 -> 59049480 | N13: ='TOTAL ESTACIONES'!N13 -> 65462131 | O13: ='TOTAL ESTACIONES'!O13 -> 66797081 | P13: ='TOTAL ESTACIONES'!P13 -> 66311059 | Q13: ='TOTAL ESTACIONES'!Q13 -> 61034025 | ... W13: ='TOTAL ESTACIONES'!W13 -> 0.8569024 | Y13: ='TOTAL ESTACIONES'!Y13 -> 60165791 | Z13: ='TOTAL ESTACIONES'!Z13 -> 59829241 | AA13: ='TOTAL ESTACIONES'!AA13 -> 66068704 | AB13: ='TOTAL ESTACIONES'!AB13 -> 63509117 | AC13: ='TOTAL ESTACIONES'!AC13 -> 72484085 | AD13: ='TOTAL ESTACIONES'!AD13 -> 73043997 | AE13: ='TOTAL ESTACIONES'!AE13 -> 72992851 | AF13: ='TOTAL ESTACIONES'!AF13 -> 74396670 | ... AM13: ='TOTAL ESTACIONES'!AM13 -> 0.092395952 | AS13: 8.3859734e+08
A14: B - COSTO DE VENTA | C14: COSTO MAGNA | D14: COSTO FORANEO MAGNA | I14: GASOLINA REGULAR | J14: ='TOTAL ESTACIONES'!J14 -> 54037503 | K14: ='TOTAL ESTACIONES'!K14 -> 52988836 | L14: ='TOTAL ESTACIONES'!L14 -> 58109663 | M14: ='TOTAL ESTACIONES'!M14 -> 54182667 | N14: ='TOTAL ESTACIONES'!N14 -> 61241981 | O14: ='TOTAL ESTACIONES'!O14 -> 60864148 | P14: ='TOTAL ESTACIONES'!P14 -> 59642077 | Q14: ='TOTAL ESTACIONES'!Q14 -> 56951729 | ... W14: ='TOTAL ESTACIONES'!W14 -> 0.76187727 | Y14: ='TOTAL ESTACIONES'!Y14 -> 43965152 | Z14: ='TOTAL ESTACIONES'!Z14 -> 43858767 | AA14: ='TOTAL ESTACIONES'!AA14 -> 48610578 | AB14: ='TOTAL ESTACIONES'!AB14 -> 46833763 | AC14: ='TOTAL ESTACIONES'!AC14 -> 53940557 | AD14: ='TOTAL ESTACIONES'!AD14 -> 53743511 | AE14: ='TOTAL ESTACIONES'!AE14 -> 53413437 | AF14: ='TOTAL ESTACIONES'!AF14 -> 55867226 | ... AM14: ='TOTAL ESTACIONES'!AM14 -> -0.091212883 | AS14: 6.2048976e+08
A15: B - COSTO DE VENTA | C15: COSTO PREMIUM | D15: COSTO FORANEO PREMIUM | I15: GASOLINA PREMIUM | J15: ='TOTAL ESTACIONES'!J15 -> 5319273 | K15: ='TOTAL ESTACIONES'!K15 -> 5477157 | L15: ='TOTAL ESTACIONES'!L15 -> 6024604 | M15: ='TOTAL ESTACIONES'!M15 -> 5759007 | N15: ='TOTAL ESTACIONES'!N15 -> 6417905 | O15: ='TOTAL ESTACIONES'!O15 -> 6709392 | P15: ='TOTAL ESTACIONES'!P15 -> 6539768 | Q15: ='TOTAL ESTACIONES'!Q15 -> 4716580 | ... W15: ='TOTAL ESTACIONES'!W15 -> 0.077487614 | Y15: ='TOTAL ESTACIONES'!Y15 -> 4659126.8 | Z15: ='TOTAL ESTACIONES'!Z15 -> 4832868.2 | AA15: ='TOTAL ESTACIONES'!AA15 -> 5459075.2 | AB15: ='TOTAL ESTACIONES'!AB15 -> 5216593.9 | AC15: ='TOTAL ESTACIONES'!AC15 -> 6098775.6 | AD15: ='TOTAL ESTACIONES'!AD15 -> 6452142 | AE15: ='TOTAL ESTACIONES'!AE15 -> 6245227.6 | AF15: ='TOTAL ESTACIONES'!AF15 -> 6398892.4 | ... AM15: ='TOTAL ESTACIONES'!AM15 -> -0.00054299936 | AS15: 69403895
A16: B - COSTO DE VENTA | C16: COSTO DIESEL | D16: COSTO FORANEO DIESEL | I16: DIESEL | J16: ='TOTAL ESTACIONES'!J16 -> 10212607 | K16: ='TOTAL ESTACIONES'!K16 -> 10010596 | L16: ='TOTAL ESTACIONES'!L16 -> 10864455 | M16: ='TOTAL ESTACIONES'!M16 -> 9847047 | N16: ='TOTAL ESTACIONES'!N16 -> 11207696 | O16: ='TOTAL ESTACIONES'!O16 -> 12305498 | P16: ='TOTAL ESTACIONES'!P16 -> 12857250 | Q16: ='TOTAL ESTACIONES'!Q16 -> 10940446 | ... W16: ='TOTAL ESTACIONES'!W16 -> 0.14682351 | Y16: ='TOTAL ESTACIONES'!Y16 -> 11478068 | Z16: ='TOTAL ESTACIONES'!Z16 -> 11076406 | AA16: ='TOTAL ESTACIONES'!AA16 -> 11917910 | AB16: ='TOTAL ESTACIONES'!AB16 -> 11399498 | AC16: ='TOTAL ESTACIONES'!AC16 -> 12380340 | AD16: ='TOTAL ESTACIONES'!AD16 -> 12787909 | AE16: ='TOTAL ESTACIONES'!AE16 -> 13273242 | AF16: ='TOTAL ESTACIONES'!AF16 -> 12072259 | ... AM16: ='TOTAL ESTACIONES'!AM16 -> 0.12648037 | AS16: 1.4821995e+08
