Workbook
Name AAI: #REF!
Name ALGDED: #REF!
Name BALANZADIC: #REF!
Name BALANZADIC14: #REF!
Name BGDECL: #REF!
Name CCF: #REF!
Name EJERCICIO: #REF!
Name ENERO16: #REF!
Name ENERO16: #REF!
Name ENERO16: #REF!
Name ENERO16: #REF!
Name ENERO16: #REF!
Name ERDECL: #REF!
Name inpc: #REF!
Name No_MES: #REF!
Name NombreRango1: #REF!
Name NombreRango1: #REF!
Name NombreRango1: #REF!
Name NombreRango1: #REF!
Name NombreRango1: #REF!
Name VAC: #REF!

Sheet Parametros SMA
A1: ESTIMULO FISCAL | D1: IEPS
A2: REGULAR | B2: ='[2]Parametros SMA'!$B$2 -> 0 | D2: REGULAR | E2: ='[2]Parametros SMA'!$E$2 -> 0.522479 | I2: *Aumento en los ingresos en proporcion minima a la inflacion
A3: PREMIUM | B3: ='[2]Parametros SMA'!$B$3 -> 0 | D3: PREMIUM | E3: ='[2]Parametros SMA'!$E$3 -> 0.637522
A4: DIESEL | B4: ='[2]Parametros SMA'!$B$4 -> 0 | D4: DIESEL | E4: ='[2]Parametros SMA'!$E$4 -> 0.433626
A6: ='[2]Parametros SMA'!$A$6 -> Precio final al 04 de sep 2024 | D6: Precio de venta sin IVA
A7: REGULAR | B7: ='[2]Parametros SMA'!$B$7 -> 24.33 | D7: =+B7/1.16 -> 20.974138
A8: PREMIUM | B8: ='[2]Parametros SMA'!$B$8 -> 26.69 | D8: =+B8/1.16 -> 23.008621
A9: DIESEL | B9: ='[2]Parametros SMA'!$B$9 -> 25.69 | D9: =+B9/1.16 -> 22.146552
A11: PRECIO DE VENTA sin IVA por LITRO
A12: Juarez | B12: ='[2]Parametros SMA'!B12 -> 0.005 | C12: ='[2]Parametros SMA'!C12 -> 0.005 | D12: ='[2]Parametros SMA'!D12 -> 0.005 | E12: ='[2]Parametros SMA'!E12 -> 0.005 | F12: ='[2]Parametros SMA'!F12 -> 0.005 | G12: ='[2]Parametros SMA'!G12 -> 0.005 | H12: ='[2]Parametros SMA'!H12 -> 0.005 | I12: ='[2]Parametros SMA'!I12 -> 0.005 | ... M12: ='[2]Parametros SMA'!M12 -> 0.005
A13: P.V. | B13: Enero | C13: Febrero | D13: Marzo | E13: Abril | F13: Mayo | G13: Junio | H13: Julio | I13: Agosto | J13: Septiembre | K13: Octubre | L13: Noviembre | M13: Diciembre
A14: MAXIMA | B14: ='[2]Parametros SMA'!B14 -> 20.974138 | C14: ='[2]Parametros SMA'!C14 -> 21.079009 | D14: ='[2]Parametros SMA'!D14 -> 21.184404 | E14: ='[2]Parametros SMA'!E14 -> 21.290326 | F14: ='[2]Parametros SMA'!F14 -> 21.396777 | G14: ='[2]Parametros SMA'!G14 -> 21.503761 | H14: ='[2]Parametros SMA'!H14 -> 21.61128 | I14: ='[2]Parametros SMA'!I14 -> 21.719336 | ... M14: ='[2]Parametros SMA'!M14 -> 22.156992
A15: SUPER | B15: ='[2]Parametros SMA'!B15 -> 23.008621 | C15: ='[2]Parametros SMA'!C15 -> 23.123664 | D15: ='[2]Parametros SMA'!D15 -> 23.239282 | E15: ='[2]Parametros SMA'!E15 -> 23.355479 | F15: ='[2]Parametros SMA'!F15 -> 23.472256 | G15: ='[2]Parametros SMA'!G15 -> 23.589617 | H15: ='[2]Parametros SMA'!H15 -> 23.707565 | I15: ='[2]Parametros SMA'!I15 -> 23.826103 | ... M15: ='[2]Parametros SMA'!M15 -> 24.306211
A16: DIESEL | B16: ='[2]Parametros SMA'!B16 -> 22.146552 | C16: ='[2]Parametros SMA'!C16 -> 22.257284 | D16: ='[2]Parametros SMA'!D16 -> 22.368571 | E16: ='[2]Parametros SMA'!E16 -> 22.480414 | F16: ='[2]Parametros SMA'!F16 -> 22.592816 | G16: ='[2]Parametros SMA'!G16 -> 22.70578 | H16: ='[2]Parametros SMA'!H16 -> 22.819309 | I16: ='[2]Parametros SMA'!I16 -> 22.933405 | ... M16: ='[2]Parametros SMA'!M16 -> 23.395525
A18: ='[2]Parametros SMA'!$A$18 -> Inflacion | B18: ='[2]Parametros SMA'!$B$18 -> 0.07
A21: MARGEN estimado por litro
A22: Juarez | B22: Margen comercial ( precio - costo según factura )
A23: P.V. | B23: Enero | C23: Febrero | D23: Marzo | E23: Abril | F23: Mayo | G23: Junio | H23: Julio | I23: Agosto | J23: Septiembre | K23: Octubre | L23: Noviembre | M23: Diciembre
A24: MAXIMA | B24: ='[2]Parametros SMA'!B24 -> 0 | C24: ='[2]Parametros SMA'!C24 -> 0 | D24: ='[2]Parametros SMA'!D24 -> 0 | E24: ='[2]Parametros SMA'!E24 -> 0 | F24: ='[2]Parametros SMA'!F24 -> 0 | G24: ='[2]Parametros SMA'!G24 -> 0 | H24: ='[2]Parametros SMA'!H24 -> 0 | I24: ='[2]Parametros SMA'!I24 -> 0 | ... M24: ='[2]Parametros SMA'!M24 -> 0
A25: SUPER | B25: ='[2]Parametros SMA'!B25 -> 0 | C25: ='[2]Parametros SMA'!C25 -> 0 | D25: ='[2]Parametros SMA'!D25 -> 0 | E25: ='[2]Parametros SMA'!E25 -> 0 | F25: ='[2]Parametros SMA'!F25 -> 0 | G25: ='[2]Parametros SMA'!G25 -> 0 | H25: ='[2]Parametros SMA'!H25 -> 0 | I25: ='[2]Parametros SMA'!I25 -> 0 | ... M25: ='[2]Parametros SMA'!M25 -> 0
A26: DIESEL | B26: ='[2]Parametros SMA'!B26 -> 0 | C26: ='[2]Parametros SMA'!C26 -> 0 | D26: ='[2]Parametros SMA'!D26 -> 0 | E26: ='[2]Parametros SMA'!E26 -> 0 | F26: ='[2]Parametros SMA'!F26 -> 0 | G26: ='[2]Parametros SMA'!G26 -> 0 | H26: ='[2]Parametros SMA'!H26 -> 0 | I26: ='[2]Parametros SMA'!I26 -> 0 | ... M26: ='[2]Parametros SMA'!M26 -> 0
B28: ='[2]Parametros SMA'!$B$28 -> Margen por contrato de volumen con PETROTAMPS
A29: P.V. | B29: Enero | C29: Febrero | D29: Marzo | E29: Abril | F29: Mayo | G29: Junio | H29: Julio | I29: Agosto | J29: Septiembre | K29: Octubre | L29: Noviembre | M29: Diciembre | N29: Porcentaje
A30: MAXIMA | B30: ='[2]Parametros SMA'!B36 -> 0 | C30: ='[2]Parametros SMA'!C36 -> 0 | D30: ='[2]Parametros SMA'!D36 -> 0 | E30: ='[2]Parametros SMA'!E36 -> 0 | F30: ='[2]Parametros SMA'!F36 -> 0 | G30: ='[2]Parametros SMA'!G36 -> 0 | H30: ='[2]Parametros SMA'!H36 -> 0 | I30: ='[2]Parametros SMA'!I36 -> 0 | ... N30: ='[2]Parametros SMA'!N36 -> 0
A31: SUPER | B31: ='[2]Parametros SMA'!B37 -> 0 | C31: ='[2]Parametros SMA'!C37 -> 0 | D31: ='[2]Parametros SMA'!D37 -> 0 | E31: ='[2]Parametros SMA'!E37 -> 0 | F31: ='[2]Parametros SMA'!F37 -> 0 | G31: ='[2]Parametros SMA'!G37 -> 0 | H31: ='[2]Parametros SMA'!H37 -> 0 | I31: ='[2]Parametros SMA'!I37 -> 0 | ... N31: ='[2]Parametros SMA'!N37 -> 0
A32: DIESEL | B32: ='[2]Parametros SMA'!B38 -> 0 | C32: ='[2]Parametros SMA'!C38 -> 0 | D32: ='[2]Parametros SMA'!D38 -> 0 | E32: ='[2]Parametros SMA'!E38 -> 0 | F32: ='[2]Parametros SMA'!F38 -> 0 | G32: ='[2]Parametros SMA'!G38 -> 0 | H32: ='[2]Parametros SMA'!H38 -> 0 | I32: ='[2]Parametros SMA'!I38 -> 0 | ... N32: ='[2]Parametros SMA'!N38 -> 0
B34: ='[2]Parametros SMA'!$B$34 -> Margen por contrato de volumen con ALLIOTH
A35: P.V. | B35: Enero | C35: Febrero | D35: Marzo | E35: Abril | F35: Mayo | G35: Junio | H35: Julio | I35: Agosto | J35: Septiembre | K35: Octubre | L35: Noviembre | M35: Diciembre | N35: Porcentaje
A36: MAXIMA | B36: ='[2]Parametros SMA'!B36 -> 0 | C36: ='[2]Parametros SMA'!C36 -> 0 | D36: ='[2]Parametros SMA'!D36 -> 0 | E36: ='[2]Parametros SMA'!E36 -> 0 | F36: ='[2]Parametros SMA'!F36 -> 0 | G36: ='[2]Parametros SMA'!G36 -> 0 | H36: ='[2]Parametros SMA'!H36 -> 0 | I36: ='[2]Parametros SMA'!I36 -> 0 | ... N36: ='[2]Parametros SMA'!N36 -> 0
A37: SUPER | B37: ='[2]Parametros SMA'!B37 -> 0 | C37: ='[2]Parametros SMA'!C37 -> 0 | D37: ='[2]Parametros SMA'!D37 -> 0 | E37: ='[2]Parametros SMA'!E37 -> 0 | F37: ='[2]Parametros SMA'!F37 -> 0 | G37: ='[2]Parametros SMA'!G37 -> 0 | H37: ='[2]Parametros SMA'!H37 -> 0 | I37: ='[2]Parametros SMA'!I37 -> 0 | ... N37: ='[2]Parametros SMA'!N37 -> 0
A38: DIESEL | B38: ='[2]Parametros SMA'!B38 -> 0 | C38: ='[2]Parametros SMA'!C38 -> 0 | D38: ='[2]Parametros SMA'!D38 -> 0 | E38: ='[2]Parametros SMA'!E38 -> 0 | F38: ='[2]Parametros SMA'!F38 -> 0 | G38: ='[2]Parametros SMA'!G38 -> 0 | H38: ='[2]Parametros SMA'!H38 -> 0 | I38: ='[2]Parametros SMA'!I38 -> 0 | ... N38: ='[2]Parametros SMA'!N38 -> 0
B40: ='[2]Parametros SMA'!$B$40 -> Margen por contrato de volumen MGC
A41: P.V. | B41: Enero | C41: Febrero | D41: Marzo | E41: Abril | F41: Mayo | G41: Junio | H41: Julio | I41: Agosto | J41: Septiembre | K41: Octubre | L41: Noviembre | M41: Diciembre | N41: Porcentaje
A42: MAXIMA | B42: ='[2]Parametros SMA'!B42 -> 0 | C42: ='[2]Parametros SMA'!C42 -> 1.22 | D42: ='[2]Parametros SMA'!D42 -> 0.51 | E42: ='[2]Parametros SMA'!E42 -> 0.48 | F42: ='[2]Parametros SMA'!F42 -> 1.34 | G42: ='[2]Parametros SMA'!G42 -> 1.19 | H42: ='[2]Parametros SMA'!H42 -> 1.25 | I42: ='[2]Parametros SMA'!I42 -> 1.19 | ... N42: ='[2]Parametros SMA'!N42 -> 1
A43: SUPER | B43: ='[2]Parametros SMA'!B43 -> 0 | C43: ='[2]Parametros SMA'!C43 -> 1.47 | D43: ='[2]Parametros SMA'!D43 -> 1.21 | E43: ='[2]Parametros SMA'!E43 -> 1.55 | F43: ='[2]Parametros SMA'!F43 -> 3.41 | G43: ='[2]Parametros SMA'!G43 -> 3.06 | H43: ='[2]Parametros SMA'!H43 -> 2.73 | I43: ='[2]Parametros SMA'!I43 -> 2.67 | ... N43: ='[2]Parametros SMA'!N43 -> 1
A44: DIESEL | B44: ='[2]Parametros SMA'!B44 -> 1.12 | C44: ='[2]Parametros SMA'!C44 -> 1.18 | D44: ='[2]Parametros SMA'!D44 -> 1.44 | E44: ='[2]Parametros SMA'!E44 -> 2.34 | F44: ='[2]Parametros SMA'!F44 -> 1.43 | G44: ='[2]Parametros SMA'!G44 -> 1.56 | H44: ='[2]Parametros SMA'!H44 -> 0 | I44: ='[2]Parametros SMA'!I44 -> 0 | ... N44: ='[2]Parametros SMA'!N44 -> 1
B46: ='[2]Parametros SMA'!$B$46 -> Margen por contrato de volumen OTROS
A47: P.V. | B47: Enero | C47: Febrero | D47: Marzo | E47: Abril | F47: Mayo | G47: Junio | H47: Julio | I47: Agosto | J47: Septiembre | K47: Octubre | L47: Noviembre | M47: Diciembre | N47: Porcentaje
A48: MAXIMA | B48: ='[2]Parametros SMA'!B48 -> 0 | C48: ='[2]Parametros SMA'!C48 -> 0 | D48: ='[2]Parametros SMA'!D48 -> 0 | E48: ='[2]Parametros SMA'!E48 -> 0 | F48: ='[2]Parametros SMA'!F48 -> 0 | G48: ='[2]Parametros SMA'!G48 -> 0 | H48: ='[2]Parametros SMA'!H48 -> 0 | I48: ='[2]Parametros SMA'!I48 -> 0 | ... N48: ='[2]Parametros SMA'!N48 -> 0
A49: SUPER | B49: ='[2]Parametros SMA'!B49 -> 0 | C49: ='[2]Parametros SMA'!C49 -> 0 | D49: ='[2]Parametros SMA'!D49 -> 0 | E49: ='[2]Parametros SMA'!E49 -> 0 | F49: ='[2]Parametros SMA'!F49 -> 0 | G49: ='[2]Parametros SMA'!G49 -> 0 | H49: ='[2]Parametros SMA'!H49 -> 0 | I49: ='[2]Parametros SMA'!I49 -> 0 | ... N49: ='[2]Parametros SMA'!N49 -> 0
...

Sheet S

Sheet CONTABILIDAD-FISCAL
I1: Mantenimiento de Imagen | Y1: 2 | Z1: 3 | AA1: 4 | AB1: 5 | AC1: 6 | AD1: 7 | AE1: 8 | AF1: 9 | AG1: 10 | AH1: 11 | AI1: 12 | AJ1: 13 | AM1: 17
J2: 2024 | V2: TOTAL ANUAL | Y2: 2025 | AK2: TOTAL ANUAL
J3: ENE | K3: FEB | L3: MAR | M3: ABR | N3: MAY | O3: JUN | P3: JUL | Q3: AGO | R3: SEP | S3: OCT | T3: NOV | U3: DIC | V3: 2025 | W3: % Part | Y3: ENE | Z3: FEB | AA3: MAR | AB3: ABR | AC3: MAY | AD3: JUN | AE3: JUL | AF3: AGO | AG3: SEP | AH3: OCT | AI3: NOV | AJ3: DIC | AK3: 2026 | AL3: % Part | AM3: Var vs AA%
I4: INGRESOS
A6: A - INGRESOS | E6: ( mas ) | I6: A - INGRESOS | V6: =SUM(J6:U6) -> 0 | W6: =V6/V$6 -> #DIV/0! | Y6: =SUM(Y7:Y9) -> 0 | Z6: =SUM(Z7:Z9) -> 0 | AA6: =SUM(AA7:AA9) -> 0 | AB6: =SUM(AB7:AB9) -> 0 | AC6: =SUM(AC7:AC9) -> 0 | AD6: =SUM(AD7:AD9) -> 0 | AE6: =SUM(AE7:AE9) -> 0 | AF6: =SUM(AF7:AF9) -> 0 | ... AJ6: =SUM(AJ7:AJ9) -> 0 | AK6: =SUM(Y6:AJ6) -> 0 | AL6: =AK6/AK$6 -> #DIV/0! | AM6: =IFERROR(AK6/V6-1,0) -> 0
A7: A - INGRESOS | B7: estaciones | C7: INGRESOS MAGNA | D7: INGRESOS FORANEOS MAGNA | I7: T-MAXIMA REGULAR | V7: =SUM(J7:U7) -> 0 | W7: =V7/V$6 -> #DIV/0! | Y7: 0 | Z7: 0 | AA7: 0 | AB7: 0 | AC7: 0 | AD7: 0 | AE7: 0 | AF7: 0 | AG7: 0 | AH7: 0 | AI7: 0 | AJ7: 0 | AK7: =SUM(Y7:AJ7) -> 0 | AL7: =AK7/AK$6 -> #DIV/0! | AM7: =IFERROR(AK7/V7-1,0) -> 0
A8: A - INGRESOS | B8: estaciones | C8: INGRESOS PREMIUM | D8: INGRESOS FORANEOS PREMIUM | I8: T-SUPER PREMIUM | V8: =SUM(J8:U8) -> 0 | W8: =V8/V$6 -> #DIV/0! | Y8: 0 | Z8: 0 | AA8: 0 | AB8: 0 | AC8: 0 | AD8: 0 | AE8: 0 | AF8: 0 | AG8: 0 | AH8: 0 | AI8: 0 | AJ8: 0 | AK8: =SUM(Y8:AJ8) -> 0 | AL8: =AK8/AK$6 -> #DIV/0! | AM8: =IFERROR(AK8/V8-1,0) -> 0
A9: A - INGRESOS | B9: estaciones | C9: INGRESOS DIESEL | D9: INGRESOS FORANEOS DIESEL | I9: DIESEL AUTOMOTRIZ | V9: =SUM(J9:U9) -> 0 | W9: =V9/V$6 -> #DIV/0! | Y9: 0 | Z9: 0 | AA9: 0 | AB9: 0 | AC9: 0 | AD9: 0 | AE9: 0 | AF9: 0 | AG9: 0 | AH9: 0 | AI9: 0 | AJ9: 0 | AK9: =SUM(Y9:AJ9) -> 0 | AL9: =AK9/AK$6 -> #DIV/0! | AM9: =IFERROR(AK9/V9-1,0) -> 0
A10: A - INGRESOS | B10: estaciones | C10: INGRESOS ADITIVOS | D10: INGRESOS ESPECIALES | E10: INGRESOS FORANEOS ADITIVOS | F10: INGRESOS FORANEOS ESPECIALES | G10: INGRESOS FORANEOS LUBRICANTES | H10: INGRESOS LUBRICANTES | I10: INGRESOS ACEITES Y LUBRICANTES | V10: =SUM(J10:U10) -> 0 | W10: =V10/V$6 -> #DIV/0! | Y10: 0 | Z10: 0 | AA10: 0 | AB10: 0 | AC10: 0 | AD10: 0 | AE10: 0 | AF10: 0 | AG10: 0 | AH10: 0 | AI10: 0 | AJ10: 0 | AK10: =SUM(Y10:AJ10) -> 0 | AL10: =AK10/AK$6 -> #DIV/0! | AM10: =IFERROR(AK10/V10-1,0) -> 0
I11: SOBRANTE COMBUSTIBLES
A12: B - COSTO DE VENTA | E12: ( menos ) | I12: B - COSTO DE VENTA | V12: =SUM(J12:U12) -> 0 | W12: =V12/V$6 -> #DIV/0! | Y12: =SUM(Y13:Y32) -> 0 | Z12: =SUM(Z13:Z32) -> 0 | AA12: =SUM(AA13:AA32) -> 0 | AB12: =SUM(AB13:AB32) -> 0 | AC12: =SUM(AC13:AC32) -> 0 | AD12: =SUM(AD13:AD32) -> 0 | AE12: =SUM(AE13:AE32) -> 0 | AF12: =SUM(AF13:AF32) -> 0 | ... AJ12: =SUM(AJ13:AJ32) -> 0 | AK12: =SUM(Y12:AJ12) -> 0 | AL12: =AK12/AK$6 -> #DIV/0! | AM12: =IFERROR(AK12/V12-1,0) -> 0
A13: B - COSTO DE VENTA | C13: COSTO MAGNA | D13: COSTO FORANEO MAGNA | I13: GASOLINA REGULAR | V13: =SUM(J13:U13) -> 0 | W13: =V13/V$6 -> #DIV/0! | Y13: 0 | Z13: 0 | AA13: 0 | AB13: 0 | AC13: 0 | AD13: 0 | AE13: 0 | AF13: 0 | AG13: 0 | AH13: 0 | AI13: 0 | AJ13: 0 | AK13: =SUM(Y13:AJ13) -> 0 | AL13: =AK13/AK$6 -> #DIV/0! | AM13: =IFERROR(AK13/V13-1,0) -> 0
A14: B - COSTO DE VENTA | C14: COSTO PREMIUM | D14: COSTO FORANEO PREMIUM | I14: GASOLINA PREMIUM | V14: =SUM(J14:U14) -> 0 | W14: =V14/V$6 -> #DIV/0! | Y14: 0 | Z14: 0 | AA14: 0 | AB14: 0 | AC14: 0 | AD14: 0 | AE14: 0 | AF14: 0 | AG14: 0 | AH14: 0 | AI14: 0 | AJ14: 0 | AK14: =SUM(Y14:AJ14) -> 0 | AL14: =AK14/AK$6 -> #DIV/0! | AM14: =IFERROR(AK14/V14-1,0) -> 0
A15: B - COSTO DE VENTA | C15: COSTO DIESEL | D15: COSTO FORANEO DIESEL | I15: DIESEL | V15: =SUM(J15:U15) -> 0 | W15: =V15/V$6 -> #DIV/0! | Y15: 0 | Z15: 0 | AA15: 0 | AB15: 0 | AC15: 0 | AD15: 0 | AE15: 0 | AF15: 0 | AG15: 0 | AH15: 0 | AI15: 0 | AJ15: 0 | AK15: =SUM(Y15:AJ15) -> 0 | AL15: =AK15/AK$6 -> #DIV/0! | AM15: =IFERROR(AK15/V15-1,0) -> 0
A16: B - COSTO DE VENTA | C16: Merma Magna | I16: MERMA GASOLINA REGULAR | V16: =SUM(J16:U16) -> 0 | W16: =V16/V$6 -> #DIV/0! | Y16: 0 | Z16: 0 | AA16: 0 | AB16: 0 | AC16: 0 | AD16: 0 | AE16: 0 | AF16: 0 | AG16: 0 | AH16: 0 | AI16: 0 | AJ16: 0 | AK16: =SUM(Y16:AJ16) -> 0 | AL16: =AK16/AK$6 -> #DIV/0! | AM16: =IFERROR(AK16/V16-1,0) -> 0
A17: B - COSTO DE VENTA | C17: Merma Premium | I17: MERMA GASOLINA PREMIUM | V17: =SUM(J17:U17) -> 0 | W17: =V17/V$6 -> #DIV/0! | Y17: 0 | Z17: 0 | AA17: 0 | AB17: 0 | AC17: 0 | AD17: 0 | AE17: 0 | AF17: 0 | AG17: 0 | AH17: 0 | AI17: 0 | AJ17: 0 | AK17: =SUM(Y17:AJ17) -> 0 | AL17: =AK17/AK$6 -> #DIV/0! | AM17: =IFERROR(AK17/V17-1,0) -> 0
A18: B - COSTO DE VENTA | C18: Merma Diesel | I18: MERMA DIESEL | V18: =SUM(J18:U18) -> 0 | W18: =V18/V$6 -> #DIV/0! | Y18: 0 | Z18: 0 | AA18: 0 | AB18: 0 | AC18: 0 | AD18: 0 | AE18: 0 | AF18: 0 | AG18: 0 | AH18: 0 | AI18: 0 | AJ18: 0 | AK18: =SUM(Y18:AJ18) -> 0 | AL18: =AK18/AK$6 -> #DIV/0! | AM18: =IFERROR(AK18/V18-1,0) -> 0
A19: B - COSTO DE VENTA | C19: ADITIVO PARA GASOLINA TMAXIMA (REGULAR) | D19: ADITIVO PARA GASOLINA TMAXIMA( REGULAR) | I19: ADITIVO TOTAL POWER GASOLINA REG | V19: =SUM(J19:U19) -> 0 | W19: =V19/V$6 -> #DIV/0! | Y19: 0 | Z19: 0 | AA19: 0 | AB19: 0 | AC19: 0 | AD19: 0 | AE19: 0 | AF19: 0 | AG19: 0 | AH19: 0 | AI19: 0 | AJ19: 0 | AK19: =SUM(Y19:AJ19) -> 0 | AL19: =AK19/AK$6 -> #DIV/0! | AM19: =IFERROR(AK19/V19-1,0) -> 0
A20: B - COSTO DE VENTA | C20: ADITIVO PARA GASOLINA TSUPER (PREMIUM) | I20: ADITIVO TOTAL POWER GASOLINA PREM | V20: =SUM(J20:U20) -> 0 | W20: =V20/V$6 -> #DIV/0! | Y20: 0 | Z20: 0 | AA20: 0 | AB20: 0 | AC20: 0 | AD20: 0 | AE20: 0 | AF20: 0 | AG20: 0 | AH20: 0 | AI20: 0 | AJ20: 0 | AK20: =SUM(Y20:AJ20) -> 0 | AL20: =AK20/AK$6 -> #DIV/0! | AM20: =IFERROR(AK20/V20-1,0) -> 0
A21: B - COSTO DE VENTA | C21: FLETE MAGNA | I21: FLETE GASOLINA REGULAR | V21: =SUM(J21:U21) -> 0 | W21: =V21/V$6 -> #DIV/0! | Y21: 0 | Z21: 0 | AA21: 0 | AB21: 0 | AC21: 0 | AD21: 0 | AE21: 0 | AF21: 0 | AG21: 0 | AH21: 0 | AI21: 0 | AJ21: 0 | AK21: =SUM(Y21:AJ21) -> 0 | AL21: =AK21/AK$6 -> #DIV/0! | AM21: =IFERROR(AK21/V21-1,0) -> 0
A22: B - COSTO DE VENTA | C22: FLETE PREMIUM | I22: FLETE GASOLINA PREMIUM | V22: =SUM(J22:U22) -> 0 | W22: =V22/V$6 -> #DIV/0! | Y22: 0 | Z22: 0 | AA22: 0 | AB22: 0 | AC22: 0 | AD22: 0 | AE22: 0 | AF22: 0 | AG22: 0 | AH22: 0 | AI22: 0 | AJ22: 0 | AK22: =SUM(Y22:AJ22) -> 0 | AL22: =AK22/AK$6 -> #DIV/0! | AM22: =IFERROR(AK22/V22-1,0) -> 0
A23: B - COSTO DE VENTA | C23: FLETE DIESEL | I23: FLETE DIESEL | V23: =SUM(J23:U23) -> 0 | W23: =V23/V$6 -> #DIV/0! | Y23: 0 | Z23: 0 | AA23: 0 | AB23: 0 | AC23: 0 | AD23: 0 | AE23: 0 | AF23: 0 | AG23: 0 | AH23: 0 | AI23: 0 | AJ23: 0 | AK23: =SUM(Y23:AJ23) -> 0 | AL23: =AK23/AK$6 -> #DIV/0! | AM23: =IFERROR(AK23/V23-1,0) -> 0
A24: B - COSTO DE VENTA | C24: Estimulo IEPS Magna | D24: INGRESOS FORANEOS MAGNA | I24: ESTIMULO REGULAR | V24: =SUM(J24:U24) -> 0 | W24: =V24/V$6 -> #DIV/0! | Y24: 0 | Z24: 0 | AA24: 0 | AB24: 0 | AC24: 0 | AD24: 0 | AE24: 0 | AF24: 0 | AG24: 0 | AH24: 0 | AI24: 0 | AJ24: 0 | AK24: =SUM(Y24:AJ24) -> 0 | AL24: =AK24/AK$6 -> #DIV/0! | AM24: =IFERROR(AK24/V24-1,0) -> 0
A25: B - COSTO DE VENTA | C25: Estimulo IEPS Premium | D25: INGRESOS FORANEOS MAGNA | I25: ESTIMULO PREMIUM | V25: =SUM(J25:U25) -> 0 | W25: =V25/V$6 -> #DIV/0! | Y25: 0 | Z25: 0 | AA25: 0 | AB25: 0 | AC25: 0 | AD25: 0 | AE25: 0 | AF25: 0 | AG25: 0 | AH25: 0 | AI25: 0 | AJ25: 0 | AK25: =SUM(Y25:AJ25) -> 0 | AL25: =AK25/AK$6 -> #DIV/0! | AM25: =IFERROR(AK25/V25-1,0) -> 0
I26: SOBRANTE MAGNA
I27: SOBRANTE PREMIUM
I28: SOBRANTE DIESEL
I29: COSTO ACEITES Y LUBRICANTES | V29: =SUM(J29:U29) -> 0 | W29: =V29/V$6 -> #DIV/0! | Y29: 0 | Z29: 0 | AA29: 0 | AB29: 0 | AC29: 0 | AD29: 0 | AE29: 0 | AF29: 0 | AG29: 0 | AH29: 0 | AI29: 0 | AJ29: 0 | AK29: =SUM(Y29:AJ29) -> 0 | AL29: =AK29/AK$6 -> #DIV/0! | AM29: =IFERROR(AK29/V29-1,0) -> 0
I30: BONIFICACION COMPRA DE COMBUSTIBLE MAGNA | V30: =SUM(J30:U30) -> 0 | W30: =V30/V$6 -> #DIV/0! | Y30: 0 | Z30: 0 | AA30: 0 | AB30: 0 | AC30: 0 | AD30: 0 | AE30: 0 | AF30: 0 | AG30: 0 | AH30: 0 | AI30: 0 | AJ30: 0 | AK30: =SUM(Y30:AJ30) -> 0 | AL30: =AK30/AK$6 -> #DIV/0! | AM30: =IFERROR(AK30/V30-1,0) -> 0
I31: BONIFICACION COMPRA DE COMBUSTIBLE PREMIUM
I32: BONIFICACION COMPRA DE COMBUSTIBLE DIESEL | V32: =SUM(J32:U32) -> 0 | W32: =V32/V$6 -> #DIV/0! | Y32: 0 | Z32: 0 | AA32: 0 | AB32: 0 | AC32: 0 | AD32: 0 | AE32: 0 | AF32: 0 | AG32: 0 | AH32: 0 | AI32: 0 | AJ32: 0 | AK32: =SUM(Y32:AJ32) -> 0 | AL32: =AK32/AK$6 -> #DIV/0! | AM32: =IFERROR(AK32/V32-1,0) -> 0
I33: MARGEN DE UTILIDAD | V33: =V6-V12 -> 0 | W33: =V33/V$6 -> #DIV/0! | Y33: =Y6-Y12 -> 0 | Z33: =Z6-Z12 -> 0 | AA33: =AA6-AA12 -> 0 | AB33: =AB6-AB12 -> 0 | AC33: =AC6-AC12 -> 0 | AD33: =AD6-AD12 -> 0 | AE33: =AE6-AE12 -> 0 | AF33: =AF6-AF12 -> 0 | ... AK33: =AK6-AK12 -> 0 | AL33: =AK33/AK$6 -> #DIV/0! | AM33: =IFERROR(AK33/V33-1,0) -> 0
I34: Regular | V34: =SUM(J34:U34) -> 0 | Y34: =+Y44*Y40 -> 0 | Z34: =+Z44*Z40 -> 0 | AA34: =+AA44*AA40 -> 0 | AB34: =+AB44*AB40 -> 0 | AC34: =+AC44*AC40 -> 0 | AD34: =+AD44*AD40 -> 0 | AE34: =+AE44*AE40 -> 0 | AF34: =+AF44*AF40 -> 0 | ... AJ34: =+AJ44*AJ40 -> 0 | AK34: =SUM(Y34:AJ34) -> 0 | AM34: =IFERROR(AK34/V34-1,0) -> 0
I35: Premium | V35: =SUM(J35:U35) -> 0 | Y35: =+Y45*Y41 -> 0 | Z35: =+Z45*Z41 -> 0 | AA35: =+AA45*AA41 -> 0 | AB35: =+AB45*AB41 -> 0 | AC35: =+AC45*AC41 -> 0 | AD35: =+AD45*AD41 -> 0 | AE35: =+AE45*AE41 -> 0 | AF35: =+AF45*AF41 -> 0 | ... AJ35: =+AJ45*AJ41 -> 0 | AK35: =SUM(Y35:AJ35) -> 0 | AM35: =IFERROR(AK35/V35-1,0) -> 0
I36: Diesel | V36: =SUM(J36:U36) -> 0 | Y36: =+Y46*Y42 -> 0 | Z36: =+Z46*Z42 -> 0 | AA36: =+AA46*AA42 -> 0 | AB36: =+AB46*AB42 -> 0 | AC36: =+AC46*AC42 -> 0 | AD36: =+AD46*AD42 -> 0 | AE36: =+AE46*AE42 -> 0 | AF36: =+AF46*AF42 -> 0 | ... AJ36: =+AJ46*AJ42 -> 0 | AK36: =SUM(Y36:AJ36) -> 0 | AM36: =IFERROR(AK36/V36-1,0) -> 0
I37: *Otros Conceptos
I38: * Aceites y Lubricantes
I39: Litros vendidos | V39: =SUM(J39:U39) -> 0 | W39: =V39/V$39 -> #DIV/0! | Y39: =SUM(Y40:Y42) -> 0 | Z39: =SUM(Z40:Z42) -> 0 | AA39: =SUM(AA40:AA42) -> 0 | AB39: =SUM(AB40:AB42) -> 0 | AC39: =SUM(AC40:AC42) -> 0 | AD39: =SUM(AD40:AD42) -> 0 | AE39: =SUM(AE40:AE42) -> 0 | AF39: =SUM(AF40:AF42) -> 0 | ... AJ39: =SUM(AJ40:AJ42) -> 0 | AK39: =SUM(Y39:AJ39) -> 0 | AL39: =AK39/AK$39 -> #DIV/0! | AM39: =IFERROR(AK39/V39-1,0) -> 0
I40: Regular | V40: =SUM(J40:U40) -> 0 | W40: =V40/V$39 -> #DIV/0! | Y40: 0 | Z40: 0 | AA40: 0 | AB40: 0 | AC40: 0 | AD40: 0 | AE40: 0 | AF40: 0 | AG40: 0 | AH40: 0 | AI40: 0 | AJ40: 0 | AK40: =SUM(Y40:AJ40) -> 0 | AL40: =AK40/AK$39 -> #DIV/0! | AM40: =IFERROR(AK40/V40-1,0) -> 0
I41: Premium | V41: =SUM(J41:U41) -> 0 | W41: =V41/V$39 -> #DIV/0! | Y41: 0 | Z41: 0 | AA41: 0 | AB41: 0 | AC41: 0 | AD41: 0 | AE41: 0 | AF41: 0 | AG41: 0 | AH41: 0 | AI41: 0 | AJ41: 0 | AK41: =SUM(Y41:AJ41) -> 0 | AL41: =AK41/AK$39 -> #DIV/0! | AM41: =IFERROR(AK41/V41-1,0) -> 0
...

Sheet COM-MKT
I1: Mantenimiento de Imagen | Y1: 2 | Z1: 3 | AA1: 4 | AB1: 5 | AC1: 6 | AD1: 7 | AE1: 8 | AF1: 9 | AG1: 10 | AH1: 11 | AI1: 12 | AJ1: 13 | AM1: 17
J2: 2024 | V2: TOTAL ANUAL | Y2: 2025 | AK2: TOTAL ANUAL
J3: ENE | K3: FEB | L3: MAR | M3: ABR | N3: MAY | O3: JUN | P3: JUL | Q3: AGO | R3: SEP | S3: OCT | T3: NOV | U3: DIC | V3: 2024 | W3: % Part | Y3: ENE | Z3: FEB | AA3: MAR | AB3: ABR | AC3: MAY | AD3: JUN | AE3: JUL | AF3: AGO | AG3: SEP | AH3: OCT | AI3: NOV | AJ3: DIC | AK3: 2025 | AL3: % Part | AM3: Var vs AA%
I4: INGRESOS
A6: A - INGRESOS | E6: ( mas ) | I6: A - INGRESOS | V6: =SUM(J6:U6) -> 0 | W6: =V6/V$6 -> #DIV/0! | Y6: =SUM(Y7:Y9) -> 0 | Z6: =SUM(Z7:Z9) -> 0 | AA6: =SUM(AA7:AA9) -> 0 | AB6: =SUM(AB7:AB9) -> 0 | AC6: =SUM(AC7:AC9) -> 0 | AD6: =SUM(AD7:AD9) -> 0 | AE6: =SUM(AE7:AE9) -> 0 | AF6: =SUM(AF7:AF9) -> 0 | ... AJ6: =SUM(AJ7:AJ9) -> 0 | AK6: =SUM(Y6:AJ6) -> 0 | AL6: =AK6/AK$6 -> #DIV/0! | AM6: =IFERROR(AK6/V6-1,0) -> 0
A7: A - INGRESOS | B7: estaciones | C7: INGRESOS MAGNA | D7: INGRESOS FORANEOS MAGNA | I7: T-MAXIMA REGULAR | V7: =SUM(J7:U7) -> 0 | W7: =V7/V$6 -> #DIV/0! | Y7: 0 | Z7: 0 | AA7: 0 | AB7: 0 | AC7: 0 | AD7: 0 | AE7: 0 | AF7: 0 | AG7: 0 | AH7: 0 | AI7: 0 | AJ7: 0 | AK7: =SUM(Y7:AJ7) -> 0 | AL7: =AK7/AK$6 -> #DIV/0! | AM7: =IFERROR(AK7/V7-1,0) -> 0
A8: A - INGRESOS | B8: estaciones | C8: INGRESOS PREMIUM | D8: INGRESOS FORANEOS PREMIUM | I8: T-SUPER PREMIUM | V8: =SUM(J8:U8) -> 0 | W8: =V8/V$6 -> #DIV/0! | Y8: 0 | Z8: 0 | AA8: 0 | AB8: 0 | AC8: 0 | AD8: 0 | AE8: 0 | AF8: 0 | AG8: 0 | AH8: 0 | AI8: 0 | AJ8: 0 | AK8: =SUM(Y8:AJ8) -> 0 | AL8: =AK8/AK$6 -> #DIV/0! | AM8: =IFERROR(AK8/V8-1,0) -> 0
A9: A - INGRESOS | B9: estaciones | C9: INGRESOS DIESEL | D9: INGRESOS FORANEOS DIESEL | I9: DIESEL AUTOMOTRIZ | V9: =SUM(J9:U9) -> 0 | W9: =V9/V$6 -> #DIV/0! | Y9: 0 | Z9: 0 | AA9: 0 | AB9: 0 | AC9: 0 | AD9: 0 | AE9: 0 | AF9: 0 | AG9: 0 | AH9: 0 | AI9: 0 | AJ9: 0 | AK9: =SUM(Y9:AJ9) -> 0 | AL9: =AK9/AK$6 -> #DIV/0! | AM9: =IFERROR(AK9/V9-1,0) -> 0
A10: A - INGRESOS | B10: estaciones | C10: INGRESOS ADITIVOS | D10: INGRESOS ESPECIALES | E10: INGRESOS FORANEOS ADITIVOS | F10: INGRESOS FORANEOS ESPECIALES | G10: INGRESOS FORANEOS LUBRICANTES | H10: INGRESOS LUBRICANTES | I10: INGRESOS ACEITES Y LUBRICANTES | V10: =SUM(J10:U10) -> 0 | W10: =V10/V$6 -> #DIV/0! | Y10: 0 | Z10: 0 | AA10: 0 | AB10: 0 | AC10: 0 | AD10: 0 | AE10: 0 | AF10: 0 | AG10: 0 | AH10: 0 | AI10: 0 | AJ10: 0 | AK10: =SUM(Y10:AJ10) -> 0 | AL10: =AK10/AK$6 -> #DIV/0! | AM10: =IFERROR(AK10/V10-1,0) -> 0
I11: SOBRANTE COMBUSTIBLES
A12: B - COSTO DE VENTA | E12: ( menos ) | I12: B - COSTO DE VENTA | V12: =SUM(J12:U12) -> 0 | W12: =V12/V$6 -> #DIV/0! | Y12: =SUM(Y13:Y32) -> 0 | Z12: =SUM(Z13:Z32) -> 0 | AA12: =SUM(AA13:AA32) -> 0 | AB12: =SUM(AB13:AB32) -> 0 | AC12: =SUM(AC13:AC32) -> 0 | AD12: =SUM(AD13:AD32) -> 0 | AE12: =SUM(AE13:AE32) -> 0 | AF12: =SUM(AF13:AF32) -> 0 | ... AJ12: =SUM(AJ13:AJ32) -> 0 | AK12: =SUM(Y12:AJ12) -> 0 | AL12: =AK12/AK$6 -> #DIV/0! | AM12: =IFERROR(AK12/V12-1,0) -> 0
A13: B - COSTO DE VENTA | C13: COSTO MAGNA | D13: COSTO FORANEO MAGNA | I13: GASOLINA REGULAR | V13: =SUM(J13:U13) -> 0 | W13: =V13/V$6 -> #DIV/0! | Y13: 0 | Z13: 0 | AA13: 0 | AB13: 0 | AC13: 0 | AD13: 0 | AE13: 0 | AF13: 0 | AG13: 0 | AH13: 0 | AI13: 0 | AJ13: 0 | AK13: =SUM(Y13:AJ13) -> 0 | AL13: =AK13/AK$6 -> #DIV/0! | AM13: =IFERROR(AK13/V13-1,0) -> 0
A14: B - COSTO DE VENTA | C14: COSTO PREMIUM | D14: COSTO FORANEO PREMIUM | I14: GASOLINA PREMIUM | V14: =SUM(J14:U14) -> 0 | W14: =V14/V$6 -> #DIV/0! | Y14: 0 | Z14: 0 | AA14: 0 | AB14: 0 | AC14: 0 | AD14: 0 | AE14: 0 | AF14: 0 | AG14: 0 | AH14: 0 | AI14: 0 | AJ14: 0 | AK14: =SUM(Y14:AJ14) -> 0 | AL14: =AK14/AK$6 -> #DIV/0! | AM14: =IFERROR(AK14/V14-1,0) -> 0
A15: B - COSTO DE VENTA | C15: COSTO DIESEL | D15: COSTO FORANEO DIESEL | I15: DIESEL | V15: =SUM(J15:U15) -> 0 | W15: =V15/V$6 -> #DIV/0! | Y15: 0 | Z15: 0 | AA15: 0 | AB15: 0 | AC15: 0 | AD15: 0 | AE15: 0 | AF15: 0 | AG15: 0 | AH15: 0 | AI15: 0 | AJ15: 0 | AK15: =SUM(Y15:AJ15) -> 0 | AL15: =AK15/AK$6 -> #DIV/0! | AM15: =IFERROR(AK15/V15-1,0) -> 0
A16: B - COSTO DE VENTA | C16: Merma Magna | I16: MERMA GASOLINA REGULAR | V16: =SUM(J16:U16) -> 0 | W16: =V16/V$6 -> #DIV/0! | Y16: 0 | Z16: 0 | AA16: 0 | AB16: 0 | AC16: 0 | AD16: 0 | AE16: 0 | AF16: 0 | AG16: 0 | AH16: 0 | AI16: 0 | AJ16: 0 | AK16: =SUM(Y16:AJ16) -> 0 | AL16: =AK16/AK$6 -> #DIV/0! | AM16: =IFERROR(AK16/V16-1,0) -> 0
A17: B - COSTO DE VENTA | C17: Merma Premium | I17: MERMA GASOLINA PREMIUM | V17: =SUM(J17:U17) -> 0 | W17: =V17/V$6 -> #DIV/0! | Y17: 0 | Z17: 0 | AA17: 0 | AB17: 0 | AC17: 0 | AD17: 0 | AE17: 0 | AF17: 0 | AG17: 0 | AH17: 0 | AI17: 0 | AJ17: 0 | AK17: =SUM(Y17:AJ17) -> 0 | AL17: =AK17/AK$6 -> #DIV/0! | AM17: =IFERROR(AK17/V17-1,0) -> 0
A18: B - COSTO DE VENTA | C18: Merma Diesel | I18: MERMA DIESEL | V18: =SUM(J18:U18) -> 0 | W18: =V18/V$6 -> #DIV/0! | Y18: 0 | Z18: 0 | AA18: 0 | AB18: 0 | AC18: 0 | AD18: 0 | AE18: 0 | AF18: 0 | AG18: 0 | AH18: 0 | AI18: 0 | AJ18: 0 | AK18: =SUM(Y18:AJ18) -> 0 | AL18: =AK18/AK$6 -> #DIV/0! | AM18: =IFERROR(AK18/V18-1,0) -> 0
A19: B - COSTO DE VENTA | C19: ADITIVO PARA GASOLINA TMAXIMA (REGULAR) | D19: ADITIVO PARA GASOLINA TMAXIMA( REGULAR) | I19: ADITIVO TOTAL POWER GASOLINA REG | V19: =SUM(J19:U19) -> 0 | W19: =V19/V$6 -> #DIV/0! | Y19: 0 | Z19: 0 | AA19: 0 | AB19: 0 | AC19: 0 | AD19: 0 | AE19: 0 | AF19: 0 | AG19: 0 | AH19: 0 | AI19: 0 | AJ19: 0 | AK19: =SUM(Y19:AJ19) -> 0 | AL19: =AK19/AK$6 -> #DIV/0! | AM19: =IFERROR(AK19/V19-1,0) -> 0
A20: B - COSTO DE VENTA | C20: ADITIVO PARA GASOLINA TSUPER (PREMIUM) | I20: ADITIVO TOTAL POWER GASOLINA PREM | V20: =SUM(J20:U20) -> 0 | W20: =V20/V$6 -> #DIV/0! | Y20: 0 | Z20: 0 | AA20: 0 | AB20: 0 | AC20: 0 | AD20: 0 | AE20: 0 | AF20: 0 | AG20: 0 | AH20: 0 | AI20: 0 | AJ20: 0 | AK20: =SUM(Y20:AJ20) -> 0 | AL20: =AK20/AK$6 -> #DIV/0! | AM20: =IFERROR(AK20/V20-1,0) -> 0
A21: B - COSTO DE VENTA | C21: FLETE MAGNA | I21: FLETE GASOLINA REGULAR | V21: =SUM(J21:U21) -> 0 | W21: =V21/V$6 -> #DIV/0! | Y21: 0 | Z21: 0 | AA21: 0 | AB21: 0 | AC21: 0 | AD21: 0 | AE21: 0 | AF21: 0 | AG21: 0 | AH21: 0 | AI21: 0 | AJ21: 0 | AK21: =SUM(Y21:AJ21) -> 0 | AL21: =AK21/AK$6 -> #DIV/0! | AM21: =IFERROR(AK21/V21-1,0) -> 0
A22: B - COSTO DE VENTA | C22: FLETE PREMIUM | I22: FLETE GASOLINA PREMIUM | V22: =SUM(J22:U22) -> 0 | W22: =V22/V$6 -> #DIV/0! | Y22: 0 | Z22: 0 | AA22: 0 | AB22: 0 | AC22: 0 | AD22: 0 | AE22: 0 | AF22: 0 | AG22: 0 | AH22: 0 | AI22: 0 | AJ22: 0 | AK22: =SUM(Y22:AJ22) -> 0 | AL22: =AK22/AK$6 -> #DIV/0! | AM22: =IFERROR(AK22/V22-1,0) -> 0
A23: B - COSTO DE VENTA | C23: FLETE DIESEL | I23: FLETE DIESEL | V23: =SUM(J23:U23) -> 0 | W23: =V23/V$6 -> #DIV/0! | Y23: 0 | Z23: 0 | AA23: 0 | AB23: 0 | AC23: 0 | AD23: 0 | AE23: 0 | AF23: 0 | AG23: 0 | AH23: 0 | AI23: 0 | AJ23: 0 | AK23: =SUM(Y23:AJ23) -> 0 | AL23: =AK23/AK$6 -> #DIV/0! | AM23: =IFERROR(AK23/V23-1,0) -> 0
A24: B - COSTO DE VENTA | C24: Estimulo IEPS Magna | D24: INGRESOS FORANEOS MAGNA | I24: ESTIMULO REGULAR | V24: =SUM(J24:U24) -> 0 | W24: =V24/V$6 -> #DIV/0! | Y24: 0 | Z24: 0 | AA24: 0 | AB24: 0 | AC24: 0 | AD24: 0 | AE24: 0 | AF24: 0 | AG24: 0 | AH24: 0 | AI24: 0 | AJ24: 0 | AK24: =SUM(Y24:AJ24) -> 0 | AL24: =AK24/AK$6 -> #DIV/0! | AM24: =IFERROR(AK24/V24-1,0) -> 0
A25: B - COSTO DE VENTA | C25: Estimulo IEPS Premium | D25: INGRESOS FORANEOS MAGNA | I25: ESTIMULO PREMIUM | V25: =SUM(J25:U25) -> 0 | W25: =V25/V$6 -> #DIV/0! | Y25: 0 | Z25: 0 | AA25: 0 | AB25: 0 | AC25: 0 | AD25: 0 | AE25: 0 | AF25: 0 | AG25: 0 | AH25: 0 | AI25: 0 | AJ25: 0 | AK25: =SUM(Y25:AJ25) -> 0 | AL25: =AK25/AK$6 -> #DIV/0! | AM25: =IFERROR(AK25/V25-1,0) -> 0
I26: SOBRANTE MAGNA
I27: SOBRANTE PREMIUM
I28: SOBRANTE DIESEL
I29: COSTO ACEITES Y LUBRICANTES
I30: BONIFICACION COMPRA DE COMBUSTIBLE MAGNA
I31: BONIFICACION COMPRA DE COMBUSTIBLE PREMIUM
I32: BONIFICACION COMPRA DE COMBUSTIBLE DIESEL | V32: =SUM(J32:U32) -> 0 | W32: =V32/V$6 -> #DIV/0! | Y32: 0 | Z32: 0 | AA32: 0 | AB32: 0 | AC32: 0 | AD32: 0 | AE32: 0 | AF32: 0 | AG32: 0 | AH32: 0 | AI32: 0 | AJ32: 0 | AK32: =SUM(Y32:AJ32) -> 0 | AL32: =AK32/AK$6 -> #DIV/0! | AM32: =IFERROR(AK32/V32-1,0) -> 0
I33: MARGEN DE UTILIDAD | V33: =V6-V12 -> 0 | W33: =V33/V$6 -> #DIV/0! | Y33: =Y6-Y12 -> 0 | Z33: =Z6-Z12 -> 0 | AA33: =AA6-AA12 -> 0 | AB33: =AB6-AB12 -> 0 | AC33: =AC6-AC12 -> 0 | AD33: =AD6-AD12 -> 0 | AE33: =AE6-AE12 -> 0 | AF33: =AF6-AF12 -> 0 | ... AK33: =AK6-AK12 -> 0 | AL33: =AK33/AK$6 -> #DIV/0! | AM33: =IFERROR(AK33/V33-1,0) -> 0
I34: Regular | V34: =SUM(J34:U34) -> 0 | Y34: =+Y44*Y40 -> 0 | Z34: =+Z44*Z40 -> 0 | AA34: =+AA44*AA40 -> 0 | AB34: =+AB44*AB40 -> 0 | AC34: =+AC44*AC40 -> 0 | AD34: =+AD44*AD40 -> 0 | AE34: =+AE44*AE40 -> 0 | AF34: =+AF44*AF40 -> 0 | ... AJ34: =+AJ44*AJ40 -> 0 | AK34: =SUM(Y34:AJ34) -> 0 | AM34: =IFERROR(AK34/V34-1,0) -> 0
I35: Premium | V35: =SUM(J35:U35) -> 0 | Y35: =+Y45*Y41 -> 0 | Z35: =+Z45*Z41 -> 0 | AA35: =+AA45*AA41 -> 0 | AB35: =+AB45*AB41 -> 0 | AC35: =+AC45*AC41 -> 0 | AD35: =+AD45*AD41 -> 0 | AE35: =+AE45*AE41 -> 0 | AF35: =+AF45*AF41 -> 0 | ... AJ35: =+AJ45*AJ41 -> 0 | AK35: =SUM(Y35:AJ35) -> 0 | AM35: =IFERROR(AK35/V35-1,0) -> 0
I36: Diesel | V36: =SUM(J36:U36) -> 0 | Y36: =+Y46*Y42 -> 0 | Z36: =+Z46*Z42 -> 0 | AA36: =+AA46*AA42 -> 0 | AB36: =+AB46*AB42 -> 0 | AC36: =+AC46*AC42 -> 0 | AD36: =+AD46*AD42 -> 0 | AE36: =+AE46*AE42 -> 0 | AF36: =+AF46*AF42 -> 0 | ... AJ36: =+AJ46*AJ42 -> 0 | AK36: =SUM(Y36:AJ36) -> 0 | AM36: =IFERROR(AK36/V36-1,0) -> 0
I37: *Otros Conceptos
I38: * Aceites y Lubricantes
I39: Litros vendidos | V39: =SUM(J39:U39) -> 0 | W39: =V39/V$39 -> #DIV/0! | Y39: =SUM(Y40:Y42) -> 0 | Z39: =SUM(Z40:Z42) -> 0 | AA39: =SUM(AA40:AA42) -> 0 | AB39: =SUM(AB40:AB42) -> 0 | AC39: =SUM(AC40:AC42) -> 0 | AD39: =SUM(AD40:AD42) -> 0 | AE39: =SUM(AE40:AE42) -> 0 | AF39: =SUM(AF40:AF42) -> 0 | ... AJ39: =SUM(AJ40:AJ42) -> 0 | AK39: =SUM(Y39:AJ39) -> 0 | AL39: =AK39/AK$39 -> #DIV/0! | AM39: =IFERROR(AK39/V39-1,0) -> 0
I40: Regular | V40: =SUM(J40:U40) -> 0 | W40: =V40/V$39 -> #DIV/0! | Y40: 0 | Z40: 0 | AA40: 0 | AB40: 0 | AC40: 0 | AD40: 0 | AE40: 0 | AF40: 0 | AG40: 0 | AH40: 0 | AI40: 0 | AJ40: 0 | AK40: =SUM(Y40:AJ40) -> 0 | AL40: =AK40/AK$39 -> #DIV/0! | AM40: =IFERROR(AK40/V40-1,0) -> 0
I41: Premium | V41: =SUM(J41:U41) -> 0 | W41: =V41/V$39 -> #DIV/0! | Y41: 0 | Z41: 0 | AA41: 0 | AB41: 0 | AC41: 0 | AD41: 0 | AE41: 0 | AF41: 0 | AG41: 0 | AH41: 0 | AI41: 0 | AJ41: 0 | AK41: =SUM(Y41:AJ41) -> 0 | AL41: =AK41/AK$39 -> #DIV/0! | AM41: =IFERROR(AK41/V41-1,0) -> 0
...

Sheet Z

Sheet EDO RESULTADOS MISMAS EST
I1: Mantenimiento de Imagen | J1: 2 | K1: 3 | L1: 4 | M1: 5 | N1: 6 | O1: 7 | Y1: 2 | Z1: 3 | AA1: 4 | AB1: 5 | AC1: 6 | AD1: 7 | AM1: 17 | AQ1: 17
J2: 2025 | V2: TOTAL ANUAL | Y2: 2026 | AK2: PPTO ANUAL MISMAS EST | AO2: PPTO ANUAL TODAS ES
J3: ENE | K3: FEB | L3: MAR | M3: ABR | N3: MAY | O3: JUN | P3: JUL | Q3: AGO | R3: SEP | S3: OCT | T3: NOV | U3: DIC | V3: 2025 | W3: % Part | Y3: ENE | Z3: FEB | AA3: MAR | AB3: ABR | AC3: MAY | AD3: JUN | AE3: JUL | AF3: AGO | AG3: SEP | AH3: OCT | AI3: NOV | AJ3: DIC | AK3: 2026 | AL3: % Part | AM3: Var vs AA% | AO3: 2024 | AP3: % Part | AQ3: Var vs AA%
I4: INGRESOS
A6: A - INGRESOS | E6: ( mas ) | I6: A - INGRESOS | J6: ='TOTAL ESTACIONES'!J6 -> 26878636 | K6: ='TOTAL ESTACIONES'!K6 -> 25528487 | L6: ='TOTAL ESTACIONES'!L6 -> 28307270 | M6: ='TOTAL ESTACIONES'!M6 -> 26579702 | N6: ='TOTAL ESTACIONES'!N6 -> 27359376 | O6: ='TOTAL ESTACIONES'!O6 -> 26727235 | P6: ='TOTAL ESTACIONES'!P6 -> 27912533 | Q6: ='TOTAL ESTACIONES'!Q6 -> 28233403 | ... AM6: ='TOTAL ESTACIONES'!AM6 -> 0.088549483 | AO6: 4.4076062e+09 | AP6: 1 | AQ6: 0.16822054
A7: A - INGRESOS | B7: estaciones | C7: INGRESOS MAGNA | D7: INGRESOS FORANEOS MAGNA | I7: MAXIMA | J7: ='TOTAL ESTACIONES'!J7 -> 19095888 | K7: ='TOTAL ESTACIONES'!K7 -> 17878224 | L7: ='TOTAL ESTACIONES'!L7 -> 19531849 | M7: ='TOTAL ESTACIONES'!M7 -> 18128009 | N7: ='TOTAL ESTACIONES'!N7 -> 18229490 | O7: ='TOTAL ESTACIONES'!O7 -> 18404815 | P7: ='TOTAL ESTACIONES'!P7 -> 19054499 | Q7: ='TOTAL ESTACIONES'!Q7 -> 19328904 | ... AM7: ='TOTAL ESTACIONES'!AM7 -> 0.095949069 | AO7: 3.4888525e+09 | AP7: 0.79155268 | AQ7: 0.14554128
A8: A - INGRESOS | B8: estaciones | C8: INGRESOS PREMIUM | D8: INGRESOS FORANEOS PREMIUM | I8: SUPER | J8: ='TOTAL ESTACIONES'!J8 -> 5623556 | K8: ='TOTAL ESTACIONES'!K8 -> 5345115 | L8: ='TOTAL ESTACIONES'!L8 -> 6151225 | M8: ='TOTAL ESTACIONES'!M8 -> 5648910 | N8: ='TOTAL ESTACIONES'!N8 -> 6559926 | O8: ='TOTAL ESTACIONES'!O8 -> 5655884 | P8: ='TOTAL ESTACIONES'!P8 -> 5857615 | Q8: ='TOTAL ESTACIONES'!Q8 -> 6197597 | ... AM8: ='TOTAL ESTACIONES'!AM8 -> 0.078467684 | AO8: 3.5285587e+08 | AP8: 0.080056124 | AQ8: 0.26460768
A9: A - INGRESOS | B9: estaciones | C9: INGRESOS DIESEL | D9: INGRESOS FORANEOS DIESEL | I9: DIESEL | J9: ='TOTAL ESTACIONES'!J9 -> 2090208 | K9: ='TOTAL ESTACIONES'!K9 -> 2235534 | L9: ='TOTAL ESTACIONES'!L9 -> 2555308 | M9: ='TOTAL ESTACIONES'!M9 -> 2773749 | N9: ='TOTAL ESTACIONES'!N9 -> 2487478 | O9: ='TOTAL ESTACIONES'!O9 -> 2589338 | P9: ='TOTAL ESTACIONES'!P9 -> 2919953 | Q9: ='TOTAL ESTACIONES'!Q9 -> 2619067 | ... AM9: ='TOTAL ESTACIONES'!AM9 -> 0.06380043 | AO9: 5.6589782e+08 | AP9: 0.12839119 | AQ9: 0.3070746
I10: INGRESOS ACEITES Y LUBRICANTES | J10: ='TOTAL ESTACIONES'!J10 -> 68984 | K10: ='TOTAL ESTACIONES'!K10 -> 69614 | L10: ='TOTAL ESTACIONES'!L10 -> 68888 | M10: ='TOTAL ESTACIONES'!M10 -> 29034 | N10: ='TOTAL ESTACIONES'!N10 -> 82482 | O10: ='TOTAL ESTACIONES'!O10 -> 77198 | P10: ='TOTAL ESTACIONES'!P10 -> 80466 | Q10: ='TOTAL ESTACIONES'!Q10 -> 87835 | ... AM10: ='TOTAL ESTACIONES'!AM10 -> -0.11393663 | AO10: 0 | AP10: 0 | AQ10: -1
I11: SOBRANTE COMBUSTIBLES | J11: ='TOTAL ESTACIONES'!J11 -> 0 | K11: ='TOTAL ESTACIONES'!K11 -> 0 | L11: ='TOTAL ESTACIONES'!L11 -> 0 | M11: ='TOTAL ESTACIONES'!M11 -> 0 | N11: ='TOTAL ESTACIONES'!N11 -> 0 | O11: ='TOTAL ESTACIONES'!O11 -> 0 | P11: ='TOTAL ESTACIONES'!P11 -> 0 | Q11: ='TOTAL ESTACIONES'!Q11 -> 0 | ... AM11: ='TOTAL ESTACIONES'!AM11 -> -1 | AO11: 0 | AP11: 0 | AQ11: -1
A12: B - COSTO DE VENTA | E12: ( menos ) | I12: B - COSTO DE VENTA | J12: ='TOTAL ESTACIONES'!J12 -> 24443667 | K12: ='TOTAL ESTACIONES'!K12 -> 22953018 | L12: ='TOTAL ESTACIONES'!L12 -> 25490800 | M12: ='TOTAL ESTACIONES'!M12 -> 23658529 | N12: ='TOTAL ESTACIONES'!N12 -> 24196460 | O12: ='TOTAL ESTACIONES'!O12 -> 23804842 | P12: ='TOTAL ESTACIONES'!P12 -> 25118023 | Q12: ='TOTAL ESTACIONES'!Q12 -> 25414036 | ... AM12: ='TOTAL ESTACIONES'!AM12 -> 0.092700589 | AO12: 3.7568617e+09 | AP12: 0.85235875 | AQ12: 0.16747315
A13: B - COSTO DE VENTA | C13: COSTO MAGNA | D13: COSTO FORANEO MAGNA | I13: GASOLINA REGULAR | J13: ='TOTAL ESTACIONES'!J13 -> 17491983 | K13: ='TOTAL ESTACIONES'!K13 -> 16105749 | L13: ='TOTAL ESTACIONES'!L13 -> 17633587 | M13: ='TOTAL ESTACIONES'!M13 -> 16414267 | N13: ='TOTAL ESTACIONES'!N13 -> 16550960 | O13: ='TOTAL ESTACIONES'!O13 -> 16752932 | P13: ='TOTAL ESTACIONES'!P13 -> 17303449 | Q13: ='TOTAL ESTACIONES'!Q13 -> 17528380 | ... AM13: ='TOTAL ESTACIONES'!AM13 -> 0.10115578 | AO13: 3.5232571e+09 | AP13: 0.7993584 | AQ13: 0.13050349
A14: B - COSTO DE VENTA | C14: COSTO PREMIUM | D14: COSTO FORANEO PREMIUM | I14: GASOLINA PREMIUM | J14: ='TOTAL ESTACIONES'!J14 -> 4933868 | K14: ='TOTAL ESTACIONES'!K14 -> 4692149 | L14: ='TOTAL ESTACIONES'!L14 -> 5366599 | M14: ='TOTAL ESTACIONES'!M14 -> 4909439 | N14: ='TOTAL ESTACIONES'!N14 -> 5542662 | O14: ='TOTAL ESTACIONES'!O14 -> 4823156 | P14: ='TOTAL ESTACIONES'!P14 -> 5160135 | Q14: ='TOTAL ESTACIONES'!Q14 -> 5519068 | ... AM14: ='TOTAL ESTACIONES'!AM14 -> 0.068487031 | AO14: 3.4716629e+08 | AP14: 0.078765269 | AQ14: 0.24745089
A15: B - COSTO DE VENTA | C15: COSTO DIESEL | D15: COSTO FORANEO DIESEL | I15: DIESEL | J15: ='TOTAL ESTACIONES'!J15 -> 1953610 | K15: ='TOTAL ESTACIONES'!K15 -> 2086291 | L15: ='TOTAL ESTACIONES'!L15 -> 2425049 | M15: ='TOTAL ESTACIONES'!M15 -> 2457800 | N15: ='TOTAL ESTACIONES'!N15 -> 2174432 | O15: ='TOTAL ESTACIONES'!O15 -> 2274518 | P15: ='TOTAL ESTACIONES'!P15 -> 2653742 | Q15: ='TOTAL ESTACIONES'!Q15 -> 2343362 | ... AM15: ='TOTAL ESTACIONES'!AM15 -> 0.065487529 | AO15: 5.0123784e+08 | AP15: 0.1137211 | AQ15: 0.29638109
A16: B - COSTO DE VENTA | C16: Merma Magna | I16: MERMA GASOLINA REGULAR | J16: ='TOTAL ESTACIONES'!J16 -> 0 | K16: ='TOTAL ESTACIONES'!K16 -> 0 | L16: ='TOTAL ESTACIONES'!L16 -> 49100 | M16: ='TOTAL ESTACIONES'!M16 -> 0 | N16: ='TOTAL ESTACIONES'!N16 -> 0 | O16: ='TOTAL ESTACIONES'!O16 -> 0 | P16: ='TOTAL ESTACIONES'!P16 -> 0 | Q16: ='TOTAL ESTACIONES'!Q16 -> 0 | ... AM16: ='TOTAL ESTACIONES'!AM16 -> -1 | AO16: 0 | AP16: 0 | AQ16: -1
A17: B - COSTO DE VENTA | C17: Merma Premium | I17: MERMA GASOLINA PREMIUM | J17: ='TOTAL ESTACIONES'!J17 -> 7882 | K17: ='TOTAL ESTACIONES'!K17 -> 14264 | L17: ='TOTAL ESTACIONES'!L17 -> 0 | M17: ='TOTAL ESTACIONES'!M17 -> 0 | N17: ='TOTAL ESTACIONES'!N17 -> 16710 | O17: ='TOTAL ESTACIONES'!O17 -> 0 | P17: ='TOTAL ESTACIONES'!P17 -> 0 | Q17: ='TOTAL ESTACIONES'!Q17 -> 3686 | ... AM17: ='TOTAL ESTACIONES'!AM17 -> -1 | AO17: 0 | AP17: 0 | AQ17: -1
A18: B - COSTO DE VENTA | C18: Merma Diesel | I18: MERMA DIESEL | J18: ='TOTAL ESTACIONES'!J18 -> 0 | K18: ='TOTAL ESTACIONES'!K18 -> 0 | L18: ='TOTAL ESTACIONES'!L18 -> 0 | M18: ='TOTAL ESTACIONES'!M18 -> 0 | N18: ='TOTAL ESTACIONES'!N18 -> 0 | O18: ='TOTAL ESTACIONES'!O18 -> 0 | P18: ='TOTAL ESTACIONES'!P18 -> 0 | Q18: ='TOTAL ESTACIONES'!Q18 -> 0 | ... AM18: ='TOTAL ESTACIONES'!AM18 -> -1 | AO18: 0 | AP18: 0 | AQ18: -1
A19: B - COSTO DE VENTA | C19: ADITIVO PARA GASOLINA TMAXIMA (REGULAR) | D19: ADITIVO PARA GASOLINA TMAXIMA( REGULAR) | I19: ADITIVO TOTAL POWER GASOLINA REG | J19: ='TOTAL ESTACIONES'!J19 -> 37098 | K19: ='TOTAL ESTACIONES'!K19 -> 30373 | L19: ='TOTAL ESTACIONES'!L19 -> 39778 | M19: ='TOTAL ESTACIONES'!M19 -> 31691 | N19: ='TOTAL ESTACIONES'!N19 -> 35405 | O19: ='TOTAL ESTACIONES'!O19 -> 33757 | P19: ='TOTAL ESTACIONES'!P19 -> 37244 | Q19: ='TOTAL ESTACIONES'!Q19 -> 38255 | ... AM19: ='TOTAL ESTACIONES'!AM19 -> -1 | AO19: 0 | AP19: 0 | AQ19: -1
A20: B - COSTO DE VENTA | C20: ADITIVO PARA GASOLINA TSUPER (PREMIUM) | I20: ADITIVO TOTAL POWER GASOLINA PREM | J20: ='TOTAL ESTACIONES'!J20 -> 10383 | K20: ='TOTAL ESTACIONES'!K20 -> 7510 | L20: ='TOTAL ESTACIONES'!L20 -> 11713 | M20: ='TOTAL ESTACIONES'!M20 -> 9665 | N20: ='TOTAL ESTACIONES'!N20 -> 10014 | O20: ='TOTAL ESTACIONES'!O20 -> 10264 | P20: ='TOTAL ESTACIONES'!P20 -> 11873 | Q20: ='TOTAL ESTACIONES'!Q20 -> 9035 | ... AM20: ='TOTAL ESTACIONES'!AM20 -> -1 | AO20: 0 | AP20: 0 | AQ20: -1
A21: B - COSTO DE VENTA | C21: FLETE MAGNA | I21: FLETE GASOLINA REGULAR | J21: ='TOTAL ESTACIONES'!J21 -> 0 | K21: ='TOTAL ESTACIONES'!K21 -> 0 | L21: ='TOTAL ESTACIONES'!L21 -> 0 | M21: ='TOTAL ESTACIONES'!M21 -> 0 | N21: ='TOTAL ESTACIONES'!N21 -> 0 | O21: ='TOTAL ESTACIONES'!O21 -> 0 | P21: ='TOTAL ESTACIONES'!P21 -> 0 | Q21: ='TOTAL ESTACIONES'!Q21 -> 0 | ... AM21: ='TOTAL ESTACIONES'!AM21 -> 0 | AO21: 0 | AP21: 0 | AQ21: -1
A22: B - COSTO DE VENTA | C22: FLETE PREMIUM | I22: FLETE GASOLINA PREMIUM | J22: ='TOTAL ESTACIONES'!J22 -> 0 | K22: ='TOTAL ESTACIONES'!K22 -> 0 | L22: ='TOTAL ESTACIONES'!L22 -> 0 | M22: ='TOTAL ESTACIONES'!M22 -> 0 | N22: ='TOTAL ESTACIONES'!N22 -> 0 | O22: ='TOTAL ESTACIONES'!O22 -> 0 | P22: ='TOTAL ESTACIONES'!P22 -> 0 | Q22: ='TOTAL ESTACIONES'!Q22 -> 0 | ... AM22: ='TOTAL ESTACIONES'!AM22 -> 0 | AO22: 0 | AP22: 0 | AQ22: -1
A23: B - COSTO DE VENTA | C23: FLETE DIESEL | I23: FLETE DIESEL | J23: ='TOTAL ESTACIONES'!J23 -> 0 | K23: ='TOTAL ESTACIONES'!K23 -> 0 | L23: ='TOTAL ESTACIONES'!L23 -> 0 | M23: ='TOTAL ESTACIONES'!M23 -> 0 | N23: ='TOTAL ESTACIONES'!N23 -> 0 | O23: ='TOTAL ESTACIONES'!O23 -> 0 | P23: ='TOTAL ESTACIONES'!P23 -> 0 | Q23: ='TOTAL ESTACIONES'!Q23 -> 0 | ... AM23: ='TOTAL ESTACIONES'!AM23 -> 0 | AO23: 0 | AP23: 0 | AQ23: -1
A24: B - COSTO DE VENTA | C24: Estimulo IEPS Magna | D24: INGRESOS FORANEOS MAGNA | I24: ESTIMULO REGULAR | J24: ='TOTAL ESTACIONES'!J24 -> 0 | K24: ='TOTAL ESTACIONES'!K24 -> 0 | L24: ='TOTAL ESTACIONES'!L24 -> 267 | M24: ='TOTAL ESTACIONES'!M24 -> 0 | N24: ='TOTAL ESTACIONES'!N24 -> 0 | O24: ='TOTAL ESTACIONES'!O24 -> 0 | P24: ='TOTAL ESTACIONES'!P24 -> 0 | Q24: ='TOTAL ESTACIONES'!Q24 -> 0 | ... AM24: ='TOTAL ESTACIONES'!AM24 -> -1 | AO24: -5.7784199e+08 | AP24: -0.13110109 | AQ24: 0.066558616
I25: ESTIMULO PREMIUM | J25: ='TOTAL ESTACIONES'!J25 -> 0 | K25: ='TOTAL ESTACIONES'!K25 -> 0 | L25: ='TOTAL ESTACIONES'!L25 -> 1204 | M25: ='TOTAL ESTACIONES'!M25 -> 2070 | N25: ='TOTAL ESTACIONES'!N25 -> 0 | O25: ='TOTAL ESTACIONES'!O25 -> 0 | P25: ='TOTAL ESTACIONES'!P25 -> 2068 | Q25: ='TOTAL ESTACIONES'!Q25 -> 0 | ... AM25: ='TOTAL ESTACIONES'!AM25 -> -1 | AO25: -36957483 | AP25: -0.0083849329 | AQ25: 0.064257395
I26: SOBRANTE MAGNA | J26: ='TOTAL ESTACIONES'!J26 -> -16996 | K26: ='TOTAL ESTACIONES'!K26 -> -26879 | L26: ='TOTAL ESTACIONES'!L26 -> -49360 | M26: ='TOTAL ESTACIONES'!M26 -> -134972 | N26: ='TOTAL ESTACIONES'!N26 -> -145599 | O26: ='TOTAL ESTACIONES'!O26 -> -112171 | P26: ='TOTAL ESTACIONES'!P26 -> -72748 | Q26: ='TOTAL ESTACIONES'!Q26 -> -71093 | ... AM26: ='TOTAL ESTACIONES'!AM26 -> -1 | AO26: 0 | AP26: 0 | AQ26: -1
I27: SOBRANTE PREMIUM | J27: ='TOTAL ESTACIONES'!J27 -> -15808 | K27: ='TOTAL ESTACIONES'!K27 -> -8530 | L27: ='TOTAL ESTACIONES'!L27 -> -22247 | M27: ='TOTAL ESTACIONES'!M27 -> -24612 | N27: ='TOTAL ESTACIONES'!N27 -> -30658 | O27: ='TOTAL ESTACIONES'!O27 -> -20889 | P27: ='TOTAL ESTACIONES'!P27 -> -26813 | Q27: ='TOTAL ESTACIONES'!Q27 -> -8260 | ... AM27: ='TOTAL ESTACIONES'!AM27 -> -1 | AO27: 6.507445e+08 | AP27: 0.14764125 | AQ27: 0.17255416
I28: SOBRANTE DIESEL | J28: ='TOTAL ESTACIONES'!J28 -> -6436 | K28: ='TOTAL ESTACIONES'!K28 -> 0 | L28: ='TOTAL ESTACIONES'!L28 -> -18941 | M28: ='TOTAL ESTACIONES'!M28 -> -22943 | N28: ='TOTAL ESTACIONES'!N28 -> -9722 | O28: ='TOTAL ESTACIONES'!O28 -> -17371 | P28: ='TOTAL ESTACIONES'!P28 -> -18629 | Q28: ='TOTAL ESTACIONES'!Q28 -> -16467 | ... AM28: ='TOTAL ESTACIONES'!AM28 -> -1 | AO28: 5.4343746e+08 | AP28: #REF! | AQ28: 0.13532128
I29: COSTO ACEITES Y LUBRICANTES | J29: ='TOTAL ESTACIONES'!J29 -> 48083 | K29: ='TOTAL ESTACIONES'!K29 -> 52091 | L29: ='TOTAL ESTACIONES'!L29 -> 54051 | M29: ='TOTAL ESTACIONES'!M29 -> 16124 | N29: ='TOTAL ESTACIONES'!N29 -> 52256 | O29: ='TOTAL ESTACIONES'!O29 -> 60646 | P29: ='TOTAL ESTACIONES'!P29 -> 67702 | Q29: ='TOTAL ESTACIONES'!Q29 -> 68070 | ... AM29: ='TOTAL ESTACIONES'!AM29 -> -0.10860852 | AO29: 42647062 | AP29: #REF! | AQ29: 0.48513341
I30: BONIFICACION COMPRA DE COMBUSTIBLE MAGNA | J30: ='TOTAL ESTACIONES'!J30 -> 0 | K30: ='TOTAL ESTACIONES'!K30 -> 0 | L30: ='TOTAL ESTACIONES'!L30 -> 0 | M30: ='TOTAL ESTACIONES'!M30 -> 0 | N30: ='TOTAL ESTACIONES'!N30 -> 0 | O30: ='TOTAL ESTACIONES'!O30 -> 0 | P30: ='TOTAL ESTACIONES'!P30 -> 0 | Q30: ='TOTAL ESTACIONES'!Q30 -> 0 | ... AM30: ='TOTAL ESTACIONES'!AM30 -> 0 | AO30: 64659974 | AP30: #REF! | AQ30: 0.41061113
I31: BONIFICACION COMPRA DE COMBUSTIBLE PREMIUM | J31: ='TOTAL ESTACIONES'!J31 -> 0 | K31: ='TOTAL ESTACIONES'!K31 -> 0 | L31: ='TOTAL ESTACIONES'!L31 -> 0 | M31: ='TOTAL ESTACIONES'!M31 -> 0 | N31: ='TOTAL ESTACIONES'!N31 -> 0 | O31: ='TOTAL ESTACIONES'!O31 -> 0 | P31: ='TOTAL ESTACIONES'!P31 -> 0 | Q31: ='TOTAL ESTACIONES'!Q31 -> 0 | ... AM31: ='TOTAL ESTACIONES'!AM31 -> 0 | AO31: 0 | AP31: #REF! | AQ31: -1
I32: BONIFICACION COMPRA DE COMBUSTIBLE DIESEL | J32: 0 | K32: ='TOTAL ESTACIONES'!K32 -> 0 | L32: ='TOTAL ESTACIONES'!L32 -> 0 | M32: ='TOTAL ESTACIONES'!M32 -> 0 | N32: ='TOTAL ESTACIONES'!N32 -> 0 | O32: ='TOTAL ESTACIONES'!O32 -> 0 | P32: ='TOTAL ESTACIONES'!P32 -> 0 | Q32: ='TOTAL ESTACIONES'!Q32 -> 0 | R32: ='TOTAL ESTACIONES'!R32 -> 0 | ... AM32: ='TOTAL ESTACIONES'!AM32 -> 0 | AO32: 2.4593624e+08 | AQ32: 0.1359541
I33: MARGEN DE UTILIDAD | J33: ='TOTAL ESTACIONES'!J33 -> 2434969 | K33: ='TOTAL ESTACIONES'!K33 -> 2575469 | L33: ='TOTAL ESTACIONES'!L33 -> 2816470 | M33: ='TOTAL ESTACIONES'!M33 -> 2921173 | N33: ='TOTAL ESTACIONES'!N33 -> 3162916 | O33: ='TOTAL ESTACIONES'!O33 -> 2922393 | P33: ='TOTAL ESTACIONES'!P33 -> 2794510 | Q33: ='TOTAL ESTACIONES'!Q33 -> 2819367 | ... AM33: ='TOTAL ESTACIONES'!AM33 -> 0.052059696 | AO33: 2.0184766e+08 | AP33: 0.045795303 | AQ33: 0.11498405 | AR33: =+AK33-V33 -> 1752691.5
I34: *Regular | J34: ='TOTAL ESTACIONES'!J34 -> 1583804 | K34: ='TOTAL ESTACIONES'!K34 -> 1768980 | L34: ='TOTAL ESTACIONES'!L34 -> 1858476 | M34: ='TOTAL ESTACIONES'!M34 -> 1817025 | N34: ='TOTAL ESTACIONES'!N34 -> 1788723 | O34: ='TOTAL ESTACIONES'!O34 -> 1730298 | P34: ='TOTAL ESTACIONES'!P34 -> 1786554 | Q34: ='TOTAL ESTACIONES'!Q34 -> 1833363 | ... AM34: ='TOTAL ESTACIONES'!AM34 -> 0.050590609 | AO34: 17513400 | AP34: 0.0039734494 | AQ34: 0.2160961
I35: *Premium | J35: ='TOTAL ESTACIONES'!J35 -> 687232 | K35: ='TOTAL ESTACIONES'!K35 -> 639721 | L35: ='TOTAL ESTACIONES'!L35 -> 793954 | M35: ='TOTAL ESTACIONES'!M35 -> 752348 | N35: ='TOTAL ESTACIONES'!N35 -> 1021198 | O35: ='TOTAL ESTACIONES'!O35 -> 843354 | P35: ='TOTAL ESTACIONES'!P35 -> 710352 | Q35: ='TOTAL ESTACIONES'!Q35 -> 674069 | ... AM35: ='TOTAL ESTACIONES'!AM35 -> 0.096472781 | AO35: 26575182 | AP35: 0.0060293911 | AQ35: 0.26135799
I36: *Diesel | J36: ='TOTAL ESTACIONES'!J36 -> 143034 | K36: ='TOTAL ESTACIONES'!K36 -> 149243 | L36: ='TOTAL ESTACIONES'!L36 -> 149199 | M36: ='TOTAL ESTACIONES'!M36 -> 338891 | N36: ='TOTAL ESTACIONES'!N36 -> 322767 | O36: ='TOTAL ESTACIONES'!O36 -> 332192 | P36: ='TOTAL ESTACIONES'!P36 -> 284840 | Q36: ='TOTAL ESTACIONES'!Q36 -> 292173 | ... AM36: ='TOTAL ESTACIONES'!AM36 -> -0.059416968 | AO36: 2.6459886 | AQ36: 0.029597448
I37: *Otros Conceptos | J37: ='TOTAL ESTACIONES'!J37 -> 20901 | K37: ='TOTAL ESTACIONES'!K37 -> 17524 | L37: ='TOTAL ESTACIONES'!L37 -> 14837 | M37: ='TOTAL ESTACIONES'!M37 -> 12910 | N37: ='TOTAL ESTACIONES'!N37 -> 30226 | O37: ='TOTAL ESTACIONES'!O37 -> 16552 | P37: ='TOTAL ESTACIONES'!P37 -> 12763 | Q37: ='TOTAL ESTACIONES'!Q37 -> 19765 | ... AM37: ='TOTAL ESTACIONES'!AM37 -> -1
I38: * Aceites y Lubricantes | J38: ='TOTAL ESTACIONES'!J38 -> 0 | K38: ='TOTAL ESTACIONES'!K38 -> 0 | L38: ='TOTAL ESTACIONES'!L38 -> 0 | M38: ='TOTAL ESTACIONES'!M38 -> 0 | N38: ='TOTAL ESTACIONES'!N38 -> 0 | O38: ='TOTAL ESTACIONES'!O38 -> 0 | P38: ='TOTAL ESTACIONES'!P38 -> 0 | Q38: ='TOTAL ESTACIONES'!Q38 -> 0 | ... AM38: ='TOTAL ESTACIONES'!AM38 -> 0 | AO38: 2.6923149 | AP38: 6.108338e-10 | AQ38: 0.03693009
I39: Litros vendidos | J39: ='TOTAL ESTACIONES'!J39 -> 1223164 | K39: ='TOTAL ESTACIONES'!K39 -> 1160892 | L39: ='TOTAL ESTACIONES'!L39 -> 1313320 | M39: ='TOTAL ESTACIONES'!M39 -> 1240762 | N39: ='TOTAL ESTACIONES'!N39 -> 1272351 | O39: ='TOTAL ESTACIONES'!O39 -> 1247404 | P39: ='TOTAL ESTACIONES'!P39 -> 1302246 | Q39: ='TOTAL ESTACIONES'!Q39 -> 1316933 | ... AM39: ='TOTAL ESTACIONES'!AM39 -> 0.048636775 | AO39: 2.4351104 | AP39: 5.5247911e-10 | AQ39: 0.11346523 | AR39: =+AK39/12 -> 1366631.3 | AS39: AUMENTOEN VTA GOMEZ A 1,365M
I40: Maxima | J40: ='TOTAL ESTACIONES'!J40 -> 1223164 | K40: ='TOTAL ESTACIONES'!K40 -> 830539 | L40: ='TOTAL ESTACIONES'!L40 -> 933279 | M40: ='TOTAL ESTACIONES'!M40 -> 873321 | N40: ='TOTAL ESTACIONES'!N40 -> 878218 | O40: ='TOTAL ESTACIONES'!O40 -> 887806 | P40: ='TOTAL ESTACIONES'!P40 -> 918225 | Q40: ='TOTAL ESTACIONES'!Q40 -> 931120 | ... AM40: ='TOTAL ESTACIONES'!AM40 -> 0.027932192 | AO40: 2.4330962 | AP40: 5.5202214e-10 | AQ40: 0.11307939
I41: Super | J41: ='TOTAL ESTACIONES'!J41 -> 887027 | K41: ='TOTAL ESTACIONES'!K41 -> 231283 | L41: ='TOTAL ESTACIONES'!L41 -> 266800 | M41: ='TOTAL ESTACIONES'!M41 -> 244981 | N41: ='TOTAL ESTACIONES'!N41 -> 284526 | O41: ='TOTAL ESTACIONES'!O41 -> 245926 | P41: ='TOTAL ESTACIONES'!P41 -> 256948 | Q41: ='TOTAL ESTACIONES'!Q41 -> 271880 | ... AM41: ='TOTAL ESTACIONES'!AM41 -> -0.14710953
...

Sheet TOTAL ESTACIONES
I1: 1147 | J1: 2 | K1: 3 | L1: 4 | M1: 5 | N1: 6 | O1: 7 | Y1: 2 | Z1: =+Y1+1 -> 3 | AA1: =+Z1+1 -> 4 | AB1: =+AA1+1 -> 5 | AC1: =+AB1+1 -> 6 | AD1: =+AC1+1 -> 7 | AE1: =+AD1+1 -> 8 | AF1: =+AE1+1 -> 9 | AG1: =+AF1+1 -> 10 | ... AK1: =+AJ1+1 -> 14 | AM1: 17
J2: 2025 | V2: TOTAL ANUAL | Y2: 2026 | AK2: TOTAL ANUAL
J3: ENE | K3: FEB | L3: MAR | M3: ABR | N3: MAY | O3: JUN | P3: JUL | Q3: AGO | R3: SEP | S3: OCT | T3: NOV | U3: DIC | V3: 2025 | W3: % Part | Y3: ENE | Z3: FEB | AA3: MAR | AB3: ABR | AC3: MAY | AD3: JUN | AE3: JUL | AF3: AGO | AG3: SEP | AH3: OCT | AI3: NOV | AJ3: DIC | AK3: 2026 | AL3: % Part | AM3: Var vs AA%
I4: INGRESOS
A6: A - INGRESOS | E6: ( mas ) | I6: A - INGRESOS | J6: =SUM(J7:J11) -> 26878636 | K6: =SUM(K7:K11) -> 25528487 | L6: =SUM(L7:L11) -> 28307270 | M6: =SUM(M7:M11) -> 26579702 | N6: =SUM(N7:N11) -> 27359376 | O6: =SUM(O7:O11) -> 26727235 | P6: =SUM(P7:P11) -> 27912533 | Q6: =SUM(Q7:Q11) -> 28233403 | ... V6: =SUM(V7:V11) -> 3.2961219e+08 | W6: =V6/V$6 -> 1 | Y6: =SUM(Y7:Y11) -> 27944944 | Z6: =SUM(Z7:Z11) -> 26629774 | AA6: =SUM(AA7:AA11) -> 29599780 | AB6: =SUM(AB7:AB11) -> 28667280 | AC6: =SUM(AC7:AC11) -> 29293497 | AD6: =SUM(AD7:AD11) -> 28502875 | AE6: =SUM(AE7:AE11) -> 29846068 | AF6: =SUM(AF7:AF11) -> 30746358 | ... AK6: =SUM(AK7:AK11) -> 3.5879918e+08 | AL6: =AK6/AK$6 -> 1 | AM6: =IFERROR(AK6/V6-1,0) -> 0.088549483
A7: A - INGRESOS | B7: estaciones | C7: INGRESOS MAGNA | D7: INGRESOS FORANEOS MAGNA | I7: MAXIMA | J7: =SUM(A:B!J7) -> 19095888 | K7: =SUM(A:B!K7) -> 17878224 | L7: =SUM(A:B!L7) -> 19531849 | M7: =SUM(A:B!M7) -> 18128009 | N7: =SUM(A:B!N7) -> 18229490 | O7: =SUM(A:B!O7) -> 18404815 | P7: =SUM(A:B!P7) -> 19054499 | Q7: =SUM(A:B!Q7) -> 19328904 | ... U7: =SUM(A:B!U7) -> 19683942 | V7: =SUM(J7:U7) -> 2.2908738e+08 | W7: =V7/V$6 -> 0.69502095 | Y7: =SUM(A:B!Y7) -> 20069259 | Z7: =SUM(A:B!Z7) -> 18878938 | AA7: =SUM(A:B!AA7) -> 20696571 | AB7: =SUM(A:B!AB7) -> 19985650 | AC7: =SUM(A:B!AC7) -> 19971013 | AD7: =SUM(A:B!AD7) -> 19987524 | AE7: =SUM(A:B!AE7) -> 20742643 | AF7: =SUM(A:B!AF7) -> 21382459 | ... AJ7: =SUM(A:B!AJ7) -> 22296641 | AK7: =SUM(Y7:AJ7) -> 2.510681e+08 | AL7: =AK7/AK$6 -> 0.69974547 | AM7: =IFERROR(AK7/V7-1,0) -> 0.095949069
A8: A - INGRESOS | B8: estaciones | C8: INGRESOS PREMIUM | D8: INGRESOS FORANEOS PREMIUM | I8: SUPER | J8: =SUM(A:B!J8) -> 5623556 | K8: =SUM(A:B!K8) -> 5345115 | L8: =SUM(A:B!L8) -> 6151225 | M8: =SUM(A:B!M8) -> 5648910 | N8: =SUM(A:B!N8) -> 6559926 | O8: =SUM(A:B!O8) -> 5655884 | P8: =SUM(A:B!P8) -> 5857615 | Q8: =SUM(A:B!Q8) -> 6197597 | ... U8: =SUM(A:B!U8) -> 4928022.3 | V8: =SUM(J8:U8) -> 69879978 | W8: =V8/V$6 -> 0.21200666 | Y8: =SUM(A:B!Y8) -> 5721139.6 | Z8: =SUM(A:B!Z8) -> 5449897 | AA8: =SUM(A:B!AA8) -> 6281390.6 | AB8: =SUM(A:B!AB8) -> 5824968.5 | AC8: =SUM(A:B!AC8) -> 6759520.8 | AD8: =SUM(A:B!AD8) -> 5854609.9 | AE8: =SUM(A:B!AE8) -> 6129670 | AF8: =SUM(A:B!AF8) -> 6631650.4 | ... AJ8: =SUM(A:B!AJ8) -> 6621310.6 | AK8: =SUM(Y8:AJ8) -> 75363298 | AL8: =AK8/AK$6 -> 0.21004312 | AM8: =IFERROR(AK8/V8-1,0) -> 0.078467684
A9: A - INGRESOS | B9: estaciones | C9: INGRESOS DIESEL | D9: INGRESOS FORANEOS DIESEL | I9: DIESEL | J9: =SUM(A:B!J9) -> 2090208 | K9: =SUM(A:B!K9) -> 2235534 | L9: =SUM(A:B!L9) -> 2555308 | M9: =SUM(A:B!M9) -> 2773749 | N9: =SUM(A:B!N9) -> 2487478 | O9: =SUM(A:B!O9) -> 2589338 | P9: =SUM(A:B!P9) -> 2919953 | Q9: =SUM(A:B!Q9) -> 2619067 | ... U9: =SUM(A:B!U9) -> 1813405.3 | V9: =SUM(J9:U9) -> 29789555 | W9: =V9/V$6 -> 0.090377589 | Y9: =SUM(A:B!Y9) -> 2101264.8 | Z9: =SUM(A:B!Z9) -> 2246999.9 | AA9: =SUM(A:B!AA9) -> 2566198.5 | AB9: =SUM(A:B!AB9) -> 2802661.6 | AC9: =SUM(A:B!AC9) -> 2506382.7 | AD9: =SUM(A:B!AD9) -> 2604761.2 | AE9: =SUM(A:B!AE9) -> 2917835.2 | AF9: =SUM(A:B!AF9) -> 2674948.2 | ... AJ9: =SUM(A:B!AJ9) -> 2589138.1 | AK9: =SUM(Y9:AJ9) -> 31690141 | AL9: =AK9/AK$6 -> 0.088322782 | AM9: =IFERROR(AK9/V9-1,0) -> 0.06380043
I10: INGRESOS ACEITES Y LUBRICANTES | J10: =SUM(A:B!J10) -> 68984 | K10: =SUM(A:B!K10) -> 69614 | L10: =SUM(A:B!L10) -> 68888 | M10: =SUM(A:B!M10) -> 29034 | N10: =SUM(A:B!N10) -> 82482 | O10: =SUM(A:B!O10) -> 77198 | P10: =SUM(A:B!P10) -> 80466 | Q10: =SUM(A:B!Q10) -> 87835 | ... U10: =SUM(A:B!U10) -> 57600 | V10: =SUM(J10:U10) -> 764776 | W10: =V10/V$6 -> 0.0023202297 | Y10: =SUM(A:B!Y10) -> 53280 | Z10: =SUM(A:B!Z10) -> 53940 | AA10: =SUM(A:B!AA10) -> 55620 | AB10: =SUM(A:B!AB10) -> 54000 | AC10: =SUM(A:B!AC10) -> 56580 | AD10: =SUM(A:B!AD10) -> 55980 | AE10: =SUM(A:B!AE10) -> 55920 | AF10: =SUM(A:B!AF10) -> 57300 | ... AJ10: =SUM(A:B!AJ10) -> 59880 | AK10: =SUM(Y10:AJ10) -> 677640 | AL10: =AK10/AK$6 -> 0.0018886331 | AM10: =IFERROR(AK10/V10-1,0) -> -0.11393663
I11: SOBRANTE COMBUSTIBLE | J11: =SUM(A:B!J11) -> 0 | K11: =SUM(A:B!K11) -> 0 | L11: =SUM(A:B!L11) -> 0 | M11: =SUM(A:B!M11) -> 0 | N11: =SUM(A:B!N11) -> 0 | O11: =SUM(A:B!O11) -> 0 | P11: =SUM(A:B!P11) -> 0 | Q11: =SUM(A:B!Q11) -> 0 | ... U11: =SUM(A:B!U11) -> 0 | V11: =SUM(J11:U11) -> 90502 | W11: =V11/V$6 -> 0.00027457116 | Y11: =SUM(A:B!Y11) -> 0 | Z11: =SUM(A:B!Z11) -> 0 | AA11: =SUM(A:B!AA11) -> 0 | AB11: =SUM(A:B!AB11) -> 0 | AC11: =SUM(A:B!AC11) -> 0 | AD11: =SUM(A:B!AD11) -> 0 | AE11: =SUM(A:B!AE11) -> 0 | AF11: =SUM(A:B!AF11) -> 0 | ... AJ11: =SUM(A:B!AJ11) -> 0 | AK11: =SUM(Y11:AJ11) -> 0 | AL11: =AK11/AK$6 -> 0 | AM11: =IFERROR(AK11/V11-1,0) -> -1
A12: B - COSTO DE VENTA | E12: ( menos ) | I12: B - COSTO DE VENTA | J12: =SUM(J13:J32) -> 24443667 | K12: =SUM(K13:K32) -> 22953018 | L12: =SUM(L13:L32) -> 25490800 | M12: =SUM(M13:M32) -> 23658529 | N12: =SUM(N13:N32) -> 24196460 | O12: =SUM(O13:O32) -> 23804842 | P12: =SUM(P13:P32) -> 25118023 | Q12: =SUM(Q13:Q32) -> 25414036 | ... U12: =SUM(U13:U32) -> 23870496 | V12: =SUM(V13:V29) -> 2.9594523e+08 | W12: =V12/V$6 -> 0.89785889 | Y12: =SUM(Y13:Y32) -> 25186024 | Z12: =SUM(Z13:Z32) -> 24068620 | AA12: =SUM(AA13:AA32) -> 26544130 | AB12: =SUM(AB13:AB32) -> 25888493 | AC12: =SUM(AC13:AC32) -> 26362658 | AD12: =SUM(AD13:AD32) -> 25744522 | AE12: =SUM(AE13:AE32) -> 26850833 | AF12: =SUM(AF13:AF32) -> 27683501 | ... AJ12: =SUM(AJ13:AJ32) -> 28510625 | AK12: =SUM(Y12:AJ12) -> 3.2337953e+08 | AL12: =AK12/AK$6 -> 0.90128281 | AM12: =IFERROR(AK12/V12-1,0) -> 0.092700589
A13: B - COSTO DE VENTA | C13: COSTO MAGNA | D13: COSTO FORANEO MAGNA | I13: GASOLINA REGULAR | J13: =SUM(A:B!J13) -> 17491983 | K13: =SUM(A:B!K13) -> 16105749 | L13: =SUM(A:B!L13) -> 17633587 | M13: =SUM(A:B!M13) -> 16414267 | N13: =SUM(A:B!N13) -> 16550960 | O13: =SUM(A:B!O13) -> 16752932 | P13: =SUM(A:B!P13) -> 17303449 | Q13: =SUM(A:B!Q13) -> 17528380 | ... U13: =SUM(A:B!U13) -> 17748781 | V13: =SUM(J13:U13) -> 2.0763024e+08 | W13: =V13/V$6 -> 0.62992283 | Y13: =SUM(A:B!Y13) -> 18268310 | Z13: =SUM(A:B!Z13) -> 17247148 | AA13: =SUM(A:B!AA13) -> 18765788 | AB13: =SUM(A:B!AB13) -> 18233965 | AC13: =SUM(A:B!AC13) -> 18195727 | AD13: =SUM(A:B!AD13) -> 18213411 | AE13: =SUM(A:B!AE13) -> 18857424 | AF13: =SUM(A:B!AF13) -> 19454504 | ... AJ13: =SUM(A:B!AJ13) -> 20340563 | AK13: =SUM(Y13:AJ13) -> 2.2863324e+08 | AL13: =AK13/AK$6 -> 0.63721786 | AM13: =IFERROR(AK13/V13-1,0) -> 0.10115578
A14: B - COSTO DE VENTA | C14: COSTO PREMIUM | D14: COSTO FORANEO PREMIUM | I14: GASOLINA PREMIUM | J14: =SUM(A:B!J14) -> 4933868 | K14: =SUM(A:B!K14) -> 4692149 | L14: =SUM(A:B!L14) -> 5366599 | M14: =SUM(A:B!M14) -> 4909439 | N14: =SUM(A:B!N14) -> 5542662 | O14: =SUM(A:B!O14) -> 4823156 | P14: =SUM(A:B!P14) -> 5160135 | Q14: =SUM(A:B!Q14) -> 5519068 | ... U14: =SUM(A:B!U14) -> 4424658.4 | V14: =SUM(J14:U14) -> 61294501 | W14: =V14/V$6 -> 0.18595945 | Y14: =SUM(A:B!Y14) -> 4970410 | Z14: =SUM(A:B!Z14) -> 4748550.6 | AA14: =SUM(A:B!AA14) -> 5422697.3 | AB14: =SUM(A:B!AB14) -> 5082200.1 | AC14: =SUM(A:B!AC14) -> 5835553.5 | AD14: =SUM(A:B!AD14) -> 5129082.5 | AE14: =SUM(A:B!AE14) -> 5317297.7 | AF14: =SUM(A:B!AF14) -> 5746258.5 | ... AJ14: =SUM(A:B!AJ14) -> 5766809 | AK14: =SUM(Y14:AJ14) -> 65492380 | AL14: =AK14/AK$6 -> 0.18253213 | AM14: =IFERROR(AK14/V14-1,0) -> 0.068487031
A15: B - COSTO DE VENTA | C15: COSTO DIESEL | D15: COSTO FORANEO DIESEL | I15: DIESEL | J15: =SUM(A:B!J15) -> 1953610 | K15: =SUM(A:B!K15) -> 2086291 | L15: =SUM(A:B!L15) -> 2425049 | M15: =SUM(A:B!M15) -> 2457800 | N15: =SUM(A:B!N15) -> 2174432 | O15: =SUM(A:B!O15) -> 2274518 | P15: =SUM(A:B!P15) -> 2653742 | Q15: =SUM(A:B!Q15) -> 2343362 | ... U15: =SUM(A:B!U15) -> 1648096.2 | V15: =SUM(J15:U15) -> 26915297 | W15: =V15/V$6 -> 0.081657469 | Y15: =SUM(A:B!Y15) -> 1902016.8 | Z15: =SUM(A:B!Z15) -> 2027072.5 | AA15: =SUM(A:B!AA15) -> 2308368.1 | AB15: =SUM(A:B!AB15) -> 2526428.2 | AC15: =SUM(A:B!AC15) -> 2283284.2 | AD15: =SUM(A:B!AD15) -> 2354445.4 | AE15: =SUM(A:B!AE15) -> 2628579.4 | AF15: =SUM(A:B!AF15) -> 2434033.6 | ... AJ15: =SUM(A:B!AJ15) -> 2352354.9 | AK15: =SUM(Y15:AJ15) -> 28677913 | AL15: =AK15/AK$6 -> 0.079927478 | AM15: =IFERROR(AK15/V15-1,0) -> 0.065487529
A16: B - COSTO DE VENTA | C16: Merma Magna | I16: MERMA GASOLINA REGULAR | J16: =SUM(A:B!J16) -> 0 | K16: =SUM(A:B!K16) -> 0 | L16: =SUM(A:B!L16) -> 49100 | M16: =SUM(A:B!M16) -> 0 | N16: =SUM(A:B!N16) -> 0 | O16: =SUM(A:B!O16) -> 0 | P16: =SUM(A:B!P16) -> 0 | Q16: =SUM(A:B!Q16) -> 0 | ... U16: =SUM(A:B!U16) -> 0 | V16: =SUM(J16:U16) -> 49100 | W16: =V16/V$6 -> 0.00014896294 | Y16: =SUM(A:B!Y16) -> 0 | Z16: =SUM(A:B!Z16) -> 0 | AA16: =SUM(A:B!AA16) -> 0 | AB16: =SUM(A:B!AB16) -> 0 | AC16: =SUM(A:B!AC16) -> 0 | AD16: =SUM(A:B!AD16) -> 0 | AE16: =SUM(A:B!AE16) -> 0 | AF16: =SUM(A:B!AF16) -> 0 | ... AJ16: =SUM(A:B!AJ16) -> 0 | AK16: =SUM(Y16:AJ16) -> 0 | AL16: =AK16/AK$6 -> 0 | AM16: =IFERROR(AK16/V16-1,0) -> -1
A17: B - COSTO DE VENTA | C17: Merma Premium | I17: MERMA GASOLINA PREMIUM | J17: =SUM(A:B!J17) -> 7882 | K17: =SUM(A:B!K17) -> 14264 | L17: =SUM(A:B!L17) -> 0 | M17: =SUM(A:B!M17) -> 0 | N17: =SUM(A:B!N17) -> 16710 | O17: =SUM(A:B!O17) -> 0 | P17: =SUM(A:B!P17) -> 0 | Q17: =SUM(A:B!Q17) -> 3686 | ... U17: =SUM(A:B!U17) -> 0 | V17: =SUM(J17:U17) -> 42542 | W17: =V17/V$6 -> 0.00012906683 | Y17: =SUM(A:B!Y17) -> 0 | Z17: =SUM(A:B!Z17) -> 0 | AA17: =SUM(A:B!AA17) -> 0 | AB17: =SUM(A:B!AB17) -> 0 | AC17: =SUM(A:B!AC17) -> 0 | AD17: =SUM(A:B!AD17) -> 0 | AE17: =SUM(A:B!AE17) -> 0 | AF17: =SUM(A:B!AF17) -> 0 | ... AJ17: =SUM(A:B!AJ17) -> 0 | AK17: =SUM(Y17:AJ17) -> 0 | AL17: =AK17/AK$6 -> 0 | AM17: =IFERROR(AK17/V17-1,0) -> -1
A18: B - COSTO DE VENTA | C18: Merma Diesel | I18: MERMA DIESEL | J18: =SUM(A:B!J18) -> 0 | K18: =SUM(A:B!K18) -> 0 | L18: =SUM(A:B!L18) -> 0 | M18: =SUM(A:B!M18) -> 0 | N18: =SUM(A:B!N18) -> 0 | O18: =SUM(A:B!O18) -> 0 | P18: =SUM(A:B!P18) -> 0 | Q18: =SUM(A:B!Q18) -> 0 | ... U18: =SUM(A:B!U18) -> 0 | V18: =SUM(J18:U18) -> 33294 | W18: =V18/V$6 -> 0.00010100961 | Y18: =SUM(A:B!Y18) -> 0 | Z18: =SUM(A:B!Z18) -> 0 | AA18: =SUM(A:B!AA18) -> 0 | AB18: =SUM(A:B!AB18) -> 0 | AC18: =SUM(A:B!AC18) -> 0 | AD18: =SUM(A:B!AD18) -> 0 | AE18: =SUM(A:B!AE18) -> 0 | AF18: =SUM(A:B!AF18) -> 0 | ... AJ18: =SUM(A:B!AJ18) -> 0 | AK18: =SUM(Y18:AJ18) -> 0 | AL18: =AK18/AK$6 -> 0 | AM18: =IFERROR(AK18/V18-1,0) -> -1
