Workbook
Name AAI: #REF!
Name ALGDED: #REF!
Name BALANZADIC: #REF!
Name BALANZADIC14: #REF!
Name BGDECL: #REF!
Name CCF: #REF!
Name EJERCICIO: #REF!
Name ENERO16: #REF!
Name ENERO16: #REF!
Name ENERO16: #REF!
Name ENERO16: #REF!
Name ENERO16: #REF!
Name ENERO16: #REF!
Name ENERO16: #REF!
Name ERDECL: #REF!
Name inpc: #REF!
Name No_MES: #REF!
Name NombreRango1: #REF!
Name NombreRango1: #REF!
Name NombreRango1: #REF!
Name NombreRango1: #REF!
Name NombreRango1: #REF!
Name NombreRango1: #REF!
Name NombreRango1: #REF!
Name VAC: #REF!

Sheet Parametros AGS
A1: ESTIMULO FISCAL | D1: IEPS
A2: REGULAR | D2: REGULAR | E2: 0.522479 | I2: *Aumento en los ingresos en proporcion minima a la inflacion
A3: PREMIUM | D3: PREMIUM | E3: 0.637522
A4: DIESEL | D4: DIESEL | E4: 0.433626
A6: Precio final al 27 de Octubre de 2025 | D6: Precio de venta sin IVA | G6: MONTEBLANCO | H6: SAN RAFEL | I6: PUERTECITO | J6: JESUS MARIA | L6: MONTEBLANCO | M6: SAN RAFEL | N6: PUERTECITO | O6: JESUS MARIA
A7: REGULAR | B7: 24 | D7: =+B7/1.08 -> 22.222222 | G7: 21.944444 | H7: 21.944444 | I7: 21.944444 | J7: 21.944444 | L7: 21.4 | M7: 21.4 | N7: 21.4 | O7: 21.4
A8: PREMIUM | B8: 25 | D8: =+B8/1.08 -> 23.148148 | G8: 23.148148 | H8: 23.148148 | I8: 23.148148 | J8: 23.148148 | L8: 22.82 | M8: 22.82 | N8: 22.82 | O8: 22.82
A9: DIESEL | B9: 26.9 | D9: =+B9/1.08 -> 24.907407 | G9: 24.907407 | H9: 24.907407 | I9: 24.907407 | J9: 24.907407 | L9: 24.45 | M9: 24.45 | N9: 24.45 | O9: 24.45
A11: PRECIO DE VENTA sin IVA por LITRO
A12: Ags | B12: 0.004 | C12: 0.004 | D12: 0.004 | E12: 0.004 | F12: 0.004 | G12: 0.004 | H12: 0.004 | I12: 0.004 | J12: 0.004 | K12: 0.004 | L12: 0.004 | M12: 0.004
A13: P.V. | B13: Enero | C13: Febrero | D13: Marzo | E13: Abril | F13: Mayo | G13: Junio | H13: Julio | I13: Agosto | J13: Septiembre | K13: Octubre | L13: Noviembre | M13: Diciembre
A14: MAXIMA | B14: =+D7 -> 22.222222 | C14: =B14*(1+$C$12) -> 22.311111 | D14: =C14*(1+$C$12) -> 22.400356 | E14: =D14*(1+$C$12) -> 22.489957 | F14: =E14*(1+$C$12) -> 22.579917 | G14: =F14*(1+$C$12) -> 22.670236 | H14: =G14*(1+$C$12) -> 22.760917 | I14: =H14*(1+$C$12) -> 22.851961 | J14: =I14*(1+$C$12) -> 22.943369 | ... M14: =L14*(1+$C$12) -> 23.219792
A15: SUPER | B15: =+D8 -> 23.148148 | C15: =B15*(1+$C$12) -> 23.240741 | D15: =C15*(1+$C$12) -> 23.333704 | E15: =D15*(1+$C$12) -> 23.427039 | F15: =E15*(1+$C$12) -> 23.520747 | G15: =F15*(1+$C$12) -> 23.61483 | H15: =G15*(1+$C$12) -> 23.709289 | I15: =H15*(1+$C$12) -> 23.804126 | J15: =I15*(1+$C$12) -> 23.899343 | ... M15: =L15*(1+$C$12) -> 24.187283
A16: DIESEL | B16: =+D9 -> 24.907407 | C16: =B16*(1+$C$12) -> 25.007037 | D16: =C16*(1+$C$12) -> 25.107065 | E16: =D16*(1+$C$12) -> 25.207493 | F16: =E16*(1+$C$12) -> 25.308323 | G16: =F16*(1+$C$12) -> 25.409557 | H16: =G16*(1+$C$12) -> 25.511195 | I16: =H16*(1+$C$12) -> 25.61324 | J16: =I16*(1+$C$12) -> 25.715693 | ... M16: =L16*(1+$C$12) -> 26.025517
A18: Inflación 2024 | B18: ='[19]Variables Globales'!$C$3 -> 1.0351
A21: MARGEN estimado por litro
A22: Ags | B22: Margen comercial ( precio - costo según factura )
A23: P.V. | B23: Enero | C23: Febrero | D23: Marzo | E23: Abril | F23: Mayo | G23: Junio | H23: Julio | I23: Agosto | J23: Septiembre | K23: Octubre | L23: Noviembre | M23: Diciembre
A24: MAXIMA | B24: 0 | C24: 0 | D24: 0 | E24: 0 | F24: 0 | G24: 0 | H24: 0 | I24: 0 | J24: 0 | K24: 0 | L24: 0 | M24: 0
A25: SUPER | B25: 0 | C25: 0 | D25: 0 | E25: 0 | F25: 0 | G25: 0 | H25: 0 | I25: 0 | J25: 0 | K25: 0 | L25: 0 | M25: 0
A26: DIESEL | B26: 0 | C26: 0 | D26: 0 | E26: 0 | F26: 0 | G26: 0 | H26: 0 | I26: 0 | J26: 0 | K26: 0 | L26: 0 | M26: 0
B28: Margen por contrato de volumen con TESORO
A29: P.V. | B29: Enero | C29: Febrero | D29: Marzo | E29: Abril | F29: Mayo | G29: Junio | H29: Julio | I29: Agosto | J29: Septiembre | K29: Octubre | L29: Noviembre | M29: Diciembre | N29: Porcentaje
A30: MAXIMA | B30: 2.08 | N30: 0.2 | P30: =AVERAGE(B30:M30) -> 2.08
A31: SUPER | B31: 3.37 | N31: 0.2 | P31: =AVERAGE(B31:M31) -> 3.37
A32: DIESEL | B32: 1.08 | N32: 0.2 | P32: =AVERAGE(B32:M32) -> 1.08
B34: Margen por contrato de volumen con PREMIER
A35: P.V. | B35: Enero | C35: Febrero | D35: Marzo | E35: Abril | F35: Mayo | G35: Junio | H35: Julio | I35: Agosto | J35: Septiembre | K35: Octubre | L35: Noviembre | M35: Diciembre | N35: Porcentaje
A36: MAXIMA | B36: 2.26 | N36: 0.43 | P36: =AVERAGE(B36:M36) -> 2.26
A37: SUPER | B37: 2.89 | N37: 0.43 | P37: =AVERAGE(B37:M37) -> 2.89
A38: DIESEL | B38: 1.93 | N38: 0.43 | P38: =AVERAGE(B38:M38) -> 1.93
B40: Margen por contrato de volumen MGC
A41: P.V. | B41: Enero | C41: Febrero | D41: Marzo | E41: Abril | F41: Mayo | G41: Junio | H41: Julio | I41: Agosto | J41: Septiembre | K41: Octubre | L41: Noviembre | M41: Diciembre | N41: Porcentaje
A42: MAXIMA | B42: 1.93 | N42: 0.29 | P42: =AVERAGE(B42:M42) -> 1.93
A43: SUPER | B43: 2.75 | N43: 0.29 | P43: =AVERAGE(B43:M43) -> 2.75
A44: DIESEL | B44: 0.62 | N44: 0.29 | P44: =AVERAGE(B44:M44) -> 0.62
B46: Margen por contrato de volumen OTROS
A47: P.V. | B47: Enero | C47: Febrero | D47: Marzo | E47: Abril | F47: Mayo | G47: Junio | H47: Julio | I47: Agosto | J47: Septiembre | K47: Octubre | L47: Noviembre | M47: Diciembre | N47: Porcentaje
A48: MAXIMA | B48: 2.13 | N48: 0.08 | P48: =AVERAGE(B48:M48) -> 2.13
A49: SUPER | B49: 0 | C49: 0 | D49: 0 | E49: 0 | F49: 0 | G49: 0 | H49: 0 | I49: 0 | J49: 0 | K49: 0 | L49: 0 | M49: 0 | N49: 0 | P49: =AVERAGE(B49:M49) -> 0
...

Sheet EDO RESULTADOS MISMAS EST
I1: Mantenimiento de Imagen | J1: 2 | K1: 3 | L1: 4 | M1: 5 | N1: 6 | O1: 7 | Y1: 2 | Z1: 3 | AA1: 4 | AB1: 5 | AC1: 6 | AD1: 7 | AM1: 17 | AQ1: 17
J2: 2024 | V2: TOTAL ANUAL | Y2: 2025 | AK2: PPTO ANUAL MISMAS EST | AO2: PPTO ANUAL TODAS ES
J3: ENE | K3: FEB | L3: MAR | M3: ABR | N3: MAY | O3: JUN | P3: JUL | Q3: AGO | R3: SEP | S3: OCT | T3: NOV | U3: DIC | V3: 2024 | W3: % Part | Y3: ENE | Z3: FEB | AA3: MAR | AB3: ABR | AC3: MAY | AD3: JUN | AE3: JUL | AF3: AGO | AG3: SEP | AH3: OCT | AI3: NOV | AJ3: DIC | AK3: 2025 | AL3: % Part | AM3: Var vs AA% | AO3: 2024 | AP3: % Part | AQ3: Var vs AA%
I4: INGRESOS
A6: A - INGRESOS | E6: ( mas ) | I6: A - INGRESOS | J6: =SUM(J7:J12) -> 17192824 | K6: =SUM(K7:K12) -> 15590830 | L6: =SUM(L7:L12) -> 18254554 | M6: =SUM(M7:M12) -> 17513698 | N6: =SUM(N7:N12) -> 19514034 | O6: =SUM(O7:O12) -> 18936949 | P6: =SUM(P7:P12) -> 18138616 | Q6: =SUM(Q7:Q12) -> 18621506 | ... V6: =SUM(V7:V12) -> 223872939 | W6: =V6/V$6 -> 1 | Y6: =SUM(Y7:Y12) -> 18780611 | Z6: =SUM(Z7:Z12) -> 17035192 | AA6: =SUM(AA7:AA12) -> 20269984 | AB6: =SUM(AB7:AB12) -> 19487182 | AC6: =SUM(AC7:AC12) -> 21864209 | AD6: =SUM(AD7:AD12) -> 21197316 | AE6: =SUM(AE7:AE12) -> 20370243 | AF6: =SUM(AF7:AF12) -> 20697143 | ... AK6: =SUM(AK7:AK12) -> 2.5074065e+08 | AL6: =AK6/AK$6 -> 1 | AM6: =IFERROR(AK6/V6-1,0) -> 0.12001323 | AO6: 4.4076062e+09 | AP6: 1 | AQ6: 0.16822054
A7: A - INGRESOS | B7: estaciones | C7: INGRESOS MAGNA | D7: INGRESOS FORANEOS MAGNA | I7: MAXIMA | J7: =SUM(A:B!J7) -> 13803132 | K7: =SUM(A:B!K7) -> 12317959 | L7: =SUM(A:B!L7) -> 14526332 | M7: =SUM(A:B!M7) -> 13887455 | N7: =SUM(A:B!N7) -> 15477447 | O7: =SUM(A:B!O7) -> 15236060 | P7: =SUM(A:B!P7) -> 14546459 | Q7: =SUM(A:B!Q7) -> 14677535 | ... U7: =SUM(A:B!U7) -> 15732735 | V7: =SUM(J7:U7) -> 1.7740332e+08 | W7: =V7/V$6 -> 0.79242861 | Y7: =SUM(A:B!Y7) -> 15202952 | Z7: =SUM(A:B!Z7) -> 13599664 | AA7: =SUM(A:B!AA7) -> 16337794 | AB7: =SUM(A:B!AB7) -> 15675014 | AC7: =SUM(A:B!AC7) -> 17580791 | AD7: =SUM(A:B!AD7) -> 17284829 | AE7: =SUM(A:B!AE7) -> 16564120 | AF7: =SUM(A:B!AF7) -> 16552821 | ... AJ7: =SUM(A:B!AJ7) -> 18147057 | AK7: =SUM(Y7:AJ7) -> 2.01564e+08 | AL7: =AK7/AK$6 -> 0.80387444 | AM7: =IFERROR(AK7/V7-1,0) -> 0.13619069 | AO7: 3.4888525e+09 | AP7: 0.79155268 | AQ7: 0.14554128
A8: A - INGRESOS | B8: estaciones | C8: INGRESOS PREMIUM | D8: INGRESOS FORANEOS PREMIUM | I8: SUPER | J8: =SUM(A:B!J8) -> 3260550 | K8: =SUM(A:B!K8) -> 3155615 | L8: =SUM(A:B!L8) -> 3577713 | M8: =SUM(A:B!M8) -> 3447065 | N8: =SUM(A:B!N8) -> 3825441 | O8: =SUM(A:B!O8) -> 3528128 | P8: =SUM(A:B!P8) -> 3411360 | Q8: =SUM(A:B!Q8) -> 3791076 | ... U8: =SUM(A:B!U8) -> 4133088.9 | V8: =SUM(J8:U8) -> 44529304 | W8: =V8/V$6 -> 0.19890436 | Y8: =SUM(A:B!Y8) -> 3435117.4 | Z8: =SUM(A:B!Z8) -> 3306549.5 | AA8: =SUM(A:B!AA8) -> 3769065.3 | AB8: =SUM(A:B!AB8) -> 3620940.7 | AC8: =SUM(A:B!AC8) -> 4053744.8 | AD8: =SUM(A:B!AD8) -> 3728103.4 | AE8: =SUM(A:B!AE8) -> 3609622 | AF8: =SUM(A:B!AF8) -> 3976339.4 | ... AJ8: =SUM(A:B!AJ8) -> 4355630.6 | AK8: =SUM(Y8:AJ8) -> 47141259 | AL8: =AK8/AK$6 -> 0.18800804 | AM8: =IFERROR(AK8/V8-1,0) -> 0.05865701 | AO8: 3.5285587e+08 | AP8: 0.080056124 | AQ8: 0.26460768
A9: A - INGRESOS | B9: estaciones | C9: INGRESOS DIESEL | D9: INGRESOS FORANEOS DIESEL | I9: DIESEL | J9: =SUM(A:B!J9) -> 119320 | K9: =SUM(A:B!K9) -> 108214 | L9: =SUM(A:B!L9) -> 130827 | M9: =SUM(A:B!M9) -> 157657 | N9: =SUM(A:B!N9) -> 189122 | O9: =SUM(A:B!O9) -> 151966 | P9: =SUM(A:B!P9) -> 162434 | Q9: =SUM(A:B!Q9) -> 130655 | ... U9: =SUM(A:B!U9) -> 139359.89 | V9: =SUM(J9:U9) -> 1707634.6 | W9: =V9/V$6 -> 0.0076276953 | Y9: =SUM(A:B!Y9) -> 133961.55 | Z9: =SUM(A:B!Z9) -> 121418.7 | AA9: =SUM(A:B!AA9) -> 147824.7 | AB9: =SUM(A:B!AB9) -> 176406.75 | AC9: =SUM(A:B!AC9) -> 212152.65 | AD9: =SUM(A:B!AD9) -> 169683 | AE9: =SUM(A:B!AE9) -> 180661.05 | AF9: =SUM(A:B!AF9) -> 151003.2 | ... AJ9: =SUM(A:B!AJ9) -> 132005.55 | AK9: =SUM(Y9:AJ9) -> 1842552 | AL9: =AK9/AK$6 -> 0.0073484374 | AM9: =IFERROR(AK9/V9-1,0) -> 0.079008383 | AO9: 5.6589782e+08 | AP9: 0.12839119 | AQ9: 0.3070746
I10: INGRESOS ACEITES Y LUBRICANTES | J10: =SUM(A:B!J10) -> 9822 | K10: =SUM(A:B!K10) -> 9042 | L10: =SUM(A:B!L10) -> 19682 | M10: =SUM(A:B!M10) -> 21521 | N10: =SUM(A:B!N10) -> 22024 | O10: =SUM(A:B!O10) -> 20795 | P10: =SUM(A:B!P10) -> 18363 | Q10: =SUM(A:B!Q10) -> 22240 | ... U10: =SUM(A:B!U10) -> 22297.778 | V10: =SUM(J10:U10) -> 232680.11 | W10: =V10/V$6 -> 0.00103934 | Y10: =SUM(A:B!Y10) -> 8580 | Z10: =SUM(A:B!Z10) -> 7560 | AA10: =SUM(A:B!AA10) -> 15300 | AB10: =SUM(A:B!AB10) -> 14820 | AC10: =SUM(A:B!AC10) -> 17520 | AD10: =SUM(A:B!AD10) -> 14700 | AE10: =SUM(A:B!AE10) -> 15840 | AF10: =SUM(A:B!AF10) -> 16980 | ... AJ10: =SUM(A:B!AJ10) -> 27480 | AK10: =SUM(Y10:AJ10) -> 192840 | AL10: =AK10/AK$6 -> 0.00076908151 | AM10: =IFERROR(AK10/V10-1,0) -> -0.17122268 | AO10: 0 | AP10: 0 | AQ10: -1
I11: SOBRANTE COMBUSTIBLE | J11: =SUM(A:B!J11) -> 0 | K11: =SUM(A:B!K11) -> 0 | L11: =SUM(A:B!L11) -> 0 | M11: =SUM(A:B!M11) -> 0 | N11: =SUM(A:B!N11) -> 0 | O11: =SUM(A:B!O11) -> 0 | P11: =SUM(A:B!P11) -> 0 | Q11: =SUM(A:B!Q11) -> 0 | ... U11: =SUM(A:B!U11) -> 0 | V11: =SUM(J11:U11) -> 0 | W11: =V11/V$6 -> 0 | Y11: =SUM(A:B!Y11) -> 0 | Z11: =SUM(A:B!Z11) -> 0 | AA11: =SUM(A:B!AA11) -> 0 | AB11: =SUM(A:B!AB11) -> 0 | AC11: =SUM(A:B!AC11) -> 0 | AD11: =SUM(A:B!AD11) -> 0 | AE11: =SUM(A:B!AE11) -> 0 | AF11: =SUM(A:B!AF11) -> 0 | ... AJ11: =SUM(A:B!AJ11) -> 0 | AK11: =SUM(Y11:AJ11) -> 0 | AL11: =AK11/AK$6 -> 0 | AM11: =IFERROR(AK11/V11-1,0) -> 0 | AO11: 0 | AP11: 0 | AQ11: -1
J12: =SUM(A:B!J12) -> 0 | K12: =SUM(A:B!K12) -> 0 | L12: =SUM(A:B!L12) -> 0 | M12: =SUM(A:B!M12) -> 0 | N12: =SUM(A:B!N12) -> 0 | O12: =SUM(A:B!O12) -> 0 | P12: =SUM(A:B!P12) -> 0 | Q12: =SUM(A:B!Q12) -> 0 | ... U12: =SUM(A:B!U12) -> 0 | V12: =SUM(J12:U12) -> 0 | W12: =V12/V$6 -> 0 | Y12: =SUM(A:B!Y12) -> 0 | Z12: =SUM(A:B!Z12) -> 0 | AA12: =SUM(A:B!AA12) -> 0 | AB12: =SUM(A:B!AB12) -> 0 | AC12: =SUM(A:B!AC12) -> 0 | AD12: =SUM(A:B!AD12) -> 0 | AE12: =SUM(A:B!AE12) -> 0 | AF12: =SUM(A:B!AF12) -> 0 | ... AJ12: =SUM(A:B!AJ12) -> 0 | AK12: =SUM(Y12:AJ12) -> 0 | AL12: =AK12/AK$6 -> 0 | AM12: =IFERROR(AK12/V12-1,0) -> 0 | AO12: 0 | AP12: 0 | AQ12: 0
A13: B - COSTO DE VENTA | E13: ( menos ) | I13: B - COSTO DE VENTA | J13: =SUM(J14:J30) -> 16106343 | K13: =SUM(K14:K30) -> 14418436 | L13: =SUM(L14:L30) -> 16740719 | M13: =SUM(M14:M30) -> 15910764 | N13: =SUM(N14:N30) -> 17765346 | O13: =SUM(O14:O30) -> 17171141 | P13: =SUM(P14:P30) -> 16730167 | Q13: =SUM(Q14:Q30) -> 17141232 | ... V13: =SUM(V14:V30) -> 2.0557055e+08 | W13: =V13/V$6 -> 0.91824653 | Y13: =SUM(Y14:Y30) -> 17094951 | Z13: =SUM(Z14:Z30) -> 15592766 | AA13: =SUM(AA14:AA30) -> 18304073 | AB13: =SUM(AB14:AB30) -> 17779061 | AC13: =SUM(AC14:AC30) -> 19790063 | AD13: =SUM(AD14:AD30) -> 19328858 | AE13: =SUM(AE14:AE30) -> 18583117 | AF13: =SUM(AF14:AF30) -> 18827660 | ... AJ13: =SUM(AJ14:AJ30) -> 20641001 | AK13: =SUM(Y13:AJ13) -> 2.2807815e+08 | AL13: =AK13/AK$6 -> 0.90961774 | AM13: =IFERROR(AK13/V13-1,0) -> 0.10948843 | AO13: 3.7568617e+09 | AP13: 0.85235875 | AQ13: 0.16747315
A14: B - COSTO DE VENTA | C14: COSTO MAGNA | D14: COSTO FORANEO MAGNA | I14: GASOLINA REGULAR | J14: =SUM(A:B!J14) -> 12973548 | K14: =SUM(A:B!K14) -> 11404250 | L14: =SUM(A:B!L14) -> 13331662 | M14: =SUM(A:B!M14) -> 12710487 | N14: =SUM(A:B!N14) -> 14240584 | O14: =SUM(A:B!O14) -> 14028976 | P14: =SUM(A:B!P14) -> 13394436 | Q14: =SUM(A:B!Q14) -> 13534987 | ... U14: =SUM(A:B!U14) -> 14490738 | V14: =SUM(J14:U14) -> 1.6358188e+08 | W14: =V14/V$6 -> 0.73069074 | Y14: =SUM(A:B!Y14) -> 13883313 | Z14: =SUM(A:B!Z14) -> 12500474 | AA14: =SUM(A:B!AA14) -> 14787073 | AB14: =SUM(A:B!AB14) -> 14347590 | AC14: =SUM(A:B!AC14) -> 15960345 | AD14: =SUM(A:B!AD14) -> 15798489 | AE14: =SUM(A:B!AE14) -> 15161171 | AF14: =SUM(A:B!AF14) -> 15119204 | ... AK14: =SUM(A:B!AK14) -> 1.8394188e+08 | AL14: =AK14/AK$6 -> 0.73359417 | AM14: =IFERROR(AK14/V14-1,0) -> 0.12446366 | AO14: 3.5232571e+09 | AP14: 0.7993584 | AQ14: 0.13050349
A15: B - COSTO DE VENTA | C15: COSTO PREMIUM | D15: COSTO FORANEO PREMIUM | I15: GASOLINA PREMIUM | J15: =SUM(A:B!J15) -> 2994699 | K15: =SUM(A:B!K15) -> 2908739 | L15: =SUM(A:B!L15) -> 3286842 | M15: =SUM(A:B!M15) -> 3157931 | N15: =SUM(A:B!N15) -> 3455437 | O15: =SUM(A:B!O15) -> 3184771 | P15: =SUM(A:B!P15) -> 3126152 | Q15: =SUM(A:B!Q15) -> 3519227 | ... U15: =SUM(A:B!U15) -> 3831077.2 | V15: =SUM(J15:U15) -> 40958107 | W15: =V15/V$6 -> 0.18295247 | Y15: =SUM(A:B!Y15) -> 3080784 | Z15: =SUM(A:B!Z15) -> 2973366.4 | AA15: =SUM(A:B!AA15) -> 3369026.9 | AB15: =SUM(A:B!AB15) -> 3257493.6 | AC15: =SUM(A:B!AC15) -> 3620816.1 | AD15: =SUM(A:B!AD15) -> 3359822.1 | AE15: =SUM(A:B!AE15) -> 3242504 | AF15: =SUM(A:B!AF15) -> 3553874.7 | ... AK15: =SUM(A:B!AK15) -> 42276501 | AL15: =AK15/AK$6 -> 0.16860649 | AM15: =IFERROR(AK15/V15-1,0) -> 0.032188835 | AO15: 3.4716629e+08 | AP15: 0.078765269 | AQ15: 0.24745089
A16: B - COSTO DE VENTA | C16: COSTO DIESEL | D16: COSTO FORANEO DIESEL | I16: DIESEL | J16: =SUM(A:B!J16) -> 111034 | K16: =SUM(A:B!K16) -> 101129 | L16: =SUM(A:B!L16) -> 122898 | M16: =SUM(A:B!M16) -> 146759 | N16: =SUM(A:B!N16) -> 171893 | O16: =SUM(A:B!O16) -> 138211 | P16: =SUM(A:B!P16) -> 152522 | Q16: =SUM(A:B!Q16) -> 127651 | ... U16: =SUM(A:B!U16) -> 130644.33 | V16: =SUM(J16:U16) -> 1594674.3 | W16: =V16/V$6 -> 0.0071231223 | Y16: =SUM(A:B!Y16) -> 123989.77 | Z16: =SUM(A:B!Z16) -> 112877.18 | AA16: =SUM(A:B!AA16) -> 135732.7 | AB16: =SUM(A:B!AB16) -> 162121.05 | AC16: =SUM(A:B!AC16) -> 194885.42 | AD16: =SUM(A:B!AD16) -> 158787.2 | AE16: =SUM(A:B!AE16) -> 166769.73 | AF16: =SUM(A:B!AF16) -> 140998.08 | ... AK16: =SUM(A:B!AK16) -> 1705493.2 | AL16: =AK16/AK$6 -> 0.0068018216 | AM16: =IFERROR(AK16/V16-1,0) -> 0.069493096 | AO16: 5.0123784e+08 | AP16: 0.1137211 | AQ16: 0.29638109
A17: B - COSTO DE VENTA | C17: Merma Magna | I17: MERMA GASOLINA REGULAR | J17: =SUM(A:B!J17) -> 0 | K17: =SUM(A:B!K17) -> 451 | L17: =SUM(A:B!L17) -> 0 | M17: =SUM(A:B!M17) -> 863 | N17: =SUM(A:B!N17) -> 0 | O17: =SUM(A:B!O17) -> 0 | P17: =SUM(A:B!P17) -> 1786 | Q17: =SUM(A:B!Q17) -> 0 | ... U17: =SUM(A:B!U17) -> 136.88889 | V17: =SUM(J17:U17) -> 3647.5556 | W17: =V17/V$6 -> 1.6292972e-05 | Y17: =SUM(A:B!Y17) -> 0 | Z17: =SUM(A:B!Z17) -> 0 | AA17: =SUM(A:B!AA17) -> 0 | AB17: =SUM(A:B!AB17) -> 0 | AC17: =SUM(A:B!AC17) -> 0 | AD17: =SUM(A:B!AD17) -> 0 | AE17: =SUM(A:B!AE17) -> 0 | AF17: =SUM(A:B!AF17) -> 0 | ... AK17: =SUM(A:B!AK17) -> 0 | AL17: =AK17/AK$6 -> 0 | AM17: =IFERROR(AK17/V17-1,0) -> -1 | AO17: 0 | AP17: 0 | AQ17: -1
A18: B - COSTO DE VENTA | C18: Merma Premium | I18: MERMA GASOLINA PREMIUM | J18: =SUM(A:B!J18) -> 10118 | K18: =SUM(A:B!K18) -> 11513 | L18: =SUM(A:B!L18) -> 5892 | M18: =SUM(A:B!M18) -> 235 | N18: =SUM(A:B!N18) -> 5571 | O18: =SUM(A:B!O18) -> 4098 | P18: =SUM(A:B!P18) -> 6579 | Q18: =SUM(A:B!Q18) -> 0 | ... U18: =SUM(A:B!U18) -> 6448.4444 | V18: =SUM(J18:U18) -> 69799.778 | W18: =V18/V$6 -> 0.00031178301 | Y18: =SUM(A:B!Y18) -> 0 | Z18: =SUM(A:B!Z18) -> 0 | AA18: =SUM(A:B!AA18) -> 0 | AB18: =SUM(A:B!AB18) -> 0 | AC18: =SUM(A:B!AC18) -> 0 | AD18: =SUM(A:B!AD18) -> 0 | AE18: =SUM(A:B!AE18) -> 0 | AF18: =SUM(A:B!AF18) -> 0 | ... AK18: =SUM(A:B!AK18) -> 0 | AL18: =AK18/AK$6 -> 0 | AM18: =IFERROR(AK18/V18-1,0) -> -1 | AO18: 0 | AP18: 0 | AQ18: -1
A19: B - COSTO DE VENTA | C19: Merma Diesel | I19: MERMA DIESEL | J19: =SUM(A:B!J19) -> -2264 | K19: =SUM(A:B!K19) -> 0 | L19: =SUM(A:B!L19) -> 203 | M19: =SUM(A:B!M19) -> 0 | N19: =SUM(A:B!N19) -> 0 | O19: =SUM(A:B!O19) -> 1796 | P19: =SUM(A:B!P19) -> 0 | Q19: =SUM(A:B!Q19) -> 0 | ... U19: =SUM(A:B!U19) -> 2120.8889 | V19: =SUM(J19:U19) -> 8218.5556 | W19: =V19/V$6 -> 3.6710804e-05 | Y19: =SUM(A:B!Y19) -> 0 | Z19: =SUM(A:B!Z19) -> 0 | AA19: =SUM(A:B!AA19) -> 0 | AB19: =SUM(A:B!AB19) -> 0 | AC19: =SUM(A:B!AC19) -> 0 | AD19: =SUM(A:B!AD19) -> 0 | AE19: =SUM(A:B!AE19) -> 0 | AF19: =SUM(A:B!AF19) -> 0 | ... AK19: =SUM(A:B!AK19) -> 0 | AL19: =AK19/AK$6 -> 0 | AM19: =IFERROR(AK19/V19-1,0) -> -1 | AO19: 0 | AP19: 0 | AQ19: -1
A20: B - COSTO DE VENTA | C20: ADITIVO PARA GASOLINA TMAXIMA (REGULAR) | D20: ADITIVO PARA GASOLINA TMAXIMA( REGULAR) | I20: SOBRANTE MAGNA | J20: =SUM(A:B!J20) -> -1655 | K20: =SUM(A:B!K20) -> -16260 | L20: =SUM(A:B!L20) -> -47534 | M20: =SUM(A:B!M20) -> -80019 | N20: =SUM(A:B!N20) -> -101412 | O20: =SUM(A:B!O20) -> -102362 | P20: =SUM(A:B!P20) -> -41438 | Q20: =SUM(A:B!Q20) -> -73785 | ... U20: =SUM(A:B!U20) -> -75022.778 | V20: =SUM(J20:U20) -> -764556.11 | W20: =V20/V$6 -> -0.0034151341 | Y20: =SUM(A:B!Y20) -> 0 | Z20: =SUM(A:B!Z20) -> 0 | AA20: =SUM(A:B!AA20) -> 0 | AB20: =SUM(A:B!AB20) -> 0 | AC20: =SUM(A:B!AC20) -> 0 | AD20: =SUM(A:B!AD20) -> 0 | AE20: =SUM(A:B!AE20) -> 0 | AF20: =SUM(A:B!AF20) -> 0 | ... AK20: =SUM(A:B!AK20) -> 0 | AL20: =AK20/AK$6 -> 0 | AM20: =IFERROR(AK20/V20-1,0) -> -1 | AO20: 0 | AP20: 0 | AQ20: -1
A21: B - COSTO DE VENTA | C21: ADITIVO PARA GASOLINA TSUPER (PREMIUM) | I21: SOBRANTE PREMIUM | J21: =SUM(A:B!J21) -> 15107 | K21: =SUM(A:B!K21) -> 4291 | L21: =SUM(A:B!L21) -> -4238 | M21: =SUM(A:B!M21) -> -6859 | N21: =SUM(A:B!N21) -> -21701 | O21: =SUM(A:B!O21) -> -91077 | P21: =SUM(A:B!P21) -> 77691 | Q21: =SUM(A:B!Q21) -> -5176 | ... U21: =SUM(A:B!U21) -> -13801.778 | V21: =SUM(J21:U21) -> -87169.111 | W21: =V21/V$6 -> -0.00038936868 | Y21: =SUM(A:B!Y21) -> 0 | Z21: =SUM(A:B!Z21) -> 0 | AA21: =SUM(A:B!AA21) -> 0 | AB21: =SUM(A:B!AB21) -> 0 | AC21: =SUM(A:B!AC21) -> 0 | AD21: =SUM(A:B!AD21) -> 0 | AE21: =SUM(A:B!AE21) -> 0 | AF21: =SUM(A:B!AF21) -> 0 | ... AK21: =SUM(A:B!AK21) -> 0 | AL21: =AK21/AK$6 -> 0 | AM21: =IFERROR(AK21/V21-1,0) -> -1 | AO21: 0 | AP21: 0 | AQ21: -1
A22: B - COSTO DE VENTA | C22: FLETE MAGNA | I22: SOBRANTE DIESEL | J22: =SUM(A:B!J22) -> 0 | K22: =SUM(A:B!K22) -> -1925 | L22: =SUM(A:B!L22) -> -2961 | M22: =SUM(A:B!M22) -> -232 | N22: =SUM(A:B!N22) -> -4780 | O22: =SUM(A:B!O22) -> 0 | P22: =SUM(A:B!P22) -> -2453 | Q22: =SUM(A:B!Q22) -> -1311 | ... U22: =SUM(A:B!U22) -> -2245.2222 | V22: =SUM(J22:U22) -> -22642.889 | W22: =V22/V$6 -> -0.0001011417 | Y22: =SUM(A:B!Y22) -> 0 | Z22: =SUM(A:B!Z22) -> 0 | AA22: =SUM(A:B!AA22) -> 0 | AB22: =SUM(A:B!AB22) -> 0 | AC22: =SUM(A:B!AC22) -> 0 | AD22: =SUM(A:B!AD22) -> 0 | AE22: =SUM(A:B!AE22) -> 0 | AF22: =SUM(A:B!AF22) -> 0 | ... AK22: =SUM(A:B!AK22) -> 0 | AL22: =AK22/AK$6 -> 0 | AM22: =IFERROR(AK22/V22-1,0) -> -1 | AO22: 0 | AP22: 0 | AQ22: -1
A23: B - COSTO DE VENTA | C23: FLETE PREMIUM | I23: ADITIVO TOTAL POWER GASOLINA REG | J23: =SUM(A:B!J23) -> 0 | K23: =SUM(A:B!K23) -> 0 | L23: =SUM(A:B!L23) -> 26670 | M23: =SUM(A:B!M23) -> -26670 | N23: =SUM(A:B!N23) -> 0 | O23: =SUM(A:B!O23) -> 0 | P23: =SUM(A:B!P23) -> 0 | Q23: =SUM(A:B!Q23) -> 0 | ... U23: =SUM(A:B!U23) -> 0 | V23: =SUM(J23:U23) -> 0 | W23: =V23/V$6 -> 0 | Y23: =SUM(A:B!Y23) -> 0 | Z23: =SUM(A:B!Z23) -> 0 | AA23: =SUM(A:B!AA23) -> 0 | AB23: =SUM(A:B!AB23) -> 0 | AC23: =SUM(A:B!AC23) -> 0 | AD23: =SUM(A:B!AD23) -> 0 | AE23: =SUM(A:B!AE23) -> 0 | AF23: =SUM(A:B!AF23) -> 0 | ... AK23: =SUM(A:B!AK23) -> 0 | AL23: =AK23/AK$6 -> 0 | AM23: =IFERROR(AK23/V23-1,0) -> 0 | AO23: 0 | AP23: 0 | AQ23: -1
A24: B - COSTO DE VENTA | C24: FLETE DIESEL | I24: ADITIVO TOTAL POWER GASOLINA PREM | J24: =SUM(A:B!J24) -> 0 | K24: =SUM(A:B!K24) -> 0 | L24: =SUM(A:B!L24) -> 6840 | M24: =SUM(A:B!M24) -> -6840 | N24: =SUM(A:B!N24) -> 0 | O24: =SUM(A:B!O24) -> 0 | P24: =SUM(A:B!P24) -> 0 | Q24: =SUM(A:B!Q24) -> 0 | ... U24: =SUM(A:B!U24) -> 0 | V24: =SUM(J24:U24) -> 0 | W24: =V24/V$6 -> 0 | Y24: =SUM(A:B!Y24) -> 0 | Z24: =SUM(A:B!Z24) -> 0 | AA24: =SUM(A:B!AA24) -> 0 | AB24: =SUM(A:B!AB24) -> 0 | AC24: =SUM(A:B!AC24) -> 0 | AD24: =SUM(A:B!AD24) -> 0 | AE24: =SUM(A:B!AE24) -> 0 | AF24: =SUM(A:B!AF24) -> 0 | ... AK24: =SUM(A:B!AK24) -> 0 | AL24: =AK24/AK$6 -> 0 | AM24: =IFERROR(AK24/V24-1,0) -> 0 | AO24: 0 | AP24: 0 | AQ24: -1
A25: B - COSTO DE VENTA | C25: Estimulo IEPS Magna | D25: INGRESOS FORANEOS MAGNA | I25: FLETE GASOLINA REGULAR | J25: =SUM(A:B!J25) -> 0 | K25: =SUM(A:B!K25) -> 0 | L25: =SUM(A:B!L25) -> 0 | M25: =SUM(A:B!M25) -> 1204 | N25: =SUM(A:B!N25) -> 2511 | O25: =SUM(A:B!O25) -> 0 | P25: =SUM(A:B!P25) -> 2415 | Q25: =SUM(A:B!Q25) -> 0 | ... U25: =SUM(A:B!U25) -> 4740.8889 | V25: =SUM(J25:U25) -> 25093.556 | W25: =V25/V$6 -> 0.00011208838 | Y25: =SUM(A:B!Y25) -> 0 | Z25: =SUM(A:B!Z25) -> 0 | AA25: =SUM(A:B!AA25) -> 0 | AB25: =SUM(A:B!AB25) -> 0 | AC25: =SUM(A:B!AC25) -> 0 | AD25: =SUM(A:B!AD25) -> 0 | AE25: =SUM(A:B!AE25) -> 0 | AF25: =SUM(A:B!AF25) -> 0 | ... AK25: =SUM(A:B!AK25) -> 0 | AL25: =AK25/AK$6 -> 0 | AM25: =IFERROR(AK25/V25-1,0) -> -1 | AO25: -5.7784199e+08 | AP25: -0.13110109 | AQ25: 0.066558616
I26: FLETE GASOLINA PREMIUM | J26: =SUM(A:B!J26) -> 0 | K26: =SUM(A:B!K26) -> 0 | L26: =SUM(A:B!L26) -> 0 | M26: =SUM(A:B!M26) -> 0 | N26: =SUM(A:B!N26) -> 1209 | O26: =SUM(A:B!O26) -> 0 | P26: =SUM(A:B!P26) -> 0 | Q26: =SUM(A:B!Q26) -> 0 | ... U26: =SUM(A:B!U26) -> 2136 | V26: =SUM(J26:U26) -> 9753 | W26: =V26/V$6 -> 4.356489e-05 | Y26: =SUM(A:B!Y26) -> 0 | Z26: =SUM(A:B!Z26) -> 0 | AA26: =SUM(A:B!AA26) -> 0 | AB26: =SUM(A:B!AB26) -> 0 | AC26: =SUM(A:B!AC26) -> 0 | AD26: =SUM(A:B!AD26) -> 0 | AE26: =SUM(A:B!AE26) -> 0 | AF26: =SUM(A:B!AF26) -> 0 | ... AK26: =SUM(A:B!AK26) -> 0 | AL26: =AK26/AK$6 -> 0 | AM26: =IFERROR(AK26/V26-1,0) -> -1 | AO26: -36957483 | AP26: -0.0083849329 | AQ26: 0.064257395
I27: FLETE DIESEL | J27: =SUM(A:B!J27) -> 0 | K27: =SUM(A:B!K27) -> 0 | L27: =SUM(A:B!L27) -> 0 | M27: =SUM(A:B!M27) -> 0 | N27: =SUM(A:B!N27) -> 0 | O27: =SUM(A:B!O27) -> 0 | P27: =SUM(A:B!P27) -> 0 | Q27: =SUM(A:B!Q27) -> 0 | ... U27: =SUM(A:B!U27) -> 0 | V27: =SUM(J27:U27) -> 0 | W27: =V27/V$6 -> 0 | Y27: =SUM(A:B!Y27) -> 0 | Z27: =SUM(A:B!Z27) -> 0 | AA27: =SUM(A:B!AA27) -> 0 | AB27: =SUM(A:B!AB27) -> 0 | AC27: =SUM(A:B!AC27) -> 0 | AD27: =SUM(A:B!AD27) -> 0 | AE27: =SUM(A:B!AE27) -> 0 | AF27: =SUM(A:B!AF27) -> 0 | ... AK27: =SUM(A:B!AK27) -> 0 | AL27: =AK27/AK$6 -> 0 | AM27: =IFERROR(AK27/V27-1,0) -> 0 | AO27: 0 | AP27: 0 | AQ27: -1
I28: ESTIMULO REGULAR | J28: =SUM(A:B!J28) -> 0 | K28: =SUM(A:B!K28) -> 0 | L28: =SUM(A:B!L28) -> 0 | M28: =SUM(A:B!M28) -> 0 | N28: =SUM(A:B!N28) -> 0 | O28: =SUM(A:B!O28) -> 0 | P28: =SUM(A:B!P28) -> 0 | Q28: =SUM(A:B!Q28) -> 0 | ... U28: =SUM(A:B!U28) -> 0 | V28: =SUM(J28:U28) -> 0 | W28: =V28/V$6 -> 0 | Y28: =SUM(A:B!Y28) -> 0 | Z28: =SUM(A:B!Z28) -> 0 | AA28: =SUM(A:B!AA28) -> 0 | AB28: =SUM(A:B!AB28) -> 0 | AC28: =SUM(A:B!AC28) -> 0 | AD28: =SUM(A:B!AD28) -> 0 | AE28: =SUM(A:B!AE28) -> 0 | AF28: =SUM(A:B!AF28) -> 0 | ... AK28: =SUM(A:B!AK28) -> 0 | AL28: =AK28/AK$6 -> 0 | AM28: =IFERROR(AK28/V28-1,0) -> 0 | AO28: 6.507445e+08 | AP28: 0.14764125 | AQ28: 0.17255416
I29: ESTIMULO PREMIUM | J29: =SUM(A:B!J29) -> 0 | K29: =SUM(A:B!K29) -> 0 | L29: =SUM(A:B!L29) -> 0 | M29: =SUM(A:B!M29) -> 0 | N29: =SUM(A:B!N29) -> 0 | O29: =SUM(A:B!O29) -> 0 | P29: =SUM(A:B!P29) -> 0 | Q29: =SUM(A:B!Q29) -> 0 | ... U29: =SUM(A:B!U29) -> 0 | V29: =SUM(J29:U29) -> 0 | W29: =V29/V$6 -> 0 | Y29: =SUM(A:B!Y29) -> 0 | Z29: =SUM(A:B!Z29) -> 0 | AA29: =SUM(A:B!AA29) -> 0 | AB29: =SUM(A:B!AB29) -> 0 | AC29: =SUM(A:B!AC29) -> 0 | AD29: =SUM(A:B!AD29) -> 0 | AE29: =SUM(A:B!AE29) -> 0 | AF29: =SUM(A:B!AF29) -> 0 | ... AK29: =SUM(A:B!AK29) -> 0 | AL29: =AK29/AK$6 -> 0 | AM29: =IFERROR(AK29/V29-1,0) -> 0 | AO29: 5.4343746e+08 | AP29: #REF! | AQ29: 0.13532128
I30: COSTO ACEITES Y LUBRICANTES | J30: =SUM(A:B!J30) -> 5756 | K30: =SUM(A:B!K30) -> 6248 | L30: =SUM(A:B!L30) -> 14445 | M30: =SUM(A:B!M30) -> 13905 | N30: =SUM(A:B!N30) -> 16034 | O30: =SUM(A:B!O30) -> 6728 | P30: =SUM(A:B!P30) -> 12477 | Q30: =SUM(A:B!Q30) -> 39639 | ... U30: =SUM(A:B!U30) -> 19627.444 | V30: =SUM(J30:U30) -> 193741.78 | W30: =V30/V$6 -> 0.00086540954 | Y30: =SUM(A:B!Y30) -> 6864 | Z30: =SUM(A:B!Z30) -> 6048 | AA30: =SUM(A:B!AA30) -> 12240 | AB30: =SUM(A:B!AB30) -> 11856 | AC30: =SUM(A:B!AC30) -> 14016 | AD30: =SUM(A:B!AD30) -> 11760 | AE30: =SUM(A:B!AE30) -> 12672 | AF30: =SUM(A:B!AF30) -> 13584 | ... AK30: =SUM(A:B!AK30) -> 154272 | AL30: =AK30/AK$6 -> 0.00061526521 | AM30: =IFERROR(AK30/V30-1,0) -> -0.20372363 | AO30: 42647062 | AP30: #REF! | AQ30: 0.48513341
I31: BONIFICACION COMPRA DE COMBUSTIBLE MAGNA | J31: =SUM(A:B!J31) -> -169846 | K31: =SUM(A:B!K31) -> -167978 | L31: =SUM(A:B!L31) -> -186098 | M31: =SUM(A:B!M31) -> -197938 | N31: =SUM(A:B!N31) -> -216128 | O31: =SUM(A:B!O31) -> -198097 | P31: =SUM(A:B!P31) -> -210124 | Q31: =SUM(A:B!Q31) -> -206915 | ... U31: =SUM(A:B!U31) -> -219100.33 | V31: =SUM(J31:U31) -> -2429525.3 | W31: =V31/V$6 -> -0.010852251 | Y31: =SUM(A:B!Y31) -> 0 | Z31: =SUM(A:B!Z31) -> 0 | AA31: =SUM(A:B!AA31) -> 0 | AB31: =SUM(A:B!AB31) -> 0 | AC31: =SUM(A:B!AC31) -> 0 | AD31: =SUM(A:B!AD31) -> 0 | AE31: =SUM(A:B!AE31) -> 0 | AF31: =SUM(A:B!AF31) -> 0 | ... AK31: =SUM(A:B!AK31) -> 0 | AL31: =AK31/AK$6 -> 0 | AM31: =IFERROR(AK31/V31-1,0) -> -1 | AO31: 64659974 | AP31: #REF! | AQ31: 0.41061113
I32: BONIFICACION COMPRA DE COMBUSTIBLE PREMIUM | J32: =SUM(A:B!J32) -> -30257 | K32: =SUM(A:B!K32) -> -31282 | L32: =SUM(A:B!L32) -> -37037 | M32: =SUM(A:B!M32) -> -29914 | N32: =SUM(A:B!N32) -> -42589 | O32: =SUM(A:B!O32) -> -30035 | P32: =SUM(A:B!P32) -> -37039 | Q32: =SUM(A:B!Q32) -> -37056 | ... U32: =SUM(A:B!U32) -> -42628.444 | V32: =SUM(J32:U32) -> -445722.78 | W32: =V32/V$6 -> -0.0019909632 | Y32: =SUM(A:B!Y32) -> 0 | Z32: =SUM(A:B!Z32) -> 0 | AA32: =SUM(A:B!AA32) -> 0 | AB32: =SUM(A:B!AB32) -> 0 | AC32: =SUM(A:B!AC32) -> 0 | AD32: =SUM(A:B!AD32) -> 0 | AE32: =SUM(A:B!AE32) -> 0 | AF32: =SUM(A:B!AF32) -> 0 | ... AK32: =SUM(A:B!AK32) -> 0 | AL32: =AK32/AK$6 -> 0 | AM32: =IFERROR(AK32/V32-1,0) -> -1 | AO32: 0 | AP32: #REF! | AQ32: -1
I33: BONIFICACION COMPRA DE COMBUSTIBLE DIESEL | J33: =SUM(A:B!J33) -> -3485 | K33: =SUM(A:B!K33) -> 0 | L33: =SUM(A:B!L33) -> -2310 | M33: =SUM(A:B!M33) -> 0 | N33: =SUM(A:B!N33) -> -2310 | O33: =SUM(A:B!O33) -> -4642 | P33: =SUM(A:B!P33) -> 0 | Q33: =SUM(A:B!Q33) -> 0 | ... U33: =SUM(A:B!U33) -> -2056 | V33: =SUM(J33:U33) -> -20971 | W33: =V33/V$6 -> -9.3673671e-05 | Y33: =SUM(A:B!Y33) -> 0 | Z33: =SUM(A:B!Z33) -> 0 | AA33: =SUM(A:B!AA33) -> 0 | AB33: =SUM(A:B!AB33) -> 0 | AC33: =SUM(A:B!AC33) -> 0 | AD33: =SUM(A:B!AD33) -> 0 | AE33: =SUM(A:B!AE33) -> 0 | AF33: =SUM(A:B!AF33) -> 0 | ... AK33: =SUM(A:B!AK33) -> 0 | AL33: =AK33/AK$6 -> 0 | AM33: =IFERROR(AK33/V33-1,0) -> -1 | AO33: 2.4593624e+08 | AQ33: 0.1359541
I34: MARGEN DE UTILIDAD | J34: =J6-J13 -> 1086481 | K34: =K6-K13 -> 1172394 | L34: =L6-L13 -> 1513835 | M34: =M6-M13 -> 1602934 | N34: =N6-N13 -> 1748688 | O34: =O6-O13 -> 1765808 | P34: =P6-P13 -> 1408449 | Q34: =Q6-Q13 -> 1480274 | ... V34: =V6-V13 -> 18302389 | W34: =V34/V$6 -> 0.081753468 | Y34: =Y6-Y13 -> 1685659.5 | Z34: =Z6-Z13 -> 1442426 | AA34: =AA6-AA13 -> 1965910.9 | AB34: =AB6-AB13 -> 1708121.1 | AC34: =AC6-AC13 -> 2074145.8 | AD34: =AD6-AD13 -> 1868457.3 | AE34: =AE6-AE13 -> 1787126.4 | AF34: =AF6-AF13 -> 1869483 | ... AK34: =AK6-AK13 -> 22662506 | AL34: =AK34/AK$6 -> 0.090382256 | AM34: =IFERROR(AK34/V34-1,0) -> 0.23822664 | AO34: 2.0184766e+08 | AP34: 0.045795303 | AQ34: 0.11498405
I35: *Regular | J35: =SUM(A:B!J35) -> 1001085 | K35: =SUM(A:B!K35) -> 1097495 | L35: =SUM(A:B!L35) -> 1401632 | M35: =SUM(A:B!M35) -> 1479528 | N35: =SUM(A:B!N35) -> 1551893 | O35: =SUM(A:B!O35) -> 1507543 | P35: =SUM(A:B!P35) -> 1399383 | Q35: =SUM(A:B!Q35) -> 1423247 | ... U35: =SUM(A:B!U35) -> 1533365 | V35: =SUM(J35:U35) -> 16995266 | W35: =V35/V$39 -> -810.41753 | Y35: =SUM(A:B!Y35) -> 1319638.3 | Z35: =SUM(A:B!Z35) -> 1099189.3 | AA35: =SUM(A:B!AA35) -> 1550720.4 | AB35: =SUM(A:B!AB35) -> 1327424.3 | AC35: =SUM(A:B!AC35) -> 1620445.9 | AD35: =SUM(A:B!AD35) -> 1486340.2 | AE35: =SUM(A:B!AE35) -> 1402949.1 | AF35: =SUM(A:B!AF35) -> 1433617.2 | ... AJ35: =SUM(A:B!AJ35) -> 1561605.4 | AK35: =SUM(Y35:AJ35) -> 17622120 | AL35: =AK35/AK$39 -> #DIV/0! | AM35: =IFERROR(AK35/V35-1,0) -> 0.036884058 | AO35: 17513400 | AP35: 0.0039734494 | AQ35: 0.2160961
I36: *Premium | J36: =SUM(A:B!J36) -> 270882 | K36: =SUM(A:B!K36) -> 262355 | L36: =SUM(A:B!L36) -> 319414 | M36: =SUM(A:B!M36) -> 332510 | N36: =SUM(A:B!N36) -> 427513 | O36: =SUM(A:B!O36) -> 460370 | P36: =SUM(A:B!P36) -> 237976 | Q36: =SUM(A:B!Q36) -> 314082 | ... U36: =SUM(A:B!U36) -> 350882.22 | V36: =SUM(J36:U36) -> 4028630.9 | W36: =V36/V$39 -> -192.10485 | Y36: =SUM(A:B!Y36) -> 354333.45 | Z36: =SUM(A:B!Z36) -> 333183.19 | AA36: =SUM(A:B!AA36) -> 400038.43 | AB36: =SUM(A:B!AB36) -> 363447.05 | AC36: =SUM(A:B!AC36) -> 432928.69 | AD36: =SUM(A:B!AD36) -> 368281.3 | AE36: =SUM(A:B!AE36) -> 367117.93 | AF36: =SUM(A:B!AF36) -> 422464.64 | ... AJ36: =SUM(A:B!AJ36) -> 444298.51 | AK36: =SUM(Y36:AJ36) -> 4864758.7 | AL36: =AK36/AK$39 -> #DIV/0! | AM36: =IFERROR(AK36/V36-1,0) -> 0.2075464 | AO36: 26575182 | AP36: 0.0060293911 | AQ36: 0.26135799
I37: *Diesel | J37: =SUM(A:B!J37) -> 14035 | K37: =SUM(A:B!K37) -> 9009 | L37: =SUM(A:B!L37) -> 12996 | M37: =SUM(A:B!M37) -> 11131 | N37: =SUM(A:B!N37) -> 24319 | O37: =SUM(A:B!O37) -> 16600 | P37: =SUM(A:B!P37) -> 12364 | Q37: =SUM(A:B!Q37) -> 4315 | ... U37: =SUM(A:B!U37) -> 11790.667 | V37: =SUM(J37:U37) -> 151931.67 | W37: =V37/V$39 -> -7.2448461 | Y37: =SUM(A:B!Y37) -> 9971.78 | Z37: =SUM(A:B!Z37) -> 8541.52 | AA37: =SUM(A:B!AA37) -> 12092 | AB37: =SUM(A:B!AB37) -> 14285.7 | AC37: =SUM(A:B!AC37) -> 17267.23 | AD37: =SUM(A:B!AD37) -> 10895.8 | AE37: =SUM(A:B!AE37) -> 13891.32 | AF37: =SUM(A:B!AF37) -> 10005.12 | ... AJ37: =SUM(A:B!AJ37) -> 9772.19 | AK37: =SUM(Y37:AJ37) -> 137058.81 | AL37: =AK37/AK$39 -> #DIV/0! | AM37: =IFERROR(AK37/V37-1,0) -> -0.09789175 | AO37: 2.6459886 | AQ37: 0.029597448
I38: * Aceites y Lubricantes | J38: =SUM(A:B!J38) -> 4066 | K38: =SUM(A:B!K38) -> 2794 | L38: =SUM(A:B!L38) -> 5238 | M38: =SUM(A:B!M38) -> 7617 | N38: =SUM(A:B!N38) -> 5989 | O38: =SUM(A:B!O38) -> 14066 | P38: =SUM(A:B!P38) -> 5887 | Q38: =SUM(A:B!Q38) -> -17400 | ... U38: =SUM(A:B!U38) -> 3011.3333 | V38: =SUM(J38:U38) -> 40302.333 | W38: =V38/V$39 -> -1.9218127 | Y38: =SUM(A:B!Y38) -> 0 | Z38: =SUM(A:B!Z38) -> 0 | AA38: =SUM(A:B!AA38) -> 0 | AB38: =SUM(A:B!AB38) -> 0 | AC38: =SUM(A:B!AC38) -> 0 | AD38: =SUM(A:B!AD38) -> 0 | AE38: =SUM(A:B!AE38) -> 0 | AF38: =SUM(A:B!AF38) -> 0 | ... AJ38: =SUM(A:B!AJ38) -> 0 | AK38: =SUM(Y38:AJ38) -> 0 | AL38: =AK38/AK$39 -> #DIV/0! | AM38: =IFERROR(AK38/V38-1,0) -> -1 | AO38: 2.6923149 | AP38: 6.108338e-10 | AQ38: 0.03693009
I39: Litros vendidos | J39: =SUM(A:B!J33) -> -3485 | K39: =SUM(A:B!K33) -> 0 | L39: =SUM(A:B!L33) -> -2310 | M39: =SUM(A:B!M33) -> 0 | N39: =SUM(A:B!N33) -> -2310 | O39: =SUM(A:B!O33) -> -4642 | P39: =SUM(A:B!P33) -> 0 | Q39: =SUM(A:B!Q33) -> 0 | ... U39: =SUM(A:B!U33) -> -2056 | V39: =SUM(J39:U39) -> -20971 | W39: =V39/V$39 -> 1 | Y39: =SUM(A:B!Y33) -> 0 | Z39: =SUM(A:B!Z33) -> 0 | AA39: =SUM(A:B!AA33) -> 0 | AB39: =SUM(A:B!AB33) -> 0 | AC39: =SUM(A:B!AC33) -> 0 | AD39: =SUM(A:B!AD33) -> 0 | AE39: =SUM(A:B!AE33) -> 0 | AF39: =SUM(A:B!AF33) -> 0 | ... AJ39: =SUM(A:B!AJ33) -> 0 | AK39: =SUM(Y39:AJ39) -> 0 | AL39: =AK39/AK$39 -> #DIV/0! | AM39: =IFERROR(AK39/V39-1,0) -> -1 | AO39: 2.4351104 | AP39: 5.5247911e-10 | AQ39: 0.11346523
I40: Maxima | J40: =SUM(A:B!J40) -> 652504 | K40: =SUM(A:B!K40) -> 579451 | L40: =SUM(A:B!L40) -> 706034 | M40: =SUM(A:B!M40) -> 653794 | N40: =SUM(A:B!N40) -> 753315 | O40: =SUM(A:B!O40) -> 741483 | P40: =SUM(A:B!P40) -> 707921 | Q40: =SUM(A:B!Q40) -> 715486 | ... U40: =SUM(A:B!U40) -> 782396 | V40: =SUM(J40:U40) -> 8626933 | W40: =V40/V$39 -> -411.37442 | Y40: =SUM(A:B!Y40) -> 710418.3 | Z40: =SUM(A:B!Z40) -> 635498.3 | AA40: =SUM(A:B!AA40) -> 763448.3 | AB40: =SUM(A:B!AB40) -> 732477.3 | AC40: =SUM(A:B!AC40) -> 821532.3 | AD40: =SUM(A:B!AD40) -> 807702.3 | AE40: =SUM(A:B!AE40) -> 774024.3 | AF40: =SUM(A:B!AF40) -> 773496.3 | ... AJ40: =SUM(A:B!AJ40) -> 847993.3 | AK40: =SUM(Y40:AJ40) -> 9418878.6 | AL40: =AK40/AK$39 -> #DIV/0! | AM40: =IFERROR(AK40/V40-1,0) -> 0.091799205 | AO40: 2.4330962 | AP40: 5.5202214e-10 | AQ40: 0.11307939
I41: Super | J41: =SUM(A:B!J41) -> 147578 | K41: =SUM(A:B!K41) -> 142154 | L41: =SUM(A:B!L41) -> 160901 | M41: =SUM(A:B!M41) -> 151568 | N41: =SUM(A:B!N41) -> 172299 | O41: =SUM(A:B!O41) -> 158797 | P41: =SUM(A:B!P41) -> 153571 | Q41: =SUM(A:B!Q41) -> 166736 | ... U41: =SUM(A:B!U41) -> 185941 | V41: =SUM(J41:U41) -> 2002797 | W41: =V41/V$39 -> -95.503171 | Y41: =SUM(A:B!Y41) -> 150531 | Z41: =SUM(A:B!Z41) -> 144897 | AA41: =SUM(A:B!AA41) -> 165165 | AB41: =SUM(A:B!AB41) -> 158674 | AC41: =SUM(A:B!AC41) -> 177640 | AD41: =SUM(A:B!AD41) -> 163370 | AE41: =SUM(A:B!AE41) -> 158178 | AF41: =SUM(A:B!AF41) -> 174248 | ... AJ41: =SUM(A:B!AJ41) -> 190869 | AK41: =SUM(Y41:AJ41) -> 2065787 | AL41: =AK41/AK$39 -> #DIV/0! | AM41: =IFERROR(AK41/V41-1,0) -> 0.031451016
...

Sheet S

Sheet COM-MKT
I1: Mantenimiento de Imagen | Y1: 2 | Z1: 3 | AA1: 4 | AB1: 5 | AC1: 6 | AD1: 7 | AE1: 8 | AF1: 9 | AG1: 10 | AH1: 11 | AI1: 12 | AJ1: 13 | AM1: 17
J2: 2024 | V2: TOTAL ANUAL | Y2: 2025 | AK2: TOTAL ANUAL
J3: ENE | K3: FEB | L3: MAR | M3: ABR | N3: MAY | O3: JUN | P3: JUL | Q3: AGO | R3: SEP | S3: OCT | T3: NOV | U3: DIC | V3: 2024 | W3: % Part | Y3: ENE | Z3: FEB | AA3: MAR | AB3: ABR | AC3: MAY | AD3: JUN | AE3: JUL | AF3: AGO | AG3: SEP | AH3: OCT | AI3: NOV | AJ3: DIC | AK3: 2025 | AL3: % Part | AM3: Var vs AA%
I4: INGRESOS
A6: A - INGRESOS | E6: ( mas ) | I6: A - INGRESOS | V6: =SUM(J6:U6) -> 0 | W6: =V6/V$6 -> #DIV/0! | Y6: =SUM(Y7:Y10) -> 0 | Z6: =SUM(Z7:Z10) -> 0 | AA6: =SUM(AA7:AA10) -> 0 | AB6: =SUM(AB7:AB10) -> 0 | AC6: =SUM(AC7:AC10) -> 0 | AD6: =SUM(AD7:AD10) -> 0 | AE6: =SUM(AE7:AE10) -> 0 | AF6: =SUM(AF7:AF10) -> 0 | ... AJ6: =SUM(AJ7:AJ10) -> 0 | AK6: =SUM(Y6:AJ6) -> 0 | AL6: =AK6/AK$6 -> #DIV/0! | AM6: =IFERROR(AK6/V6-1,0) -> 0
A7: A - INGRESOS | B7: estaciones | C7: INGRESOS MAGNA | D7: INGRESOS FORANEOS MAGNA | I7: T-MAXIMA REGULAR | V7: =SUM(J7:U7) -> 0 | W7: =V7/V$6 -> #DIV/0! | Y7: 0 | Z7: 0 | AA7: 0 | AB7: 0 | AC7: 0 | AD7: 0 | AE7: 0 | AF7: 0 | AG7: 0 | AH7: 0 | AI7: 0 | AJ7: 0 | AK7: =SUM(Y7:AJ7) -> 0 | AL7: =AK7/AK$6 -> #DIV/0! | AM7: =IFERROR(AK7/V7-1,0) -> 0
A8: A - INGRESOS | B8: estaciones | C8: INGRESOS PREMIUM | D8: INGRESOS FORANEOS PREMIUM | I8: T-SUPER PREMIUM | V8: =SUM(J8:U8) -> 0 | W8: =V8/V$6 -> #DIV/0! | Y8: 0 | Z8: 0 | AA8: 0 | AB8: 0 | AC8: 0 | AD8: 0 | AE8: 0 | AF8: 0 | AG8: 0 | AH8: 0 | AI8: 0 | AJ8: 0 | AK8: =SUM(Y8:AJ8) -> 0 | AL8: =AK8/AK$6 -> #DIV/0! | AM8: =IFERROR(AK8/V8-1,0) -> 0
A9: A - INGRESOS | B9: estaciones | C9: INGRESOS DIESEL | D9: INGRESOS FORANEOS DIESEL | I9: DIESEL AUTOMOTRIZ | V9: =SUM(J9:U9) -> 0 | W9: =V9/V$6 -> #DIV/0! | Y9: 0 | Z9: 0 | AA9: 0 | AB9: 0 | AC9: 0 | AD9: 0 | AE9: 0 | AF9: 0 | AG9: 0 | AH9: 0 | AI9: 0 | AJ9: 0 | AK9: =SUM(Y9:AJ9) -> 0 | AL9: =AK9/AK$6 -> #DIV/0! | AM9: =IFERROR(AK9/V9-1,0) -> 0
A10: A - INGRESOS | B10: estaciones | C10: INGRESOS ADITIVOS | D10: INGRESOS ESPECIALES | F10: INGRESOS FORANEOS ESPECIALES | G10: INGRESOS FORANEOS LUBRICANTES | H10: INGRESOS LUBRICANTES | I10: PREPAGO facturación (neto) | V10: =SUM(J10:U10) -> 0 | W10: =V10/V$6 -> #DIV/0! | Y10: 0 | Z10: 0 | AA10: 0 | AB10: 0 | AC10: 0 | AD10: 0 | AE10: 0 | AF10: 0 | AG10: 0 | AH10: 0 | AI10: 0 | AJ10: 0 | AK10: =SUM(Y10:AJ10) -> 0 | AL10: =AK10/AK$6 -> #DIV/0! | AM10: =IFERROR(AK10/V10-1,0) -> 0
A11: A - INGRESOS | B11: estaciones | C11: INGRESOS ADITIVOS | D11: INGRESOS ESPECIALES | E11: INGRESOS FORANEOS ADITIVOS | F11: INGRESOS FORANEOS ESPECIALES | G11: INGRESOS FORANEOS LUBRICANTES | H11: INGRESOS LUBRICANTES | I11: INGRESOS ACEITES Y LUBRICANTES | V11: =SUM(J11:U11) -> 0 | W11: =V11/V$6 -> #DIV/0! | Y11: 0 | Z11: 0 | AA11: 0 | AB11: 0 | AC11: 0 | AD11: 0 | AE11: 0 | AF11: 0 | AG11: 0 | AH11: 0 | AI11: 0 | AJ11: 0 | AK11: =SUM(Y11:AJ11) -> 0 | AL11: =AK11/AK$6 -> #DIV/0! | AM11: =IFERROR(AK11/V11-1,0) -> 0
I12: SOBRANTE REGULAR
I13: SOBRANTE PREMIUM
I14: SOBRANTE DIESEL
A15: B - COSTO DE VENTA | E15: ( menos ) | I15: B - COSTO DE VENTA | V15: =SUM(J15:U15) -> 0 | W15: =V15/V$6 -> #DIV/0! | Y15: =SUM(Y16:Y31) -> 0 | Z15: =SUM(Z16:Z31) -> 0 | AA15: =SUM(AA16:AA31) -> 0 | AB15: =SUM(AB16:AB31) -> 0 | AC15: =SUM(AC16:AC31) -> 0 | AD15: =SUM(AD16:AD31) -> 0 | AE15: =SUM(AE16:AE31) -> 0 | AF15: =SUM(AF16:AF31) -> 0 | ... AJ15: =SUM(AJ16:AJ31) -> 0 | AK15: =SUM(Y15:AJ15) -> 0 | AL15: =AK15/AK$6 -> #DIV/0! | AM15: =IFERROR(AK15/V15-1,0) -> 0
A16: B - COSTO DE VENTA | C16: COSTO MAGNA | D16: COSTO FORANEO MAGNA | I16: GASOLINA REGULAR | V16: =SUM(J16:U16) -> 0 | W16: =V16/V$6 -> #DIV/0! | Y16: 0 | Z16: 0 | AA16: 0 | AB16: 0 | AC16: 0 | AD16: 0 | AE16: 0 | AF16: 0 | AG16: 0 | AH16: 0 | AI16: 0 | AJ16: 0 | AK16: =SUM(Y16:AJ16) -> 0 | AL16: =AK16/AK$6 -> #DIV/0! | AM16: =IFERROR(AK16/V16-1,0) -> 0
A17: B - COSTO DE VENTA | C17: COSTO PREMIUM | D17: COSTO FORANEO PREMIUM | I17: GASOLINA PREMIUM | V17: =SUM(J17:U17) -> 0 | W17: =V17/V$6 -> #DIV/0! | Y17: 0 | Z17: 0 | AA17: 0 | AB17: 0 | AC17: 0 | AD17: 0 | AE17: 0 | AF17: 0 | AG17: 0 | AH17: 0 | AI17: 0 | AJ17: 0 | AK17: =SUM(Y17:AJ17) -> 0 | AL17: =AK17/AK$6 -> #DIV/0! | AM17: =IFERROR(AK17/V17-1,0) -> 0
A18: B - COSTO DE VENTA | C18: COSTO DIESEL | D18: COSTO FORANEO DIESEL | I18: DIESEL | V18: =SUM(J18:U18) -> 0 | W18: =V18/V$6 -> #DIV/0! | Y18: 0 | Z18: 0 | AA18: 0 | AB18: 0 | AC18: 0 | AD18: 0 | AE18: 0 | AF18: 0 | AG18: 0 | AH18: 0 | AI18: 0 | AJ18: 0 | AK18: =SUM(Y18:AJ18) -> 0 | AL18: =AK18/AK$6 -> #DIV/0! | AM18: =IFERROR(AK18/V18-1,0) -> 0
A19: B - COSTO DE VENTA | C19: Merma Magna | I19: MERMA GASOLINA REGULAR | V19: =SUM(J19:U19) -> 0 | W19: =V19/V$6 -> #DIV/0! | Y19: 0 | Z19: 0 | AA19: 0 | AB19: 0 | AC19: 0 | AD19: 0 | AE19: 0 | AF19: 0 | AG19: 0 | AH19: 0 | AI19: 0 | AJ19: 0 | AK19: =SUM(Y19:AJ19) -> 0 | AL19: =AK19/AK$6 -> #DIV/0! | AM19: =IFERROR(AK19/V19-1,0) -> 0
A20: B - COSTO DE VENTA | C20: Merma Premium | I20: MERMA GASOLINA PREMIUM | V20: =SUM(J20:U20) -> 0 | W20: =V20/V$6 -> #DIV/0! | Y20: 0 | Z20: 0 | AA20: 0 | AB20: 0 | AC20: 0 | AD20: 0 | AE20: 0 | AF20: 0 | AG20: 0 | AH20: 0 | AI20: 0 | AJ20: 0 | AK20: =SUM(Y20:AJ20) -> 0 | AL20: =AK20/AK$6 -> #DIV/0! | AM20: =IFERROR(AK20/V20-1,0) -> 0
A21: B - COSTO DE VENTA | C21: Merma Diesel | I21: MERMA DIESEL | V21: =SUM(J21:U21) -> 0 | W21: =V21/V$6 -> #DIV/0! | Y21: 0 | Z21: 0 | AA21: 0 | AB21: 0 | AC21: 0 | AD21: 0 | AE21: 0 | AF21: 0 | AG21: 0 | AH21: 0 | AI21: 0 | AJ21: 0 | AK21: =SUM(Y21:AJ21) -> 0 | AL21: =AK21/AK$6 -> #DIV/0! | AM21: =IFERROR(AK21/V21-1,0) -> 0
A22: B - COSTO DE VENTA | C22: ADITIVO PARA GASOLINA TMAXIMA (REGULAR) | D22: ADITIVO PARA GASOLINA TMAXIMA( REGULAR) | I22: ADITIVO TOTAL POWER GASOLINA REG | V22: =SUM(J22:U22) -> 0 | W22: =V22/V$6 -> #DIV/0! | Y22: 0 | Z22: 0 | AA22: 0 | AB22: 0 | AC22: 0 | AD22: 0 | AE22: 0 | AF22: 0 | AG22: 0 | AH22: 0 | AI22: 0 | AJ22: 0 | AK22: =SUM(Y22:AJ22) -> 0 | AL22: =AK22/AK$6 -> #DIV/0! | AM22: =IFERROR(AK22/V22-1,0) -> 0
A23: B - COSTO DE VENTA | C23: ADITIVO PARA GASOLINA TSUPER (PREMIUM) | I23: ADITIVO TOTAL POWER GASOLINA PREM | V23: =SUM(J23:U23) -> 0 | W23: =V23/V$6 -> #DIV/0! | Y23: 0 | Z23: 0 | AA23: 0 | AB23: 0 | AC23: 0 | AD23: 0 | AE23: 0 | AF23: 0 | AG23: 0 | AH23: 0 | AI23: 0 | AJ23: 0 | AK23: =SUM(Y23:AJ23) -> 0 | AL23: =AK23/AK$6 -> #DIV/0! | AM23: =IFERROR(AK23/V23-1,0) -> 0
A24: B - COSTO DE VENTA | C24: FLETE MAGNA | I24: FLETE GASOLINA REGULAR | V24: =SUM(J24:U24) -> 0 | W24: =V24/V$6 -> #DIV/0! | Y24: 0 | Z24: 0 | AA24: 0 | AB24: 0 | AC24: 0 | AD24: 0 | AE24: 0 | AF24: 0 | AG24: 0 | AH24: 0 | AI24: 0 | AJ24: 0 | AK24: =SUM(Y24:AJ24) -> 0 | AL24: =AK24/AK$6 -> #DIV/0! | AM24: =IFERROR(AK24/V24-1,0) -> 0
A25: B - COSTO DE VENTA | C25: FLETE PREMIUM | I25: FLETE GASOLINA PREMIUM | V25: =SUM(J25:U25) -> 0 | W25: =V25/V$6 -> #DIV/0! | Y25: 0 | Z25: 0 | AA25: 0 | AB25: 0 | AC25: 0 | AD25: 0 | AE25: 0 | AF25: 0 | AG25: 0 | AH25: 0 | AI25: 0 | AJ25: 0 | AK25: =SUM(Y25:AJ25) -> 0 | AL25: =AK25/AK$6 -> #DIV/0! | AM25: =IFERROR(AK25/V25-1,0) -> 0
A26: B - COSTO DE VENTA | C26: FLETE DIESEL | I26: FLETE DIESEL | V26: =SUM(J26:U26) -> 0 | W26: =V26/V$6 -> #DIV/0! | Y26: 0 | Z26: 0 | AA26: 0 | AB26: 0 | AC26: 0 | AD26: 0 | AE26: 0 | AF26: 0 | AG26: 0 | AH26: 0 | AI26: 0 | AJ26: 0 | AK26: =SUM(Y26:AJ26) -> 0 | AL26: =AK26/AK$6 -> #DIV/0! | AM26: =IFERROR(AK26/V26-1,0) -> 0
A27: B - COSTO DE VENTA | C27: Estimulo IEPS Magna | D27: INGRESOS FORANEOS MAGNA | I27: ESTIMULO REGULAR | V27: =SUM(J27:U27) -> 0 | W27: =V27/V$6 -> #DIV/0! | Y27: 0 | Z27: 0 | AA27: 0 | AB27: 0 | AC27: 0 | AD27: 0 | AE27: 0 | AF27: 0 | AG27: 0 | AH27: 0 | AI27: 0 | AJ27: 0 | AK27: =SUM(Y27:AJ27) -> 0 | AL27: =AK27/AK$6 -> #DIV/0! | AM27: =IFERROR(AK27/V27-1,0) -> 0
A28: B - COSTO DE VENTA | C28: Estimulo IEPS Premium | D28: INGRESOS FORANEOS MAGNA | I28: ESTIMULO PREMIUM | V28: =SUM(J28:U28) -> 0 | W28: =V28/V$6 -> #DIV/0! | Y28: 0 | Z28: 0 | AA28: 0 | AB28: 0 | AC28: 0 | AD28: 0 | AE28: 0 | AF28: 0 | AG28: 0 | AH28: 0 | AI28: 0 | AJ28: 0 | AK28: =SUM(Y28:AJ28) -> 0 | AL28: =AK28/AK$6 -> #DIV/0! | AM28: =IFERROR(AK28/V28-1,0) -> 0
I29: DESCUENTO SOBRE VENTA
I30: COSTO UNIFORMES
I31: COSTO ACEITES Y LUBRICANTES | V31: =SUM(J31:U31) -> 0 | W31: =V31/V$6 -> #DIV/0! | Y31: 0 | Z31: 0 | AA31: 0 | AB31: 0 | AC31: 0 | AD31: 0 | AE31: 0 | AF31: 0 | AG31: 0 | AH31: 0 | AI31: 0 | AJ31: 0 | AK31: =SUM(Y31:AJ31) -> 0 | AL31: =AK31/AK$6 -> #DIV/0! | AM31: =IFERROR(AK31/V31-1,0) -> 0
I32: MARGEN DE UTILIDAD | V32: =V6-V15 -> 0 | W32: =V32/V$6 -> #DIV/0! | Y32: =Y6-Y15 -> 0 | Z32: =Z6-Z15 -> 0 | AA32: =AA6-AA15 -> 0 | AB32: =AB6-AB15 -> 0 | AC32: =AC6-AC15 -> 0 | AD32: =AD6-AD15 -> 0 | AE32: =AE6-AE15 -> 0 | AF32: =AF6-AF15 -> 0 | ... AK32: =AK6-AK15 -> 0 | AL32: =AK32/AK$6 -> #DIV/0! | AM32: =IFERROR(AK32/V32-1,0) -> 0
I33: Regular | V33: =SUM(J33:U33) -> 0 | Y33: =+Y43*Y39 -> 0 | Z33: =+Z43*Z39 -> 0 | AA33: =+AA43*AA39 -> 0 | AB33: =+AB43*AB39 -> 0 | AC33: =+AC43*AC39 -> 0 | AD33: =+AD43*AD39 -> 0 | AE33: =+AE43*AE39 -> 0 | AF33: =+AF43*AF39 -> 0 | ... AJ33: =+AJ43*AJ39 -> 0 | AK33: =SUM(Y33:AJ33) -> 0 | AM33: =IFERROR(AK33/V33-1,0) -> 0
I34: Premium | V34: =SUM(J34:U34) -> 0 | Y34: =+Y44*Y40 -> 0 | Z34: =+Z44*Z40 -> 0 | AA34: =+AA44*AA40 -> 0 | AB34: =+AB44*AB40 -> 0 | AC34: =+AC44*AC40 -> 0 | AD34: =+AD44*AD40 -> 0 | AE34: =+AE44*AE40 -> 0 | AF34: =+AF44*AF40 -> 0 | ... AJ34: =+AJ44*AJ40 -> 0 | AK34: =SUM(Y34:AJ34) -> 0 | AM34: =IFERROR(AK34/V34-1,0) -> 0
I35: Diesel | V35: =SUM(J35:U35) -> 0 | Y35: =+Y45*Y41 -> 0 | Z35: =+Z45*Z41 -> 0 | AA35: =+AA45*AA41 -> 0 | AB35: =+AB45*AB41 -> 0 | AC35: =+AC45*AC41 -> 0 | AD35: =+AD45*AD41 -> 0 | AE35: =+AE45*AE41 -> 0 | AF35: =+AF45*AF41 -> 0 | ... AJ35: =+AJ45*AJ41 -> 0 | AK35: =SUM(Y35:AJ35) -> 0 | AM35: =IFERROR(AK35/V35-1,0) -> 0
I36: *Otros Conceptos
I37: * Aceites y Lubricantes
I38: Litros vendidos | V38: =SUM(J38:U38) -> 0 | W38: =V38/V$38 -> #DIV/0! | Y38: =SUM(Y39:Y41) -> 0 | Z38: =SUM(Z39:Z41) -> 0 | AA38: =SUM(AA39:AA41) -> 0 | AB38: =SUM(AB39:AB41) -> 0 | AC38: =SUM(AC39:AC41) -> 0 | AD38: =SUM(AD39:AD41) -> 0 | AE38: =SUM(AE39:AE41) -> 0 | AF38: =SUM(AF39:AF41) -> 0 | ... AJ38: =SUM(AJ39:AJ41) -> 0 | AK38: =SUM(Y38:AJ38) -> 0 | AL38: =AK38/AK$38 -> #DIV/0! | AM38: =IFERROR(AK38/V38-1,0) -> 0
I39: Regular | V39: =SUM(J39:U39) -> 0 | W39: =V39/V$38 -> #DIV/0! | Y39: 0 | Z39: 0 | AA39: 0 | AB39: 0 | AC39: 0 | AD39: 0 | AE39: 0 | AF39: 0 | AG39: 0 | AH39: 0 | AI39: 0 | AJ39: 0 | AK39: =SUM(Y39:AJ39) -> 0 | AL39: =AK39/AK$38 -> #DIV/0! | AM39: =IFERROR(AK39/V39-1,0) -> 0
I40: Premium | V40: =SUM(J40:U40) -> 0 | W40: =V40/V$38 -> #DIV/0! | Y40: 0 | Z40: 0 | AA40: 0 | AB40: 0 | AC40: 0 | AD40: 0 | AE40: 0 | AF40: 0 | AG40: 0 | AH40: 0 | AI40: 0 | AJ40: 0 | AK40: =SUM(Y40:AJ40) -> 0 | AL40: =AK40/AK$38 -> #DIV/0! | AM40: =IFERROR(AK40/V40-1,0) -> 0
I41: Diesel | V41: =SUM(J41:U41) -> 0 | W41: =V41/V$38 -> #DIV/0! | Y41: 0 | Z41: 0 | AA41: 0 | AB41: 0 | AC41: 0 | AD41: 0 | AE41: 0 | AF41: 0 | AG41: 0 | AH41: 0 | AI41: 0 | AJ41: 0 | AK41: =SUM(Y41:AJ41) -> 0 | AL41: =AK41/AK$38 -> #DIV/0! | AM41: =IFERROR(AK41/V41-1,0) -> 0
...

Sheet Z

Sheet TOTAL ESTACIONES
I1: 1147 | J1: 2 | K1: 3 | L1: 4 | M1: 5 | N1: 6 | O1: 7 | Y1: 2 | Z1: =+Y1+1 -> 3 | AA1: =+Z1+1 -> 4 | AB1: =+AA1+1 -> 5 | AC1: =+AB1+1 -> 6 | AD1: =+AC1+1 -> 7 | AE1: =+AD1+1 -> 8 | AF1: =+AE1+1 -> 9 | AG1: =+AF1+1 -> 10 | ... AK1: =+AJ1+1 -> 14 | AM1: 17
J2: 2025 | V2: TOTAL ANUAL | Y2: 2026 | AK2: TOTAL ANUAL
J3: ENE | K3: FEB | L3: MAR | M3: ABR | N3: MAY | O3: JUN | P3: JUL | Q3: AGO | R3: SEP | S3: OCT | T3: NOV | U3: DIC | V3: 2025 | W3: % Part | Y3: ENE | Z3: FEB | AA3: MAR | AB3: ABR | AC3: MAY | AD3: JUN | AE3: JUL | AF3: AGO | AG3: SEP | AH3: OCT | AI3: NOV | AJ3: DIC | AK3: 2026 | AL3: % Part | AM3: Var vs AA%
I4: INGRESOS
A6: A - INGRESOS | E6: ( mas ) | I6: A - INGRESOS | J6: =SUM(J7:J12) -> 17192824 | K6: =SUM(K7:K12) -> 15590830 | L6: =SUM(L7:L12) -> 18254554 | M6: =SUM(M7:M12) -> 17513698 | N6: =SUM(N7:N12) -> 19514034 | O6: =SUM(O7:O12) -> 18936949 | P6: =SUM(P7:P12) -> 18138616 | Q6: =SUM(Q7:Q12) -> 18621506 | ... V6: =SUM(V7:V12) -> 223872939 | W6: =V6/V$6 -> 1 | Y6: =SUM(Y7:Y12) -> 18780611 | Z6: =SUM(Z7:Z12) -> 17035192 | AA6: =SUM(AA7:AA12) -> 20269984 | AB6: =SUM(AB7:AB12) -> 19487182 | AC6: =SUM(AC7:AC12) -> 21864209 | AD6: =SUM(AD7:AD12) -> 21197316 | AE6: =SUM(AE7:AE12) -> 20370243 | AF6: =SUM(AF7:AF12) -> 20697143 | ... AK6: =SUM(AK7:AK12) -> 2.5074065e+08 | AL6: =AK6/AK$6 -> 1 | AM6: =IFERROR(AK6/V6-1,0) -> 0.12001323
A7: A - INGRESOS | B7: estaciones | C7: INGRESOS MAGNA | D7: INGRESOS FORANEOS MAGNA | I7: MAXIMA | J7: =SUM(A:B!J7) -> 13803132 | K7: =SUM(A:B!K7) -> 12317959 | L7: =SUM(A:B!L7) -> 14526332 | M7: =SUM(A:B!M7) -> 13887455 | N7: =SUM(A:B!N7) -> 15477447 | O7: =SUM(A:B!O7) -> 15236060 | P7: =SUM(A:B!P7) -> 14546459 | Q7: =SUM(A:B!Q7) -> 14677535 | ... U7: =SUM(A:B!U7) -> 15732735 | V7: =SUM(J7:U7) -> 1.7740332e+08 | W7: =V7/V$6 -> 0.79242861 | Y7: =SUM(A:B!Y7) -> 15202952 | Z7: =SUM(A:B!Z7) -> 13599664 | AA7: =SUM(A:B!AA7) -> 16337794 | AB7: =SUM(A:B!AB7) -> 15675014 | AC7: =SUM(A:B!AC7) -> 17580791 | AD7: =SUM(A:B!AD7) -> 17284829 | AE7: =SUM(A:B!AE7) -> 16564120 | AF7: =SUM(A:B!AF7) -> 16552821 | ... AJ7: =SUM(A:B!AJ7) -> 18147057 | AK7: =SUM(Y7:AJ7) -> 2.01564e+08 | AL7: =AK7/AK$6 -> 0.80387444 | AM7: =IFERROR(AK7/V7-1,0) -> 0.13619069
A8: A - INGRESOS | B8: estaciones | C8: INGRESOS PREMIUM | D8: INGRESOS FORANEOS PREMIUM | I8: SUPER | J8: =SUM(A:B!J8) -> 3260550 | K8: =SUM(A:B!K8) -> 3155615 | L8: =SUM(A:B!L8) -> 3577713 | M8: =SUM(A:B!M8) -> 3447065 | N8: =SUM(A:B!N8) -> 3825441 | O8: =SUM(A:B!O8) -> 3528128 | P8: =SUM(A:B!P8) -> 3411360 | Q8: =SUM(A:B!Q8) -> 3791076 | ... U8: =SUM(A:B!U8) -> 4133088.9 | V8: =SUM(J8:U8) -> 44529304 | W8: =V8/V$6 -> 0.19890436 | Y8: =SUM(A:B!Y8) -> 3435117.4 | Z8: =SUM(A:B!Z8) -> 3306549.5 | AA8: =SUM(A:B!AA8) -> 3769065.3 | AB8: =SUM(A:B!AB8) -> 3620940.7 | AC8: =SUM(A:B!AC8) -> 4053744.8 | AD8: =SUM(A:B!AD8) -> 3728103.4 | AE8: =SUM(A:B!AE8) -> 3609622 | AF8: =SUM(A:B!AF8) -> 3976339.4 | ... AJ8: =SUM(A:B!AJ8) -> 4355630.6 | AK8: =SUM(Y8:AJ8) -> 47141259 | AL8: =AK8/AK$6 -> 0.18800804 | AM8: =IFERROR(AK8/V8-1,0) -> 0.05865701
A9: A - INGRESOS | B9: estaciones | C9: INGRESOS DIESEL | D9: INGRESOS FORANEOS DIESEL | I9: DIESEL | J9: =SUM(A:B!J9) -> 119320 | K9: =SUM(A:B!K9) -> 108214 | L9: =SUM(A:B!L9) -> 130827 | M9: =SUM(A:B!M9) -> 157657 | N9: =SUM(A:B!N9) -> 189122 | O9: =SUM(A:B!O9) -> 151966 | P9: =SUM(A:B!P9) -> 162434 | Q9: =SUM(A:B!Q9) -> 130655 | ... U9: =SUM(A:B!U9) -> 139359.89 | V9: =SUM(J9:U9) -> 1707634.6 | W9: =V9/V$6 -> 0.0076276953 | Y9: =SUM(A:B!Y9) -> 133961.55 | Z9: =SUM(A:B!Z9) -> 121418.7 | AA9: =SUM(A:B!AA9) -> 147824.7 | AB9: =SUM(A:B!AB9) -> 176406.75 | AC9: =SUM(A:B!AC9) -> 212152.65 | AD9: =SUM(A:B!AD9) -> 169683 | AE9: =SUM(A:B!AE9) -> 180661.05 | AF9: =SUM(A:B!AF9) -> 151003.2 | ... AJ9: =SUM(A:B!AJ9) -> 132005.55 | AK9: =SUM(Y9:AJ9) -> 1842552 | AL9: =AK9/AK$6 -> 0.0073484374 | AM9: =IFERROR(AK9/V9-1,0) -> 0.079008383
I10: INGRESOS ACEITES Y LUBRICANTES | J10: =SUM(A:B!J10) -> 9822 | K10: =SUM(A:B!K10) -> 9042 | L10: =SUM(A:B!L10) -> 19682 | M10: =SUM(A:B!M10) -> 21521 | N10: =SUM(A:B!N10) -> 22024 | O10: =SUM(A:B!O10) -> 20795 | P10: =SUM(A:B!P10) -> 18363 | Q10: =SUM(A:B!Q10) -> 22240 | ... U10: =SUM(A:B!U10) -> 22297.778 | V10: =SUM(J10:U10) -> 232680.11 | W10: =V10/V$6 -> 0.00103934 | Y10: =SUM(A:B!Y10) -> 8580 | Z10: =SUM(A:B!Z10) -> 7560 | AA10: =SUM(A:B!AA10) -> 15300 | AB10: =SUM(A:B!AB10) -> 14820 | AC10: =SUM(A:B!AC10) -> 17520 | AD10: =SUM(A:B!AD10) -> 14700 | AE10: =SUM(A:B!AE10) -> 15840 | AF10: =SUM(A:B!AF10) -> 16980 | ... AJ10: =SUM(A:B!AJ10) -> 27480 | AK10: =SUM(Y10:AJ10) -> 192840 | AL10: =AK10/AK$6 -> 0.00076908151 | AM10: =IFERROR(AK10/V10-1,0) -> -0.17122268
I11: SOBRANTE COMBUSTIBLE | J11: =SUM(A:B!J11) -> 0 | K11: =SUM(A:B!K11) -> 0 | L11: =SUM(A:B!L11) -> 0 | M11: =SUM(A:B!M11) -> 0 | N11: =SUM(A:B!N11) -> 0 | O11: =SUM(A:B!O11) -> 0 | P11: =SUM(A:B!P11) -> 0 | Q11: =SUM(A:B!Q11) -> 0 | ... U11: =SUM(A:B!U11) -> 0 | V11: =SUM(J11:U11) -> 0 | W11: =V11/V$6 -> 0 | Y11: =SUM(A:B!Y11) -> 0 | Z11: =SUM(A:B!Z11) -> 0 | AA11: =SUM(A:B!AA11) -> 0 | AB11: =SUM(A:B!AB11) -> 0 | AC11: =SUM(A:B!AC11) -> 0 | AD11: =SUM(A:B!AD11) -> 0 | AE11: =SUM(A:B!AE11) -> 0 | AF11: =SUM(A:B!AF11) -> 0 | ... AJ11: =SUM(A:B!AJ11) -> 0 | AK11: =SUM(Y11:AJ11) -> 0 | AL11: =AK11/AK$6 -> 0 | AM11: =IFERROR(AK11/V11-1,0) -> 0
J12: =SUM(A:B!J12) -> 0 | K12: =SUM(A:B!K12) -> 0 | L12: =SUM(A:B!L12) -> 0 | M12: =SUM(A:B!M12) -> 0 | N12: =SUM(A:B!N12) -> 0 | O12: =SUM(A:B!O12) -> 0 | P12: =SUM(A:B!P12) -> 0 | Q12: =SUM(A:B!Q12) -> 0 | ... U12: =SUM(A:B!U12) -> 0 | V12: =SUM(J12:U12) -> 0 | W12: =V12/V$6 -> 0 | Y12: =SUM(A:B!Y12) -> 0 | Z12: =SUM(A:B!Z12) -> 0 | AA12: =SUM(A:B!AA12) -> 0 | AB12: =SUM(A:B!AB12) -> 0 | AC12: =SUM(A:B!AC12) -> 0 | AD12: =SUM(A:B!AD12) -> 0 | AE12: =SUM(A:B!AE12) -> 0 | AF12: =SUM(A:B!AF12) -> 0 | ... AJ12: =SUM(A:B!AJ12) -> 0 | AK12: =SUM(Y12:AJ12) -> 0 | AL12: =AK12/AK$6 -> 0 | AM12: =IFERROR(AK12/V12-1,0) -> 0
A13: B - COSTO DE VENTA | E13: ( menos ) | I13: B - COSTO DE VENTA | J13: =SUM(J14:J33) -> 15902755 | K13: =SUM(K14:K33) -> 14219176 | L13: =SUM(L14:L33) -> 16515274 | M13: =SUM(M14:M33) -> 15682912 | N13: =SUM(N14:N33) -> 17504319 | O13: =SUM(O14:O33) -> 16938367 | P13: =SUM(P14:P33) -> 16483004 | Q13: =SUM(Q14:Q33) -> 16897261 | ... V13: =SUM(V14:V33) -> 2.0267433e+08 | W13: =V13/V$6 -> 0.90530964 | Y13: =SUM(Y14:Y30) -> 17094951 | Z13: =SUM(Z14:Z30) -> 15592766 | AA13: =SUM(AA14:AA30) -> 18304073 | AB13: =SUM(AB14:AB30) -> 17779061 | AC13: =SUM(AC14:AC30) -> 19790063 | AD13: =SUM(AD14:AD30) -> 19328858 | AE13: =SUM(AE14:AE30) -> 18583117 | AF13: =SUM(AF14:AF30) -> 18827660 | ... AJ13: =SUM(AJ14:AJ30) -> 20641001 | AK13: =SUM(Y13:AJ13) -> 2.2807815e+08 | AL13: =AK13/AK$6 -> 0.90961774 | AM13: =IFERROR(AK13/V13-1,0) -> 0.12534304
A14: B - COSTO DE VENTA | C14: COSTO MAGNA | D14: COSTO FORANEO MAGNA | I14: GASOLINA REGULAR | J14: =SUM(A:B!J14) -> 12973548 | K14: =SUM(A:B!K14) -> 11404250 | L14: =SUM(A:B!L14) -> 13331662 | M14: =SUM(A:B!M14) -> 12710487 | N14: =SUM(A:B!N14) -> 14240584 | O14: =SUM(A:B!O14) -> 14028976 | P14: =SUM(A:B!P14) -> 13394436 | Q14: =SUM(A:B!Q14) -> 13534987 | ... U14: =SUM(A:B!U14) -> 14490738 | V14: =SUM(J14:U14) -> 1.6358188e+08 | W14: =V14/V$6 -> 0.73069074 | Y14: =SUM(A:B!Y14) -> 13883313 | Z14: =SUM(A:B!Z14) -> 12500474 | AA14: =SUM(A:B!AA14) -> 14787073 | AB14: =SUM(A:B!AB14) -> 14347590 | AC14: =SUM(A:B!AC14) -> 15960345 | AD14: =SUM(A:B!AD14) -> 15798489 | AE14: =SUM(A:B!AE14) -> 15161171 | AF14: =SUM(A:B!AF14) -> 15119204 | ... AK14: =SUM(A:B!AK14) -> 1.8394188e+08 | AL14: =AK14/AK$6 -> 0.73359417 | AM14: =IFERROR(AK14/V14-1,0) -> 0.12446366
A15: B - COSTO DE VENTA | C15: COSTO PREMIUM | D15: COSTO FORANEO PREMIUM | I15: GASOLINA PREMIUM | J15: =SUM(A:B!J15) -> 2994699 | K15: =SUM(A:B!K15) -> 2908739 | L15: =SUM(A:B!L15) -> 3286842 | M15: =SUM(A:B!M15) -> 3157931 | N15: =SUM(A:B!N15) -> 3455437 | O15: =SUM(A:B!O15) -> 3184771 | P15: =SUM(A:B!P15) -> 3126152 | Q15: =SUM(A:B!Q15) -> 3519227 | ... U15: =SUM(A:B!U15) -> 3831077.2 | V15: =SUM(J15:U15) -> 40958107 | W15: =V15/V$6 -> 0.18295247 | Y15: =SUM(A:B!Y15) -> 3080784 | Z15: =SUM(A:B!Z15) -> 2973366.4 | AA15: =SUM(A:B!AA15) -> 3369026.9 | AB15: =SUM(A:B!AB15) -> 3257493.6 | AC15: =SUM(A:B!AC15) -> 3620816.1 | AD15: =SUM(A:B!AD15) -> 3359822.1 | AE15: =SUM(A:B!AE15) -> 3242504 | AF15: =SUM(A:B!AF15) -> 3553874.7 | ... AK15: =SUM(A:B!AK15) -> 42276501 | AL15: =AK15/AK$6 -> 0.16860649 | AM15: =IFERROR(AK15/V15-1,0) -> 0.032188835
A16: B - COSTO DE VENTA | C16: COSTO DIESEL | D16: COSTO FORANEO DIESEL | I16: DIESEL | J16: =SUM(A:B!J16) -> 111034 | K16: =SUM(A:B!K16) -> 101129 | L16: =SUM(A:B!L16) -> 122898 | M16: =SUM(A:B!M16) -> 146759 | N16: =SUM(A:B!N16) -> 171893 | O16: =SUM(A:B!O16) -> 138211 | P16: =SUM(A:B!P16) -> 152522 | Q16: =SUM(A:B!Q16) -> 127651 | ... U16: =SUM(A:B!U16) -> 130644.33 | V16: =SUM(J16:U16) -> 1594674.3 | W16: =V16/V$6 -> 0.0071231223 | Y16: =SUM(A:B!Y16) -> 123989.77 | Z16: =SUM(A:B!Z16) -> 112877.18 | AA16: =SUM(A:B!AA16) -> 135732.7 | AB16: =SUM(A:B!AB16) -> 162121.05 | AC16: =SUM(A:B!AC16) -> 194885.42 | AD16: =SUM(A:B!AD16) -> 158787.2 | AE16: =SUM(A:B!AE16) -> 166769.73 | AF16: =SUM(A:B!AF16) -> 140998.08 | ... AK16: =SUM(A:B!AK16) -> 1705493.2 | AL16: =AK16/AK$6 -> 0.0068018216 | AM16: =IFERROR(AK16/V16-1,0) -> 0.069493096
A17: B - COSTO DE VENTA | C17: Merma Magna | I17: MERMA GASOLINA REGULAR | J17: =SUM(A:B!J17) -> 0 | K17: =SUM(A:B!K17) -> 451 | L17: =SUM(A:B!L17) -> 0 | M17: =SUM(A:B!M17) -> 863 | N17: =SUM(A:B!N17) -> 0 | O17: =SUM(A:B!O17) -> 0 | P17: =SUM(A:B!P17) -> 1786 | Q17: =SUM(A:B!Q17) -> 0 | ... U17: =SUM(A:B!U17) -> 136.88889 | V17: =SUM(J17:U17) -> 3647.5556 | W17: =V17/V$6 -> 1.6292972e-05 | Y17: =SUM(A:B!Y17) -> 0 | Z17: =SUM(A:B!Z17) -> 0 | AA17: =SUM(A:B!AA17) -> 0 | AB17: =SUM(A:B!AB17) -> 0 | AC17: =SUM(A:B!AC17) -> 0 | AD17: =SUM(A:B!AD17) -> 0 | AE17: =SUM(A:B!AE17) -> 0 | AF17: =SUM(A:B!AF17) -> 0 | ... AK17: =SUM(A:B!AK17) -> 0 | AL17: =AK17/AK$6 -> 0 | AM17: =IFERROR(AK17/V17-1,0) -> -1
A18: B - COSTO DE VENTA | C18: Merma Premium | I18: MERMA GASOLINA PREMIUM | J18: =SUM(A:B!J18) -> 10118 | K18: =SUM(A:B!K18) -> 11513 | L18: =SUM(A:B!L18) -> 5892 | M18: =SUM(A:B!M18) -> 235 | N18: =SUM(A:B!N18) -> 5571 | O18: =SUM(A:B!O18) -> 4098 | P18: =SUM(A:B!P18) -> 6579 | Q18: =SUM(A:B!Q18) -> 0 | ... U18: =SUM(A:B!U18) -> 6448.4444 | V18: =SUM(J18:U18) -> 69799.778 | W18: =V18/V$6 -> 0.00031178301 | Y18: =SUM(A:B!Y18) -> 0 | Z18: =SUM(A:B!Z18) -> 0 | AA18: =SUM(A:B!AA18) -> 0 | AB18: =SUM(A:B!AB18) -> 0 | AC18: =SUM(A:B!AC18) -> 0 | AD18: =SUM(A:B!AD18) -> 0 | AE18: =SUM(A:B!AE18) -> 0 | AF18: =SUM(A:B!AF18) -> 0 | ... AK18: =SUM(A:B!AK18) -> 0 | AL18: =AK18/AK$6 -> 0 | AM18: =IFERROR(AK18/V18-1,0) -> -1
A19: B - COSTO DE VENTA | C19: Merma Diesel | I19: MERMA DIESEL | J19: =SUM(A:B!J19) -> -2264 | K19: =SUM(A:B!K19) -> 0 | L19: =SUM(A:B!L19) -> 203 | M19: =SUM(A:B!M19) -> 0 | N19: =SUM(A:B!N19) -> 0 | O19: =SUM(A:B!O19) -> 1796 | P19: =SUM(A:B!P19) -> 0 | Q19: =SUM(A:B!Q19) -> 0 | ... U19: =SUM(A:B!U19) -> 2120.8889 | V19: =SUM(J19:U19) -> 8218.5556 | W19: =V19/V$6 -> 3.6710804e-05 | Y19: =SUM(A:B!Y19) -> 0 | Z19: =SUM(A:B!Z19) -> 0 | AA19: =SUM(A:B!AA19) -> 0 | AB19: =SUM(A:B!AB19) -> 0 | AC19: =SUM(A:B!AC19) -> 0 | AD19: =SUM(A:B!AD19) -> 0 | AE19: =SUM(A:B!AE19) -> 0 | AF19: =SUM(A:B!AF19) -> 0 | ... AK19: =SUM(A:B!AK19) -> 0 | AL19: =AK19/AK$6 -> 0 | AM19: =IFERROR(AK19/V19-1,0) -> -1
I20: SOBRANTE MAGNA | J20: =SUM(A:B!J20) -> -1655 | K20: =SUM(A:B!K20) -> -16260 | L20: =SUM(A:B!L20) -> -47534 | M20: =SUM(A:B!M20) -> -80019 | N20: =SUM(A:B!N20) -> -101412 | O20: =SUM(A:B!O20) -> -102362 | P20: =SUM(A:B!P20) -> -41438 | Q20: =SUM(A:B!Q20) -> -73785 | ... U20: =SUM(A:B!U20) -> -75022.778 | V20: =SUM(J20:U20) -> -764556.11 | W20: =V20/V$6 -> -0.0034151341 | Y20: =SUM(A:B!Y20) -> 0 | Z20: =SUM(A:B!Z20) -> 0 | AA20: =SUM(A:B!AA20) -> 0 | AB20: =SUM(A:B!AB20) -> 0 | AC20: =SUM(A:B!AC20) -> 0 | AD20: =SUM(A:B!AD20) -> 0 | AE20: =SUM(A:B!AE20) -> 0 | AF20: =SUM(A:B!AF20) -> 0 | ... AK20: =SUM(A:B!AK20) -> 0 | AL20: =AK20/AK$6 -> 0 | AM20: =IFERROR(AK20/V20-1,0) -> -1
I21: SOBRANTE PREMIUM | J21: =SUM(A:B!J21) -> 15107 | K21: =SUM(A:B!K21) -> 4291 | L21: =SUM(A:B!L21) -> -4238 | M21: =SUM(A:B!M21) -> -6859 | N21: =SUM(A:B!N21) -> -21701 | O21: =SUM(A:B!O21) -> -91077 | P21: =SUM(A:B!P21) -> 77691 | Q21: =SUM(A:B!Q21) -> -5176 | ... U21: =SUM(A:B!U21) -> -13801.778 | V21: =SUM(J21:U21) -> -87169.111 | W21: =V21/V$6 -> -0.00038936868 | Y21: =SUM(A:B!Y21) -> 0 | Z21: =SUM(A:B!Z21) -> 0 | AA21: =SUM(A:B!AA21) -> 0 | AB21: =SUM(A:B!AB21) -> 0 | AC21: =SUM(A:B!AC21) -> 0 | AD21: =SUM(A:B!AD21) -> 0 | AE21: =SUM(A:B!AE21) -> 0 | AF21: =SUM(A:B!AF21) -> 0 | ... AK21: =SUM(A:B!AK21) -> 0 | AL21: =AK21/AK$6 -> 0 | AM21: =IFERROR(AK21/V21-1,0) -> -1
I22: SOBRANTE DIESEL | J22: =SUM(A:B!J22) -> 0 | K22: =SUM(A:B!K22) -> -1925 | L22: =SUM(A:B!L22) -> -2961 | M22: =SUM(A:B!M22) -> -232 | N22: =SUM(A:B!N22) -> -4780 | O22: =SUM(A:B!O22) -> 0 | P22: =SUM(A:B!P22) -> -2453 | Q22: =SUM(A:B!Q22) -> -1311 | ... U22: =SUM(A:B!U22) -> -2245.2222 | V22: =SUM(J22:U22) -> -22642.889 | W22: =V22/V$6 -> -0.0001011417 | Y22: =SUM(A:B!Y22) -> 0 | Z22: =SUM(A:B!Z22) -> 0 | AA22: =SUM(A:B!AA22) -> 0 | AB22: =SUM(A:B!AB22) -> 0 | AC22: =SUM(A:B!AC22) -> 0 | AD22: =SUM(A:B!AD22) -> 0 | AE22: =SUM(A:B!AE22) -> 0 | AF22: =SUM(A:B!AF22) -> 0 | ... AK22: =SUM(A:B!AK22) -> 0 | AL22: =AK22/AK$6 -> 0 | AM22: =IFERROR(AK22/V22-1,0) -> -1
A23: B - COSTO DE VENTA | C23: ADITIVO PARA GASOLINA TMAXIMA (REGULAR) | D23: ADITIVO PARA GASOLINA TMAXIMA( REGULAR) | I23: ADITIVO TOTAL POWER GASOLINA REG | J23: =SUM(A:B!J23) -> 0 | K23: =SUM(A:B!K23) -> 0 | L23: =SUM(A:B!L23) -> 26670 | M23: =SUM(A:B!M23) -> -26670 | N23: =SUM(A:B!N23) -> 0 | O23: =SUM(A:B!O23) -> 0 | P23: =SUM(A:B!P23) -> 0 | Q23: =SUM(A:B!Q23) -> 0 | ... U23: =SUM(A:B!U23) -> 0 | V23: =SUM(J23:U23) -> 0 | W23: =V23/V$6 -> 0 | Y23: =SUM(A:B!Y23) -> 0 | Z23: =SUM(A:B!Z23) -> 0 | AA23: =SUM(A:B!AA23) -> 0 | AB23: =SUM(A:B!AB23) -> 0 | AC23: =SUM(A:B!AC23) -> 0 | AD23: =SUM(A:B!AD23) -> 0 | AE23: =SUM(A:B!AE23) -> 0 | AF23: =SUM(A:B!AF23) -> 0 | ... AK23: =SUM(A:B!AK23) -> 0 | AL23: =AK23/AK$6 -> 0 | AM23: =IFERROR(AK23/V23-1,0) -> 0
